Workbook
Name Ạ2: Portfolio!$AI$49
Name RPT: Report!$C$2
Name Yesterday: Report!$C$3

Sheet Log
A1: Ngày | B1: Log | C1: PIC
B2: Tạo file và các bảng query | C2: thaottp14
B3: Tạo code VBA và bảng lưu trữ rating lên 53 | C3: thaottp14
A4: 46157 | B4: Sửa query, sửa bảng tham chiếu do thay đổi folder | C4: thaottp14
A5: 46157 | B5: Thêm tenor, tenor ảnh hưởng call put | C5: thaottp14
A6: 46157 | B6: Thêm đối ứng, và tính lại tỷ lệ cho deal đối ứng | C6: thaottp14

Sheet Report
A1: STT | B1: Indicator | C1: Values | G1: 1. Thay đổi rating
A2: 1 | B2: RptDate | C2: 46268 | G2: Issuer code | H2: Issuer name | I2: New Rating FI | J2: Last Rating | K2: New Date Rating | L2: Last Date Rating
A3: 2 | B3: Raw data | C3: ="\\filesrv01.msb.com.vn\06.Khoi Quan Ly Rui Ro\02.Trung Tam QLRR Thi Truong\02.Phong GSRRTT\05.Report\01.Daily report\"&TEXT(RPT,"yyyy.mm.dd")&"\00.Input\00.Raw_Data.xlsm" -> \\filesrv01.msb.com.vn\06.Khoi Quan Ly Rui Ro\02.Trung Tam QLRR Thi Truong\02.Phong GSRRTT\05.Report\01.Daily report\2026.09.03\00.Input\00.Raw_Data.xlsm | G3: =_xlfn.XLOOKUP(H3,Rating!A:A,Rating!B:B,"",0) | H3: {=IFERROR(_xlfn._xlws.FILTER(Rating!A:A,Rating!N:N="Yes"),"")} | I3: =_xlfn.XLOOKUP(H3,Rating!A:A,Rating!D:D,"",0) | J3: =_xlfn.XLOOKUP(H4,Rating!S:S,Rating!U:U,"",0) -> 0 | K3: 46182
A4: 3 | B4: Tool FIBond | C4: ="\\filesrv01.msb.com.vn\06.Khoi Quan Ly Rui Ro\02.Trung Tam QLRR Thi Truong\02.Phong GSRRTT\05.Report\01.Daily Report\"&TEXT(RPT,"yyyy.mm.dd")&"\BOND\02.FI Bond\01.RptTool_FIBond_"&TEXT(RPT,"yyyy.mm.dd")&".xlsb" -> \\filesrv01.msb.com.vn\06.Khoi Quan Ly Rui Ro\02.Trung Tam QLRR Thi Truong\02.Phong GSRRTT\05.Report\01.Daily Report\2026.09.03\BOND\02.FI Bond\01.RptTool_FIBond_2026.09.03.xlsb | G4: =_xlfn.XLOOKUP(H4,Rating!A:A,Rating!B:B,"",0) -> 0 | I4: =_xlfn.XLOOKUP(H4,Rating!A:A,Rating!D:D,"",0) -> 0 | J4: =_xlfn.XLOOKUP(H4,Rating!S:S,Rating!U:U,"",0) -> 0 | K4: =_xlfn.XLOOKUP(H4,Rating!A:A,Rating!E:E,"",0) -> 0
A5: 4 | B5: Rating | C5: ="\\filesrv01.msb.com.vn\06.Khoi Quan Ly Rui Ro\02.Trung Tam QLRR Thi Truong\02.Phong GSRRTT\05.Report\02.Monthly Report\06. Bond Monthly\03.FIBond_Internal rating\Input\"&YEAR(RPT)&"\FI rating và External rating_"&TEXT(RPT,"yyyy.mm")&".xlsx" -> \\filesrv01.msb.com.vn\06.Khoi Quan Ly Rui Ro\02.Trung Tam QLRR Thi Truong\02.Phong GSRRTT\05.Report\02.Monthly Report\06. Bond Monthly\03.FIBond_Internal rating\Input\2026\FI rating và External rating_2026.09.xlsx
A6: 5 | B6: RPBOD3 | C6: ="\\filesrv01.msb.com.vn\06.Khoi Quan Ly Rui Ro\02.Trung Tam QLRR Thi Truong\02.Phong GSRRTT\05.Report\01.Daily report\"&TEXT(RPT,"yyyy.mm.dd")&"\00.Input\02.Kondor\RPBOD_B003.xlsx" -> \\filesrv01.msb.com.vn\06.Khoi Quan Ly Rui Ro\02.Trung Tam QLRR Thi Truong\02.Phong GSRRTT\05.Report\01.Daily report\2026.09.03\00.Input\02.Kondor\RPBOD_B003.xlsx
A7: 6 | B7: Backup | C7: ="\\filesrv01.msb.com.vn\06.Khoi Quan Ly Rui Ro\02.Trung Tam QLRR Thi Truong\02.Phong GSRRTT\05.Report\02.Monthly Report\06. Bond Monthly\03.FIBond_Internal rating\Backup\01.FIBond_Rating_"&TEXT(RPT,"yyyy.mm")&".xlsb" -> \\filesrv01.msb.com.vn\06.Khoi Quan Ly Rui Ro\02.Trung Tam QLRR Thi Truong\02.Phong GSRRTT\05.Report\02.Monthly Report\06. Bond Monthly\03.FIBond_Internal rating\Backup\01.FIBond_Rating_2026.09.xlsb
A8: 7 | B8: Tháng | C8: =MONTH(RPT-30) -> 8
A9: 8 | B9: Năm | C9: =YEAR(RPT-30) -> 2026 | G9: 2. Thay đổi ngày review, giữ nguyên rating (chủ yếu do đến tần suất review định kỳ 1 lần/năm)
A10: 9 | B10: Check | C10: =IF(AND(Portfolio!D10=Portfolio!B24,Portfolio!D10=Portfolio_by_issuer[[#Totals],[Total Amount]],Portfolio!D10=Portfolio!B24),"OK","CHECK") -> CHECK | G10: Issuer code | H10: Issuer name | I10: Rating FI | J10: New Date Rating | K10: Last Date Rating
A11: 10 | B11: FNRP BB MSB | C11: ="\\filesrv01.msb.com.vn\06.Khoi Quan Ly Rui Ro\02.Trung Tam QLRR Thi Truong\02.Phong GSRRTT\05.Report\01.Daily Report\"&TEXT(RPT,"yyyy.mm.dd")&"\00.Input\01.DataFile53\BondAllBS2BK.BondsSynthetic.csv" -> \\filesrv01.msb.com.vn\06.Khoi Quan Ly Rui Ro\02.Trung Tam QLRR Thi Truong\02.Phong GSRRTT\05.Report\01.Daily Report\2026.09.03\00.Input\01.DataFile53\BondAllBS2BK.BondsSynthetic.csv | G11: =_xlfn.XLOOKUP(H11,Rating!A:A,Rating!B:B,"",0) -> PBVN | H11: {=_xlfn._xlws.FILTER(Rating!A:A, (Rating!L:L="No") * (Rating!M:M="Yes"))} -> NGAN HANG TNHH MTV PUBLIC VN | I11: =_xlfn.XLOOKUP(H11,Rating!A:A,Rating!D:D,"",0) -> BB | J11: =_xlfn.XLOOKUP(H11,Rating!A:A,Rating!E:E,"",0) -> 46237 | K11: =_xlfn.XLOOKUP(H11,Rating!S:S,Rating!V:V,"",0) -> 45782
A12: 11 | B12: Tỷ giá | C12: 298.3522 | G12: =_xlfn.XLOOKUP(H12,Rating!A:A,Rating!B:B,"",0) -> SGTT | H12: NGAN HANG TMCP SAI GON TAI LOC | I12: =_xlfn.XLOOKUP(H12,Rating!A:A,Rating!D:D,"",0) -> A | J12: =_xlfn.XLOOKUP(H12,Rating!A:A,Rating!E:E,"",0) -> 46253 | K12: =_xlfn.XLOOKUP(H12,Rating!S:S,Rating!V:V,"",0) -> 0
G13: =_xlfn.XLOOKUP(H13,Rating!A:A,Rating!B:B,"",0) -> VNDIRECT | H13: CONG TY CP CHUNG KHOAN VNDIRECT | I13: =_xlfn.XLOOKUP(H13,Rating!A:A,Rating!D:D,"",0) -> AAA | J13: =_xlfn.XLOOKUP(H13,Rating!A:A,Rating!E:E,"",0) -> 46216 | K13: =_xlfn.XLOOKUP(H13,Rating!S:S,Rating!V:V,"",0) -> 45460
G14: =_xlfn.XLOOKUP(H14,Rating!A:A,Rating!B:B,"",0) -> PINETREE | H14: CONG TY CP CHUNG KHOAN PINETREE | I14: =_xlfn.XLOOKUP(H14,Rating!A:A,Rating!D:D,"",0) -> BBB | J14: =_xlfn.XLOOKUP(H14,Rating!A:A,Rating!E:E,"",0) -> 46231 | K14: =_xlfn.XLOOKUP(H14,Rating!S:S,Rating!V:V,"",0) -> 45866
G15: =_xlfn.XLOOKUP(H15,Rating!A:A,Rating!B:B,"",0) -> 0 | I15: =_xlfn.XLOOKUP(H15,Rating!A:A,Rating!D:D,"",0) -> 0 | J15: =_xlfn.XLOOKUP(H15,Rating!A:A,Rating!E:E,"",0) -> 0 | K15: =_xlfn.XLOOKUP(H15,Rating!S:S,Rating!V:V,"",0) -> 0
G16: =_xlfn.XLOOKUP(H16,Rating!A:A,Rating!B:B,"",0) -> 0 | I16: =_xlfn.XLOOKUP(H16,Rating!A:A,Rating!D:D,"",0) -> 0 | J16: =_xlfn.XLOOKUP(H16,Rating!A:A,Rating!E:E,"",0) -> 0 | K16: =_xlfn.XLOOKUP(H16,Rating!S:S,Rating!V:V,"",0) -> 0
G22: 3. Issuer mới được xếp hạng hoặc bị xóa xếp hạng
G23: Issuer code | H23: Issuer name | I23: Loại hình DN | J23: FI Rating | K23: Ngày xếp hạng | L23: Tổ chức xếp hạng | O23: Ngày xếp hạng
L24: Fitch | M24: Moody's | N24: S&P | O24: Fitch | P24: Moody's | Q24: S&P
G25: =_xlfn.XLOOKUP(H25,Rating!A:A,Rating!B:B,"",0) | H25: {=IFERROR(_xlfn._xlws.FILTER(Rating!A:A,Rating!N:N="Yes"),"")} | I25: =_xlfn.XLOOKUP(H25,Rating!A:A,Rating!C:C,"",0) | J25: =_xlfn.XLOOKUP(H25,Rating!A:A,Rating!D:D,"",0) | K25: 46182 | L25: =_xlfn.XLOOKUP(H25,Rating!A:A,Rating!F:F,"",0) | M25: =_xlfn.XLOOKUP(H25,Rating!A:A,Rating!H:H,"",0) | N25: =_xlfn.XLOOKUP(H25,Rating!A:A,Rating!J:J,"",0) | O25: =_xlfn.XLOOKUP(H25,Rating!A:A,Rating!G:G,"-",0) -> - | P25: =_xlfn.XLOOKUP(H25,Rating!A:A,Rating!I:I,"",0) | Q25: =_xlfn.XLOOKUP(H25,Rating!A:A,Rating!K:K,"",0)
G26: =_xlfn.XLOOKUP(H26,Rating!A:A,Rating!B:B,"",0) -> 0 | I26: =_xlfn.XLOOKUP(H26,Rating!A:A,Rating!C:C,"",0) -> 0 | J26: =_xlfn.XLOOKUP(H26,Rating!A:A,Rating!D:D,"",0) -> 0 | K26: =_xlfn.XLOOKUP(H26,Rating!A:A,Rating!E:E,"",0) -> 0 | L26: =_xlfn.XLOOKUP(H26,Rating!A:A,Rating!F:F,"",0) -> 0 | M26: =_xlfn.XLOOKUP(H26,Rating!A:A,Rating!H:H,"",0) -> 0 | N26: =_xlfn.XLOOKUP(H26,Rating!A:A,Rating!J:J,"",0) -> 0 | O26: =_xlfn.XLOOKUP(H26,Rating!A:A,Rating!G:G,"",0) -> 0 | P26: =_xlfn.XLOOKUP(H26,Rating!A:A,Rating!I:I,"",0) -> 0 | Q26: =_xlfn.XLOOKUP(H26,Rating!A:A,Rating!K:K,"",0) -> 0
L27: =_xlfn.XLOOKUP(H27,Rating!A:A,Rating!F:F,"",0) -> 0 | M27: =_xlfn.XLOOKUP(H27,Rating!A:A,Rating!H:H,"",0) -> 0 | N27: =_xlfn.XLOOKUP(H27,Rating!A:A,Rating!J:J,"",0) -> 0 | O27: =_xlfn.XLOOKUP(H27,Rating!A:A,Rating!G:G,"",0) -> 0 | P27: =_xlfn.XLOOKUP(H27,Rating!A:A,Rating!I:I,"",0) -> 0 | Q27: =_xlfn.XLOOKUP(H27,Rating!A:A,Rating!K:K,"",0) -> 0
L28: =_xlfn.XLOOKUP(H28,Rating!A:A,Rating!F:F,"",0) -> 0 | M28: =_xlfn.XLOOKUP(H28,Rating!A:A,Rating!H:H,"",0) -> 0 | N28: =_xlfn.XLOOKUP(H28,Rating!A:A,Rating!J:J,"",0) -> 0 | O28: =_xlfn.XLOOKUP(H28,Rating!A:A,Rating!G:G,"",0) -> 0 | P28: =_xlfn.XLOOKUP(H28,Rating!A:A,Rating!I:I,"",0) -> 0 | Q28: =_xlfn.XLOOKUP(H28,Rating!A:A,Rating!K:K,"",0) -> 0
L29: =_xlfn.XLOOKUP(H29,Rating!A:A,Rating!F:F,"",0) -> 0 | M29: =_xlfn.XLOOKUP(H29,Rating!A:A,Rating!H:H,"",0) -> 0 | N29: =_xlfn.XLOOKUP(H29,Rating!A:A,Rating!J:J,"",0) -> 0 | O29: =_xlfn.XLOOKUP(H29,Rating!A:A,Rating!G:G,"",0) -> 0 | P29: =_xlfn.XLOOKUP(H29,Rating!A:A,Rating!I:I,"",0) -> 0 | Q29: =_xlfn.XLOOKUP(H29,Rating!A:A,Rating!K:K,"",0) -> 0

Sheet Portfolio
A1: Internal Rating | B1: Haircut in Normal | C1: Haircut in Stress | D1: Sau khi điều chỉnh rating | G1: Trước khi điều chỉnh rating | J1: Outstandings By issuers | K1: Issuer | L1: Total Amount | M1: Rating | N1: Review Date | O1: Fitch Rating | P1: Moody Rating | Q1: S&P Rating | R1: Tỷ lệ lũy kế | S1: Last rating | T1: Tỷ lệ lũy kế | V1: Outstandings By bond | W1: Issuer | X1: Issuer_Name | Y1: Bond_Code | Z1: Tenor | AA1: Tenor (c/p) | AB1: Rating | AC1: Review Date | AD1: Fitch Rating | AE1: Moody Rating | AF1: S&P Rating | AG1: Total Amount | AH1: Tỷ lệ lũy kế | AI1: Amount adj đối ứng | AJ1: Tỷ lệ lũy kế | AK1: Tenor (ca/pu) | AM1: Row Labels | AN1: Sum of Total Amount | AP1: Row Labels | AQ1: Sum of Total Amount
D2: Bond Oustanding | E2: Tỷ lệ lũy kế | F2: Tỷ lệ lũy kế adj đối ứng | G2: Bond Oustanding | H2: Tỷ lệ lũy kế | J2: Tỷ lệ this rate | K2: VBAH | L2: 3000 | M2: AAA | N2: 46203 | P2: Ba2 | R2: =Portfolio_by_issuer[[#This Row],[Total Amount]]/Portfolio_by_issuer[[#Totals],[Total Amount]] -> 0.081679114 | S2: =_xlfn.XLOOKUP(Portfolio_by_issuer[[#This Row],[Issuer]],Rating!T:T,Rating!U:U,,0) -> AAA | T2: =Portfolio_by_issuer[[#This Row],[Total Amount]]/Portfolio_by_issuer[[#Totals],[Total Amount]] -> 0.081679114 | W2: HCVN | X2: CONG TY TAI CHINH TNHH MTV HOME CREDIT VN | Y2: HCVCD180926 | Z2: <1M | AB2: AAA | AC2: 46128 | AG2: 50 | AH2: =AG2/Portfolio_by_bond[[#Totals],[Total Amount]] -> 0.0013613364 | AI2: =Portfolio_by_bond[[#This Row],[Total Amount]]-_xlfn.XLOOKUP(Portfolio_by_bond[[#This Row],[Bond_Code]],'Ref'!F:F,'Ref'!G:G,0,0) -> 50 | AJ2: =AI2/(SUM(AI:AI)/2) -> 0.0017328851 | AK2: =IF(AA2="",Z2,AA2) -> <1M | AM2: <1M | AN2: 3350 | AP2: <1M | AQ2: 3350
A3: AAA | B3: 0.2 | C3: 0.19 | D3: =SUMIFS(L:L,M:M,A3) -> 8765 | E3: =_xlfn.MAXIFS(T:T,M:M,A3) -> 0.23863914 | F3: =SUMIFS(AI:AI,AB:AB,A3)/(SUM(AI:AI)/2) -> 0.30377476 | G3: =SUMIFS(L:L,S:S,A3) -> 8765 | H3: =_xlfn.MAXIFS(T:T,S:S,A3) -> 0.23863914 | J3: =_xlfn.MAXIFS(R:R,M:M,"BBB") -> 0.79991068 | K3: TCBV-HO | L3: 2300 | M3: AAA | N3: 46211 | R3: =R2+Portfolio_by_issuer[[#This Row],[Total Amount]]/Portfolio_by_issuer[[#Totals],[Total Amount]] -> 0.14429977 | S3: =_xlfn.XLOOKUP(Portfolio_by_issuer[[#This Row],[Issuer]],Rating!T:T,Rating!U:U,,0) -> AAA | T3: =T2+Portfolio_by_issuer[[#This Row],[Total Amount]]/Portfolio_by_issuer[[#Totals],[Total Amount]] -> 0.14429977 | W3: HCVN | X3: CONG TY TAI CHINH TNHH MTV HOME CREDIT VN | Y3: HCVCD231026 | Z3: 1-3M | AB3: AAA | AC3: 46128 | AG3: 200 | AH3: =AH2+AG3/Portfolio_by_bond[[#Totals],[Total Amount]] -> 0.006806682 | AI3: =Portfolio_by_bond[[#This Row],[Total Amount]]-_xlfn.XLOOKUP(Portfolio_by_bond[[#This Row],[Bond_Code]],'Ref'!F:F,'Ref'!G:G,0,0) -> 200 | AJ3: =AJ2+AI3/(SUM(AI:AI)/2) -> 0.0086644257 | AK3: =IF(AA3="",Z3,AA3) -> 1-3M | AM3: 1-2Y | AN3: 700 | AP3: 1-2Y | AQ3: 1700
A4: AA | B4: 0.2 | C4: 0.2 | D4: =SUMIFS(L:L,M:M,A4) -> 6344.6106 | E4: =_xlfn.MAXIFS(T:T,M:M,A4) -> 0.41137987 | F4: =F3+SUMIFS(AI:AI,AB:AB,A4)/(SUM(AI:AI)/2) -> 0.47167784 | G4: =SUMIFS(L:L,S:S,A4) -> 6344.6106 | H4: =_xlfn.MAXIFS(T:T,S:S,A4) -> 0.41137987 | J4: Tỷ lệ last rate | K4: HCVN | L4: 2250 | M4: AAA | N4: 46128 | R4: =R3+Portfolio_by_issuer[[#This Row],[Total Amount]]/Portfolio_by_issuer[[#Totals],[Total Amount]] -> 0.2055591 | S4: =_xlfn.XLOOKUP(Portfolio_by_issuer[[#This Row],[Issuer]],Rating!T:T,Rating!U:U,,0) -> AAA | T4: =T3+Portfolio_by_issuer[[#This Row],[Total Amount]]/Portfolio_by_issuer[[#Totals],[Total Amount]] -> 0.2055591 | W4: HCVN | X4: CONG TY TAI CHINH TNHH MTV HOME CREDIT VN | Y4: HCVNCD190427 | Z4: 6M-1Y | AB4: AAA | AC4: 46128 | AG4: 400 | AH4: =AH3+AG4/Portfolio_by_bond[[#Totals],[Total Amount]] -> 0.017697373 | AI4: =Portfolio_by_bond[[#This Row],[Total Amount]]-_xlfn.XLOOKUP(Portfolio_by_bond[[#This Row],[Bond_Code]],'Ref'!F:F,'Ref'!G:G,0,0) -> 400 | AJ4: =AJ3+AI4/(SUM(AI:AI)/2) -> 0.022527507 | AK4: =IF(AA4="",Z4,AA4) -> 6M-1Y | AM4: 1-3M | AN4: 7950 | AP4: 1-3M | AQ4: 7950
A5: A | B5: 0.2 | C5: 0.23 | D5: =SUMIFS(L:L,M:M,A5) -> 8200 | E5: =_xlfn.MAXIFS(T:T,M:M,A5) -> 0.63463611 | F5: =F4+SUMIFS(AI:AI,AB:AB,A5)/(SUM(AI:AI)/2) -> 0.755871 | G5: =SUMIFS(L:L,S:S,A5) -> 8200 | H5: =_xlfn.MAXIFS(T:T,S:S,A5) -> 0.63463611 | J5: =_xlfn.MAXIFS(T:T,S:S,"BBB") -> 0.79991068 | K5: MCSB | L5: 1215 | M5: AAA | N5: 46136 | O5: BB | P5: Ba2 | R5: =R4+Portfolio_by_issuer[[#This Row],[Total Amount]]/Portfolio_by_issuer[[#Totals],[Total Amount]] -> 0.23863914 | S5: =_xlfn.XLOOKUP(Portfolio_by_issuer[[#This Row],[Issuer]],Rating!T:T,Rating!U:U,,0) -> AAA | T5: =T4+Portfolio_by_issuer[[#This Row],[Total Amount]]/Portfolio_by_issuer[[#Totals],[Total Amount]] -> 0.23863914 | W5: HCVN | X5: CONG TY TAI CHINH TNHH MTV HOME CREDIT VN | Y5: HCV12502 | Z5: 6M-1Y | AB5: AAA | AC5: 46128 | AG5: 400 | AH5: =AH4+AG5/Portfolio_by_bond[[#Totals],[Total Amount]] -> 0.028588064 | AI5: =Portfolio_by_bond[[#This Row],[Total Amount]]-_xlfn.XLOOKUP(Portfolio_by_bond[[#This Row],[Bond_Code]],'Ref'!F:F,'Ref'!G:G,0,0) -> 400 | AJ5: =AJ4+AI5/(SUM(AI:AI)/2) -> 0.036390588 | AK5: =IF(AA5="",Z5,AA5) -> 6M-1Y | AM5: 2-3Y | AN5: 3000 | AP5: 3-6M | AQ5: 3172
A6: BBB | B6: 0.2 | C6: 0.26 | D6: =SUMIFS(L:L,M:M,A6) -> 6070.3854 | E6: =_xlfn.MAXIFS(T:T,M:M,A6) -> 0.79991068 | F6: =F5+SUMIFS(AI:AI,AB:AB,A6)/(SUM(AI:AI)/2) -> 0.77319985 | G6: =SUMIFS(L:L,S:S,A6) -> 6070.3854 | H6: =_xlfn.MAXIFS(T:T,S:S,A6) -> 0.79991068 | K6: HDBV | L6: 2697.6106 | M6: AA | N6: 46022 | P6: B1 | R6: =R5+Portfolio_by_issuer[[#This Row],[Total Amount]]/Portfolio_by_issuer[[#Totals],[Total Amount]] -> 0.31208529 | S6: =_xlfn.XLOOKUP(Portfolio_by_issuer[[#This Row],[Issuer]],Rating!T:T,Rating!U:U,,0) -> AA | T6: =T5+Portfolio_by_issuer[[#This Row],[Total Amount]]/Portfolio_by_issuer[[#Totals],[Total Amount]] -> 0.31208529 | W6: HCVN | X6: CONG TY TAI CHINH TNHH MTV HOME CREDIT VN | Y6: HCVL12606 | Z6: 1-2Y | AB6: AAA | AC6: 46128 | AG6: 200 | AH6: =AH5+AG6/Portfolio_by_bond[[#Totals],[Total Amount]] -> 0.03403341 | AI6: =Portfolio_by_bond[[#This Row],[Total Amount]]-_xlfn.XLOOKUP(Portfolio_by_bond[[#This Row],[Bond_Code]],'Ref'!F:F,'Ref'!G:G,0,0) -> 200 | AJ6: =AJ5+AI6/(SUM(AI:AI)/2) -> 0.043322128 | AK6: =IF(AA6="",Z6,AA6) -> 1-2Y | AM6: 3-6M | AN6: 3172 | AP6: 6M-1Y | AQ6: 17986.711
A7: BB | B7: 0.2 | C7: 0.36 | D7: =SUMIFS(L:L,M:M,A7) -> 5850 | E7: =_xlfn.MAXIFS(T:T,M:M,A7) -> 0.95918495 | F7: =F6+SUMIFS(AI:AI,AB:AB,A7)/(SUM(AI:AI)/2) -> 0.97594741 | G7: =SUMIFS(L:L,S:S,A7) -> 5850 | H7: =_xlfn.MAXIFS(T:T,S:S,A7) -> 0.95918495 | K7: ACBV | L7: 1400 | M7: AA | N7: 46203 | O7: BB- | P7: Ba3 | R7: =R6+Portfolio_by_issuer[[#This Row],[Total Amount]]/Portfolio_by_issuer[[#Totals],[Total Amount]] -> 0.35020221 | S7: =_xlfn.XLOOKUP(Portfolio_by_issuer[[#This Row],[Issuer]],Rating!T:T,Rating!U:U,,0) -> AA | T7: =T6+Portfolio_by_issuer[[#This Row],[Total Amount]]/Portfolio_by_issuer[[#Totals],[Total Amount]] -> 0.35020221 | W7: HCVN | X7: CONG TY TAI CHINH TNHH MTV HOME CREDIT VN | Y7: HCV12602 | Z7: 2-3Y | AB7: AAA | AC7: 46128 | AG7: 1000 | AH7: =AH6+AG7/Portfolio_by_bond[[#Totals],[Total Amount]] -> 0.061260138 | AI7: =Portfolio_by_bond[[#This Row],[Total Amount]]-_xlfn.XLOOKUP(Portfolio_by_bond[[#This Row],[Bond_Code]],'Ref'!F:F,'Ref'!G:G,0,0) -> 1000 | AJ7: =AJ6+AI7/(SUM(AI:AI)/2) -> 0.077979831 | AK7: =IF(AA7="",Z7,AA7) -> 2-3Y | AM7: 5-7Y | AN7: 3897.6106 | AP7: 2-3Y | AQ7: 1000
A8: B | B8: 0.2 | C8: 0.52 | D8: =SUMIFS(L:L,M:M,A8) -> 1000 | E8: 0.98 | F8: 0.99 | G8: =SUMIFS(L:L,S:S,A8) -> 1000 | H8: 0.99 | K8: LVBT | L8: 1000 | M8: AA | N8: 46199 | P8: Ba3 | R8: =R7+Portfolio_by_issuer[[#This Row],[Total Amount]]/Portfolio_by_issuer[[#Totals],[Total Amount]] -> 0.37742858 | S8: =_xlfn.XLOOKUP(Portfolio_by_issuer[[#This Row],[Issuer]],Rating!T:T,Rating!U:U,,0) -> AA | T8: =T7+Portfolio_by_issuer[[#This Row],[Total Amount]]/Portfolio_by_issuer[[#Totals],[Total Amount]] -> 0.37742858 | W8: MCSB | X8: NGAN HANG TMCP QUAN DOI | Y8: MBBOND2027 | Z8: 1-2Y | AB8: AAA | AC8: 46136 | AD8: BB | AE8: Ba2 | AG8: 500 | AH8: =AH7+AG8/Portfolio_by_bond[[#Totals],[Total Amount]] -> 0.074873502 | AI8: =Portfolio_by_bond[[#This Row],[Total Amount]]-_xlfn.XLOOKUP(Portfolio_by_bond[[#This Row],[Bond_Code]],'Ref'!F:F,'Ref'!G:G,0,0) -> 500 | AJ8: =AJ7+AI8/(SUM(AI:AI)/2) -> 0.095308683 | AK8: =IF(AA8="",Z8,AA8) -> 1-2Y | AM8: 6M-1Y | AN8: 14089.1 | AP8: 3-5Y | AQ8: 569.90402
A9: D | B9: 0.2 | C9: 0.52 | D9: =SUMIFS(L:L,M:M,A9) -> 499.1 | E9: 1 | F9: 1 | G9: =SUMIFS(L:L,S:S,A9) -> 499.1 | H9: 1 | K9: TC_DIENLUC | L9: 847 | M9: AA | N9: 46164 | P9: B2 | R9: =R8+Portfolio_by_issuer[[#This Row],[Total Amount]]/Portfolio_by_issuer[[#Totals],[Total Amount]] -> 0.40048932 | S9: =_xlfn.XLOOKUP(Portfolio_by_issuer[[#This Row],[Issuer]],Rating!T:T,Rating!U:U,,0) -> AA | T9: =T8+Portfolio_by_issuer[[#This Row],[Total Amount]]/Portfolio_by_issuer[[#Totals],[Total Amount]] -> 0.40048932 | W9: MCSB | X9: NGAN HANG TMCP QUAN DOI | Y9: MBBCD040227 | Z9: 3-6M | AB9: AAA | AC9: 46136 | AD9: BB | AE9: Ba2 | AG9: 715 | AH9: =AH8+AG9/Portfolio_by_bond[[#Totals],[Total Amount]] -> 0.094340613 | AI9: =Portfolio_by_bond[[#This Row],[Total Amount]]-_xlfn.XLOOKUP(Portfolio_by_bond[[#This Row],[Bond_Code]],'Ref'!F:F,'Ref'!G:G,0,0) -> 715 | AJ9: =AJ8+AI9/(SUM(AI:AI)/2) -> 0.12008894 | AK9: =IF(AA9="",Z9,AA9) -> 3-6M | AM9: 3-5Y | AN9: 569.90402 | AP9: 5-7Y | AQ9: 1000
A10: Grand Total | D10: =SUM(D3:D9) -> 36729.096 | E10: =E9 -> 1 | F10: =F9 -> 1 | G10: =SUM(G3:G9) -> 36729.096 | H10: =H9 -> 1 | K10: VPVN | L10: 400 | M10: AA | N10: 46142 | P10: Ba3 | R10: =R9+Portfolio_by_issuer[[#This Row],[Total Amount]]/Portfolio_by_issuer[[#Totals],[Total Amount]] -> 0.41137987 | S10: =_xlfn.XLOOKUP(Portfolio_by_issuer[[#This Row],[Issuer]],Rating!T:T,Rating!U:U,,0) -> AA | T10: =T9+Portfolio_by_issuer[[#This Row],[Total Amount]]/Portfolio_by_issuer[[#Totals],[Total Amount]] -> 0.41137987 | W10: TCBV-HO | X10: NGAN HANG TMCP KY THUONG VN | Y10: TCBCD0251226 | Z10: 3-6M | AB10: AAA | AC10: 46211 | AG10: 300 | AH10: =AH9+AG10/Portfolio_by_bond[[#Totals],[Total Amount]] -> 0.10250863 | AI10: =Portfolio_by_bond[[#This Row],[Total Amount]]-_xlfn.XLOOKUP(Portfolio_by_bond[[#This Row],[Bond_Code]],'Ref'!F:F,'Ref'!G:G,0,0) -> 300 | AJ10: =AJ9+AI10/(SUM(AI:AI)/2) -> 0.13048625 | AK10: =IF(AA10="",Z10,AA10) -> 3-6M | AM10: Grand Total | AN10: 36728.615 | AP10: Grand Total | AQ10: 36728.615
K11: SGTT | L11: 3700 | M11: A | N11: 46253 | O11: BB- | P11: B1 | R11: =R10+Portfolio_by_issuer[[#This Row],[Total Amount]]/Portfolio_by_issuer[[#Totals],[Total Amount]] -> 0.51211744 | S11: =_xlfn.XLOOKUP(Portfolio_by_issuer[[#This Row],[Issuer]],Rating!T:T,Rating!U:U,,0) -> A | T11: =T10+Portfolio_by_issuer[[#This Row],[Total Amount]]/Portfolio_by_issuer[[#Totals],[Total Amount]] -> 0.51211744 | W11: TCBV-HO | X11: NGAN HANG TMCP KY THUONG VN | Y11: TCB12603 | Z11: 2-3Y | AA11: 6M-1Y | AB11: AAA | AC11: 46211 | AG11: 2000 | AH11: =AH10+AG11/Portfolio_by_bond[[#Totals],[Total Amount]] -> 0.15696209 | AI11: =Portfolio_by_bond[[#This Row],[Total Amount]]-_xlfn.XLOOKUP(Portfolio_by_bond[[#This Row],[Bond_Code]],'Ref'!F:F,'Ref'!G:G,0,0) -> 2000 | AJ11: =AJ10+AI11/(SUM(AI:AI)/2) -> 0.19980166 | AK11: =IF(AA11="",Z11,AA11) -> 6M-1Y
K12: SABH | L12: 3000 | M12: A | N12: 46141 | O12: B+ | P12: B2 | R12: =R11+Portfolio_by_issuer[[#This Row],[Total Amount]]/Portfolio_by_issuer[[#Totals],[Total Amount]] -> 0.59379655 | S12: =_xlfn.XLOOKUP(Portfolio_by_issuer[[#This Row],[Issuer]],Rating!T:T,Rating!U:U,,0) -> A | T12: =T11+Portfolio_by_issuer[[#This Row],[Total Amount]]/Portfolio_by_issuer[[#Totals],[Total Amount]] -> 0.59379655 | W12: VBAH | X12: NGAN HANG NONG NGHIEP VA PHAT TRIEN NONG THON | Y12: VBA12503 | Z12: 6M-1Y | AB12: AAA | AC12: 46203 | AE12: Ba2 | AG12: 3000 | AH12: =AH11+AG12/Portfolio_by_bond[[#Totals],[Total Amount]] -> 0.23864227 | AI12: =Portfolio_by_bond[[#This Row],[Total Amount]]-_xlfn.XLOOKUP(Portfolio_by_bond[[#This Row],[Bond_Code]],'Ref'!F:F,'Ref'!G:G,0,0) -> 3000 | AJ12: =AJ11+AI12/(SUM(AI:AI)/2) -> 0.30377476 | AK12: =IF(AA12="",Z12,AA12) -> 6M-1Y
A13: Tenor | B13: Amount | C13: Amount (c/p) | K13: SHBV | L13: 1500 | M13: A | N13: 46211 | O13: BB- | P13: B1 | R13: =R12+Portfolio_by_issuer[[#This Row],[Total Amount]]/Portfolio_by_issuer[[#Totals],[Total Amount]] -> 0.63463611 | S13: =_xlfn.XLOOKUP(Portfolio_by_issuer[[#This Row],[Issuer]],Rating!T:T,Rating!U:U,,0) -> A | T13: =T12+Portfolio_by_issuer[[#This Row],[Total Amount]]/Portfolio_by_issuer[[#Totals],[Total Amount]] -> 0.63463611 | W13: ACBV | X13: NGAN HANG TMCP A CHAU | Y13: ACBCD140127 | Z13: 3-6M | AB13: AA | AC13: 46203 | AD13: BB- | AE13: Ba3 | AG13: 300 | AH13: =AH12+AG13/Portfolio_by_bond[[#Totals],[Total Amount]] -> 0.24681029 | AI13: =Portfolio_by_bond[[#This Row],[Total Amount]]-_xlfn.XLOOKUP(Portfolio_by_bond[[#This Row],[Bond_Code]],'Ref'!F:F,'Ref'!G:G,0,0) -> 300 | AJ13: =AJ12+AI13/(SUM(AI:AI)/2) -> 0.31417208 | AK13: =IF(AA13="",Z13,AA13) -> 3-6M
K14: NABV | L14: 3000 | M14: BBB | N14: 46146 | O14: B+ | R14: =R13+Portfolio_by_issuer[[#This Row],[Total Amount]]/Portfolio_by_issuer[[#Totals],[Total Amount]] -> 0.71631522 | S14: =_xlfn.XLOOKUP(Portfolio_by_issuer[[#This Row],[Issuer]],Rating!T:T,Rating!U:U,,0) -> BBB | T14: =T13+Portfolio_by_issuer[[#This Row],[Total Amount]]/Portfolio_by_issuer[[#Totals],[Total Amount]] -> 0.71631522 | W14: ACBV | X14: NGAN HANG TMCP A CHAU | Y14: ACBCD090427 | Z14: 6M-1Y | AB14: AA | AC14: 46203 | AD14: BB- | AE14: Ba3 | AG14: 200 | AH14: =AH13+AG14/Portfolio_by_bond[[#Totals],[Total Amount]] -> 0.25225563 | AI14: =Portfolio_by_bond[[#This Row],[Total Amount]]-_xlfn.XLOOKUP(Portfolio_by_bond[[#This Row],[Bond_Code]],'Ref'!F:F,'Ref'!G:G,0,0) -> 200 | AJ14: =AJ13+AI14/(SUM(AI:AI)/2) -> 0.32110362 | AK14: =IF(AA14="",Z14,AA14) -> 6M-1Y
A15: <1M | B15: =_xlfn.XLOOKUP(A15,AM:AM,AN:AN,0,0) -> 3350 | C15: =_xlfn.XLOOKUP(A15,AP:AP,AQ:AQ,0,0) -> 3350 | K15: OCBV | L15: 2500 | M15: BBB | N15: 46206 | P15: Ba3 | R15: =R14+Portfolio_by_issuer[[#This Row],[Total Amount]]/Portfolio_by_issuer[[#Totals],[Total Amount]] -> 0.78438115 | S15: =_xlfn.XLOOKUP(Portfolio_by_issuer[[#This Row],[Issuer]],Rating!T:T,Rating!U:U,,0) -> BBB | T15: =T14+Portfolio_by_issuer[[#This Row],[Total Amount]]/Portfolio_by_issuer[[#Totals],[Total Amount]] -> 0.78438115 | W15: ACBV | X15: NGAN HANG TMCP A CHAU | Y15: ACBCD190127 | Z15: 3-6M | AB15: AA | AC15: 46203 | AD15: BB- | AE15: Ba3 | AG15: 400 | AH15: =AH14+AG15/Portfolio_by_bond[[#Totals],[Total Amount]] -> 0.26314633 | AI15: =Portfolio_by_bond[[#This Row],[Total Amount]]-_xlfn.XLOOKUP(Portfolio_by_bond[[#This Row],[Bond_Code]],'Ref'!F:F,'Ref'!G:G,0,0) -> 400 | AJ15: =AJ14+AI15/(SUM(AI:AI)/2) -> 0.3349667 | AK15: =IF(AA15="",Z15,AA15) -> 3-6M
A16: 1-3M | B16: =_xlfn.SINGLE(_xlfn.XLOOKUP(A16,AM:AM,AN:AN,0,0)) -> 7950 | C16: =_xlfn.SINGLE(_xlfn.XLOOKUP(A16,AP:AP,AQ:AQ,0,0)) -> 7950 | K16: MFKR | L16: 570.38538 | M16: BBB | O16: B | P16: B3 | Q16: B+ | R16: =R15+Portfolio_by_issuer[[#This Row],[Total Amount]]/Portfolio_by_issuer[[#Totals],[Total Amount]] -> 0.79991068 | S16: =_xlfn.XLOOKUP(Portfolio_by_issuer[[#This Row],[Issuer]],Rating!T:T,Rating!U:U,,0) -> BBB | T16: =T15+Portfolio_by_issuer[[#This Row],[Total Amount]]/Portfolio_by_issuer[[#Totals],[Total Amount]] -> 0.79991068 | W16: ACBV | X16: NGAN HANG TMCP A CHAU | Y16: ACBCD021226 | Z16: 1-3M | AB16: AA | AC16: 46203 | AD16: BB- | AE16: Ba3 | AG16: 500 | AH16: =AH15+AG16/Portfolio_by_bond[[#Totals],[Total Amount]] -> 0.27675969 | AI16: =Portfolio_by_bond[[#This Row],[Total Amount]]-_xlfn.XLOOKUP(Portfolio_by_bond[[#This Row],[Bond_Code]],'Ref'!F:F,'Ref'!G:G,0,0) -> 500 | AJ16: =AJ15+AI16/(SUM(AI:AI)/2) -> 0.35229555 | AK16: =IF(AA16="",Z16,AA16) -> 1-3M
A17: 3-6M | B17: =_xlfn.SINGLE(_xlfn.XLOOKUP(A17,AM:AM,AN:AN,0,0)) -> 3172 | C17: =_xlfn.SINGLE(_xlfn.XLOOKUP(A17,AP:AP,AQ:AQ,0,0)) -> 3172 | K17: VIETBANK | L17: 2500 | M17: BB | N17: 46128 | R17: =R16+Portfolio_by_issuer[[#This Row],[Total Amount]]/Portfolio_by_issuer[[#Totals],[Total Amount]] -> 0.8679766 | S17: =_xlfn.XLOOKUP(Portfolio_by_issuer[[#This Row],[Issuer]],Rating!T:T,Rating!U:U,,0) -> BB | T17: =T16+Portfolio_by_issuer[[#This Row],[Total Amount]]/Portfolio_by_issuer[[#Totals],[Total Amount]] -> 0.8679766 | W17: HDBV | X17: NGAN HANG TMCP PHAT TRIEN TP HO CHI MINH | Y17: HDB125011 | Z17: 5-7Y | AA17: 6M-1Y | AB17: AA | AC17: 46022 | AE17: B1 | AG17: 397.6106 | AH17: =AH16+AG17/Portfolio_by_bond[[#Totals],[Total Amount]] -> 0.28758533 | AI17: =Portfolio_by_bond[[#This Row],[Total Amount]]-_xlfn.XLOOKUP(Portfolio_by_bond[[#This Row],[Bond_Code]],'Ref'!F:F,'Ref'!G:G,0,0) -> 397.6106 | AJ17: =AJ16+AI17/(SUM(AI:AI)/2) -> 0.36607582 | AK17: =IF(AA17="",Z17,AA17) -> 6M-1Y
A18: 6M-1Y | B18: =_xlfn.SINGLE(_xlfn.XLOOKUP(A18,AM:AM,AN:AN,0,0)) -> 14089.1 | C18: =_xlfn.SINGLE(_xlfn.XLOOKUP(A18,AP:AP,AQ:AQ,0,0)) -> 17986.711 | K18: EIBV | L18: 1500 | M18: BB | N18: 46190 | Q18: B+ | R18: =R17+Portfolio_by_issuer[[#This Row],[Total Amount]]/Portfolio_by_issuer[[#Totals],[Total Amount]] -> 0.90881616 | S18: =_xlfn.XLOOKUP(Portfolio_by_issuer[[#This Row],[Issuer]],Rating!T:T,Rating!U:U,,0) -> BB | T18: =T17+Portfolio_by_issuer[[#This Row],[Total Amount]]/Portfolio_by_issuer[[#Totals],[Total Amount]] -> 0.90881616 | W18: HDBV | X18: NGAN HANG TMCP PHAT TRIEN TP HO CHI MINH | Y18: HDB12M261126 | Z18: 1-3M | AB18: AA | AC18: 46022 | AE18: B1 | AG18: 1500 | AH18: =AH17+AG18/Portfolio_by_bond[[#Totals],[Total Amount]] -> 0.32842542 | AI18: =Portfolio_by_bond[[#This Row],[Total Amount]]-_xlfn.XLOOKUP(Portfolio_by_bond[[#This Row],[Bond_Code]],'Ref'!F:F,'Ref'!G:G,0,0) -> 0 | AJ18: =AJ17+AI18/(SUM(AI:AI)/2) -> 0.36607582 | AK18: =IF(AA18="",Z18,AA18) -> 1-3M
A19: 1-2Y | B19: =_xlfn.SINGLE(_xlfn.XLOOKUP(A19,AM:AM,AN:AN,0,0)) -> 700 | C19: =_xlfn.SINGLE(_xlfn.XLOOKUP(A19,AP:AP,AQ:AQ,0,0)) -> 1700 | K19: TC_SHINSEI | L19: 1000 | M19: BB | N19: 45747 | O19: B+ | R19: =R18+Portfolio_by_issuer[[#This Row],[Total Amount]]/Portfolio_by_issuer[[#Totals],[Total Amount]] -> 0.93604253 | S19: =_xlfn.XLOOKUP(Portfolio_by_issuer[[#This Row],[Issuer]],Rating!T:T,Rating!U:U,,0) -> BB | T19: =T18+Portfolio_by_issuer[[#This Row],[Total Amount]]/Portfolio_by_issuer[[#Totals],[Total Amount]] -> 0.93604253 | W19: HDBV | X19: NGAN HANG TMCP PHAT TRIEN TP HO CHI MINH | Y19: HDB1CD031126 | Z19: 1-3M | AB19: AA | AC19: 46022 | AE19: B1 | AG19: 800 | AH19: =AH18+AG19/Portfolio_by_bond[[#Totals],[Total Amount]] -> 0.3502068 | AI19: =Portfolio_by_bond[[#This Row],[Total Amount]]-_xlfn.XLOOKUP(Portfolio_by_bond[[#This Row],[Bond_Code]],'Ref'!F:F,'Ref'!G:G,0,0) -> 800 | AJ19: =AJ18+AI19/(SUM(AI:AI)/2) -> 0.39380198 | AK19: =IF(AA19="",Z19,AA19) -> 1-3M
A20: 2-3Y | B20: =_xlfn.SINGLE(_xlfn.XLOOKUP(A20,AM:AM,AN:AN,0,0)) -> 3000 | C20: =_xlfn.SINGLE(_xlfn.XLOOKUP(A20,AP:AP,AQ:AQ,0,0)) -> 1000 | K20: VABV | L20: 600 | M20: BB | N20: 45792 | O20: B+ | P20: B2 | R20: =R19+Portfolio_by_issuer[[#This Row],[Total Amount]]/Portfolio_by_issuer[[#Totals],[Total Amount]] -> 0.95237835 | S20: =_xlfn.XLOOKUP(Portfolio_by_issuer[[#This Row],[Issuer]],Rating!T:T,Rating!U:U,,0) -> BB | T20: =T19+Portfolio_by_issuer[[#This Row],[Total Amount]]/Portfolio_by_issuer[[#Totals],[Total Amount]] -> 0.95237835 | W20: LVBT | X20: NGAN HANG TMCP LOC PHAT VN | Y20: LPB12407 | Z20: <1M | AA20: <1M | AB20: AA | AC20: 46199 | AE20: Ba3 | AG20: 1000 | AH20: =AH19+AG20/Portfolio_by_bond[[#Totals],[Total Amount]] -> 0.37743353 | AI20: =Portfolio_by_bond[[#This Row],[Total Amount]]-_xlfn.XLOOKUP(Portfolio_by_bond[[#This Row],[Bond_Code]],'Ref'!F:F,'Ref'!G:G,0,0) -> 1000 | AJ20: =AJ19+AI20/(SUM(AI:AI)/2) -> 0.42845968 | AK20: =IF(AA20="",Z20,AA20) -> <1M
A21: 3-5Y | B21: =_xlfn.SINGLE(_xlfn.XLOOKUP(A21,AM:AM,AN:AN,0,0)) -> 569.90402 | C21: =_xlfn.SINGLE(_xlfn.XLOOKUP(A21,AP:AP,AQ:AQ,0,0)) -> 569.90402 | K21: VCCB | L21: 250 | M21: BB | N21: 46209 | O21: B+ | R21: =R20+Portfolio_by_issuer[[#This Row],[Total Amount]]/Portfolio_by_issuer[[#Totals],[Total Amount]] -> 0.95918495 | S21: =_xlfn.XLOOKUP(Portfolio_by_issuer[[#This Row],[Issuer]],Rating!T:T,Rating!U:U,,0) -> BB | T21: =T20+Portfolio_by_issuer[[#This Row],[Total Amount]]/Portfolio_by_issuer[[#Totals],[Total Amount]] -> 0.95918495 | W21: TC_DIENLUC | X21: CONG TY TAI CHINH CO PHAN DIEN LUC | Y21: EVNFC160427 | Z21: 6M-1Y | AB21: AA | AC21: 46164 | AE21: B2 | AG21: 300 | AH21: =AH20+AG21/Portfolio_by_bond[[#Totals],[Total Amount]] -> 0.38560155 | AI21: =Portfolio_by_bond[[#This Row],[Total Amount]]-_xlfn.XLOOKUP(Portfolio_by_bond[[#This Row],[Bond_Code]],'Ref'!F:F,'Ref'!G:G,0,0) -> 300 | AJ21: =AJ20+AI21/(SUM(AI:AI)/2) -> 0.43885699 | AK21: =IF(AA21="",Z21,AA21) -> 6M-1Y
A22: 5-7Y | B22: =_xlfn.SINGLE(_xlfn.XLOOKUP(A22,AM:AM,AN:AN,0,0)) -> 3897.6106 | C22: =_xlfn.SINGLE(_xlfn.XLOOKUP(A22,AP:AP,AQ:AQ,0,0)) -> 1000 | K22: PVFC | L22: 1000 | M22: B | N22: 46218 | R22: =R21+Portfolio_by_issuer[[#This Row],[Total Amount]]/Portfolio_by_issuer[[#Totals],[Total Amount]] -> 0.98641132 | S22: =_xlfn.XLOOKUP(Portfolio_by_issuer[[#This Row],[Issuer]],Rating!T:T,Rating!U:U,,0) -> B | T22: =T21+Portfolio_by_issuer[[#This Row],[Total Amount]]/Portfolio_by_issuer[[#Totals],[Total Amount]] -> 0.98641132 | W22: TC_DIENLUC | X22: CONG TY TAI CHINH CO PHAN DIEN LUC | Y22: EVNFC260427 | Z22: 6M-1Y | AB22: AA | AC22: 46164 | AE22: B2 | AG22: 100 | AH22: =AH21+AG22/Portfolio_by_bond[[#Totals],[Total Amount]] -> 0.38832422 | AI22: =Portfolio_by_bond[[#This Row],[Total Amount]]-_xlfn.XLOOKUP(Portfolio_by_bond[[#This Row],[Bond_Code]],'Ref'!F:F,'Ref'!G:G,0,0) -> 100 | AJ22: =AJ21+AI22/(SUM(AI:AI)/2) -> 0.44232277 | AK22: =IF(AA22="",Z22,AA22) -> 6M-1Y
A23: >7Y | B23: =_xlfn.SINGLE(_xlfn.XLOOKUP(A23,AM:AM,AN:AN,0,0)) -> 0 | C23: =_xlfn.SINGLE(_xlfn.XLOOKUP(A23,AP:AP,AQ:AQ,0,0)) -> 0 | K23: OJBV | L23: 499.1 | M23: D | R23: =R22+Portfolio_by_issuer[[#This Row],[Total Amount]]/Portfolio_by_issuer[[#Totals],[Total Amount]] -> 1 | S23: =_xlfn.XLOOKUP(Portfolio_by_issuer[[#This Row],[Issuer]],Rating!T:T,Rating!U:U,,0) -> D | T23: =T22+Portfolio_by_issuer[[#This Row],[Total Amount]]/Portfolio_by_issuer[[#Totals],[Total Amount]] -> 1 | W23: TC_DIENLUC | X23: CONG TY TAI CHINH CO PHAN DIEN LUC | Y23: EVNFC170527 | Z23: 6M-1Y | AB23: AA | AC23: 46164 | AE23: B2 | AG23: 390 | AH23: =AH22+AG23/Portfolio_by_bond[[#Totals],[Total Amount]] -> 0.39894264 | AI23: =Portfolio_by_bond[[#This Row],[Total Amount]]-_xlfn.XLOOKUP(Portfolio_by_bond[[#This Row],[Bond_Code]],'Ref'!F:F,'Ref'!G:G,0,0) -> 390 | AJ23: =AJ22+AI23/(SUM(AI:AI)/2) -> 0.45583927 | AK23: =IF(AA23="",Z23,AA23) -> 6M-1Y
A24: Total | B24: =SUM(B15:B23) -> 36728.615 | C24: =SUM(C15:C23) -> 36728.615 | K24: Total | L24: =SUBTOTAL(109,Portfolio_by_issuer[Total Amount]) -> 36729.096 | W24: TC_DIENLUC | X24: CONG TY TAI CHINH CO PHAN DIEN LUC | Y24: EVNFC010227 | Z24: 3-6M | AB24: AA | AC24: 46164 | AE24: B2 | AG24: 57 | AH24: =AH23+AG24/Portfolio_by_bond[[#Totals],[Total Amount]] -> 0.40049457 | AI24: =Portfolio_by_bond[[#This Row],[Total Amount]]-_xlfn.XLOOKUP(Portfolio_by_bond[[#This Row],[Bond_Code]],'Ref'!F:F,'Ref'!G:G,0,0) -> 57 | AJ24: =AJ23+AI24/(SUM(AI:AI)/2) -> 0.45781476 | AK24: =IF(AA24="",Z24,AA24) -> 3-6M
W25: VPVN | X25: NGAN HANG TMCP VIET NAM THINH VUONG | Y25: VPBCD080427 | Z25: 6M-1Y | AB25: AA | AC25: 46142 | AE25: Ba3 | AG25: 400 | AH25: =AH24+AG25/Portfolio_by_bond[[#Totals],[Total Amount]] -> 0.41138526 | AI25: =Portfolio_by_bond[[#This Row],[Total Amount]]-_xlfn.XLOOKUP(Portfolio_by_bond[[#This Row],[Bond_Code]],'Ref'!F:F,'Ref'!G:G,0,0) -> 400 | AJ25: =AJ24+AI25/(SUM(AI:AI)/2) -> 0.47167784 | AK25: =IF(AA25="",Z25,AA25) -> 6M-1Y
W26: SABH | X26: NGAN HANG TMCP NAM A | Y26: NABCD041226 | Z26: 3-6M | AB26: A | AC26: 46141 | AD26: B+ | AE26: B2 | AG26: 1000 | AH26: =AH25+AG26/Portfolio_by_bond[[#Totals],[Total Amount]] -> 0.43861199 | AI26: =Portfolio_by_bond[[#This Row],[Total Amount]]-_xlfn.XLOOKUP(Portfolio_by_bond[[#This Row],[Bond_Code]],'Ref'!F:F,'Ref'!G:G,0,0) -> 1000 | AJ26: =AJ25+AI26/(SUM(AI:AI)/2) -> 0.50633554 | AK26: =IF(AA26="",Z26,AA26) -> 3-6M
W27: SABH | X27: NGAN HANG TMCP NAM A | Y27: NABCD200527 | Z27: 6M-1Y | AB27: A | AC27: 46141 | AD27: B+ | AE27: B2 | AG27: 2000 | AH27: =AH26+AG27/Portfolio_by_bond[[#Totals],[Total Amount]] -> 0.49306544 | AI27: =Portfolio_by_bond[[#This Row],[Total Amount]]-_xlfn.XLOOKUP(Portfolio_by_bond[[#This Row],[Bond_Code]],'Ref'!F:F,'Ref'!G:G,0,0) -> 2000 | AJ27: =AJ26+AI27/(SUM(AI:AI)/2) -> 0.57565095 | AK27: =IF(AA27="",Z27,AA27) -> 6M-1Y
W28: SHBV | X28: NGAN HANG TMCP SAI GON HA NOI | Y28: SHBL12601 | Z28: 5-7Y | AB28: A | AC28: 46211 | AD28: BB- | AE28: B1 | AG28: 1000 | AH28: =AH27+AG28/Portfolio_by_bond[[#Totals],[Total Amount]] -> 0.52029217 | AI28: =Portfolio_by_bond[[#This Row],[Total Amount]]-_xlfn.XLOOKUP(Portfolio_by_bond[[#This Row],[Bond_Code]],'Ref'!F:F,'Ref'!G:G,0,0) -> 1000 | AJ28: =AJ27+AI28/(SUM(AI:AI)/2) -> 0.61030865 | AK28: =IF(AA28="",Z28,AA28) -> 5-7Y
W29: SHBV | X29: NGAN HANG TMCP SAI GON HA NOI | Y29: SHB12503 | Z29: 5-7Y | AA29: 6M-1Y | AB29: A | AC29: 46211 | AD29: BB- | AE29: B1 | AG29: 500 | AH29: =AH28+AG29/Portfolio_by_bond[[#Totals],[Total Amount]] -> 0.53390553 | AI29: =Portfolio_by_bond[[#This Row],[Total Amount]]-_xlfn.XLOOKUP(Portfolio_by_bond[[#This Row],[Bond_Code]],'Ref'!F:F,'Ref'!G:G,0,0) -> 500 | AJ29: =AJ28+AI29/(SUM(AI:AI)/2) -> 0.6276375 | AK29: =IF(AA29="",Z29,AA29) -> 6M-1Y
W30: NABV | X30: NGAN HANG TMCP BAC A | Y30: BAB12603 | Z30: 6M-1Y | AA30: 6M-1Y | AB30: BBB | AC30: 46146 | AD30: B+ | AG30: 1000 | AH30: =AH29+AG30/Portfolio_by_bond[[#Totals],[Total Amount]] -> 0.56113226 | AI30: =Portfolio_by_bond[[#This Row],[Total Amount]]-_xlfn.XLOOKUP(Portfolio_by_bond[[#This Row],[Bond_Code]],'Ref'!F:F,'Ref'!G:G,0,0) -> 0 | AJ30: =AJ29+AI30/(SUM(AI:AI)/2) -> 0.6276375 | AK30: =IF(AA30="",Z30,AA30) -> 6M-1Y
W31: NABV | X31: NGAN HANG TMCP BAC A | Y31: BAB12601 | Z31: 6M-1Y | AA31: 6M-1Y | AB31: BBB | AC31: 46146 | AD31: B+ | AG31: 2000 | AH31: =AH30+AG31/Portfolio_by_bond[[#Totals],[Total Amount]] -> 0.61558572 | AI31: =Portfolio_by_bond[[#This Row],[Total Amount]]-_xlfn.XLOOKUP(Portfolio_by_bond[[#This Row],[Bond_Code]],'Ref'!F:F,'Ref'!G:G,0,0) -> 0 | AJ31: =AJ30+AI31/(SUM(AI:AI)/2) -> 0.6276375 | AK31: =IF(AA31="",Z31,AA31) -> 6M-1Y
W32: OCBV | X32: NGAN HANG TMCP PHUONG DONG | Y32: OCBCD241126 | Z32: 1-3M | AB32: BBB | AC32: 46206 | AE32: Ba3 | AG32: 2000 | AH32: =AH31+AG32/Portfolio_by_bond[[#Totals],[Total Amount]] -> 0.67003917 | AI32: =Portfolio_by_bond[[#This Row],[Total Amount]]-_xlfn.XLOOKUP(Portfolio_by_bond[[#This Row],[Bond_Code]],'Ref'!F:F,'Ref'!G:G,0,0) -> 0 | AJ32: =AJ31+AI32/(SUM(AI:AI)/2) -> 0.6276375 | AK32: =IF(AA32="",Z32,AA32) -> 1-3M
W33: OCBV | X33: NGAN HANG TMCP PHUONG DONG | Y33: OCBCD281026 | Z33: 1-3M | AB33: BBB | AC33: 46206 | AE33: Ba3 | AG33: 500 | AH33: =AH32+AG33/Portfolio_by_bond[[#Totals],[Total Amount]] -> 0.68365254 | AI33: =Portfolio_by_bond[[#This Row],[Total Amount]]-_xlfn.XLOOKUP(Portfolio_by_bond[[#This Row],[Bond_Code]],'Ref'!F:F,'Ref'!G:G,0,0) -> 500 | AJ33: =AJ32+AI33/(SUM(AI:AI)/2) -> 0.64496635 | AK33: =IF(AA33="",Z33,AA33) -> 1-3M
W34: EIBV | X34: NGAN HANG TMCP XUAT NHAP KHAU VN | Y34: EIBCD291026 | Z34: 1-3M | AB34: BB | AC34: 46190 | AF34: B+ | AG34: 500 | AH34: =AH33+AG34/Portfolio_by_bond[[#Totals],[Total Amount]] -> 0.6972659 | AI34: =Portfolio_by_bond[[#This Row],[Total Amount]]-_xlfn.XLOOKUP(Portfolio_by_bond[[#This Row],[Bond_Code]],'Ref'!F:F,'Ref'!G:G,0,0) -> 500 | AJ34: =AJ33+AI34/(SUM(AI:AI)/2) -> 0.6622952 | AK34: =IF(AA34="",Z34,AA34) -> 1-3M
W35: EIBV | X35: NGAN HANG TMCP XUAT NHAP KHAU VN | Y35: EIBCD240926 | Z35: <1M | AB35: BB | AC35: 46190 | AF35: B+ | AG35: 1000 | AH35: =AH34+AG35/Portfolio_by_bond[[#Totals],[Total Amount]] -> 0.72449263 | AI35: =Portfolio_by_bond[[#This Row],[Total Amount]]-_xlfn.XLOOKUP(Portfolio_by_bond[[#This Row],[Bond_Code]],'Ref'!F:F,'Ref'!G:G,0,0) -> 1000 | AJ35: =AJ34+AI35/(SUM(AI:AI)/2) -> 0.69695291 | AK35: =IF(AA35="",Z35,AA35) -> <1M
W36: TC_SHINSEI | X36: CONG TY TAI CHINH TNHH MB SHINSEI | Y36: MCCD240327 | Z36: 6M-1Y | AB36: BB | AC36: 45747 | AD36: B+ | AG36: 400 | AH36: =AH35+AG36/Portfolio_by_bond[[#Totals],[Total Amount]] -> 0.73538332 | AI36: =Portfolio_by_bond[[#This Row],[Total Amount]]-_xlfn.XLOOKUP(Portfolio_by_bond[[#This Row],[Bond_Code]],'Ref'!F:F,'Ref'!G:G,0,0) -> 400 | AJ36: =AJ35+AI36/(SUM(AI:AI)/2) -> 0.71081599 | AK36: =IF(AA36="",Z36,AA36) -> 6M-1Y
W37: TC_SHINSEI | X37: CONG TY TAI CHINH TNHH MB SHINSEI | Y37: MSF12404 | Z37: 3-6M | AB37: BB | AC37: 45747 | AD37: B+ | AG37: 400 | AH37: =AH36+AG37/Portfolio_by_bond[[#Totals],[Total Amount]] -> 0.74627401 | AI37: =Portfolio_by_bond[[#This Row],[Total Amount]]-_xlfn.XLOOKUP(Portfolio_by_bond[[#This Row],[Bond_Code]],'Ref'!F:F,'Ref'!G:G,0,0) -> 400 | AJ37: =AJ36+AI37/(SUM(AI:AI)/2) -> 0.72467907 | AK37: =IF(AA37="",Z37,AA37) -> 3-6M
W38: TC_SHINSEI | X38: CONG TY TAI CHINH TNHH MB SHINSEI | Y38: MCCD060827 | Z38: 6M-1Y | AB38: BB | AC38: 45747 | AD38: B+ | AG38: 200 | AH38: =AH37+AG38/Portfolio_by_bond[[#Totals],[Total Amount]] -> 0.75171936 | AI38: =Portfolio_by_bond[[#This Row],[Total Amount]]-_xlfn.XLOOKUP(Portfolio_by_bond[[#This Row],[Bond_Code]],'Ref'!F:F,'Ref'!G:G,0,0) -> 200 | AJ38: =AJ37+AI38/(SUM(AI:AI)/2) -> 0.73161061 | AK38: =IF(AA38="",Z38,AA38) -> 6M-1Y
W39: VABV | X39: NGAN HANG TMCP VIET A | Y39: VABCD190827 | Z39: 6M-1Y | AB39: BB | AC39: 45792 | AD39: B+ | AE39: B2 | AG39: 600 | AH39: =AH38+AG39/Portfolio_by_bond[[#Totals],[Total Amount]] -> 0.76805539 | AI39: =Portfolio_by_bond[[#This Row],[Total Amount]]-_xlfn.XLOOKUP(Portfolio_by_bond[[#This Row],[Bond_Code]],'Ref'!F:F,'Ref'!G:G,0,0) -> 600 | AJ39: =AJ38+AI39/(SUM(AI:AI)/2) -> 0.75240523 | AK39: =IF(AA39="",Z39,AA39) -> 6M-1Y
W40: VCCB | X40: NGAN HANG TMCP BAN VIET | Y40: VCCB1Y301026 | Z40: 1-3M | AB40: BB | AC40: 46209 | AD40: B+ | AG40: 250 | AH40: =AH39+AG40/Portfolio_by_bond[[#Totals],[Total Amount]] -> 0.77486208 | AI40: =Portfolio_by_bond[[#This Row],[Total Amount]]-_xlfn.XLOOKUP(Portfolio_by_bond[[#This Row],[Bond_Code]],'Ref'!F:F,'Ref'!G:G,0,0) -> 250 | AJ40: =AJ39+AI40/(SUM(AI:AI)/2) -> 0.76106966 | AK40: =IF(AA40="",Z40,AA40) -> 1-3M
...

Sheet Rating
A1: CPTY_NAME | B1: CPTY_CODE_ISSUER | C1: CPTY_TYPE | D1: FI_RATING | E1: FI_RATING_DATE | F1: FITCH_RATING | G1: FITCH_RATING_DATE | H1: MOODY_RATING | I1: MOODY_RATING_DATE | J1: SP_RATING | K1: SP_RATING_DATE | L1: Change Rating | M1: Chang rv date | N1: New Rating | P1: His | Q1: Month | R1: Year | S1: CptyName | T1: CptyCode | U1: FiRating | V1: FiRatingDate
A2: ZUERCHER KANTONAL BANK | B2: ZKB | C2: NHNN | D2: AAA | F2: AAA | H2: A1 | L2: =IF(OR(CtpyRating[[#This Row],[FI_RATING]]="",_xlfn.XLOOKUP(CtpyRating[[#This Row],[CPTY_NAME]],S:S,U:U,"",0)=CtpyRating[[#This Row],[FI_RATING]],CtpyRating[[#This Row],[New Rating]]="Yes"),"No","Yes") -> No | M2: =IF(OR(CtpyRating[[#This Row],[FI_RATING_DATE]]="",CtpyRating[[#This Row],[FI_RATING_DATE]]=_xlfn.XLOOKUP(CtpyRating[[#This Row],[CPTY_NAME]],S:S,V:V,"",0),CtpyRating[[#This Row],[New Rating]]="Yes"),"No","Yes") -> No | N2: =IF(AND(CtpyRating[[#This Row],[FI_RATING]]<>"",_xlfn.XLOOKUP(CtpyRating[[#This Row],[CPTY_NAME]],S:S,U:U,"",0)=""),"Yes","No") -> No | Q2: 8 | R2: 2026 | S2: NGAN HANG PHAT TRIEN VN | T2: VDB | U2: BB | V2: 45820
A3: WOORI BANK | B3: HVHB-VN | C3: NHNN | F3: A | G3: 45807 | H3: A1 | I3: 45889 | L3: =IF(OR(CtpyRating[[#This Row],[FI_RATING]]="",_xlfn.XLOOKUP(CtpyRating[[#This Row],[CPTY_NAME]],S:S,U:U,"",0)=CtpyRating[[#This Row],[FI_RATING]],CtpyRating[[#This Row],[New Rating]]="Yes"),"No","Yes") -> No | M3: =IF(OR(CtpyRating[[#This Row],[FI_RATING_DATE]]="",CtpyRating[[#This Row],[FI_RATING_DATE]]=_xlfn.XLOOKUP(CtpyRating[[#This Row],[CPTY_NAME]],S:S,V:V,"",0),CtpyRating[[#This Row],[New Rating]]="Yes"),"No","Yes") -> No | N3: =IF(AND(CtpyRating[[#This Row],[FI_RATING]]<>"",_xlfn.XLOOKUP(CtpyRating[[#This Row],[CPTY_NAME]],S:S,U:U,"",0)=""),"Yes","No") -> No | Q3: 8 | R3: 2026 | S3: NGAN HANG NONG NGHIEP VA PHAT TRIEN NONG THON | T3: VBAH | U3: AAA | V3: 46203
A4: WELLS FARGO NA | B4: WAHK-LDON | C4: NHNN | F4: AA- | G4: 45793 | H4: Aa2 | I4: 45978 | L4: =IF(OR(CtpyRating[[#This Row],[FI_RATING]]="",_xlfn.XLOOKUP(CtpyRating[[#This Row],[CPTY_NAME]],S:S,U:U,"",0)=CtpyRating[[#This Row],[FI_RATING]],CtpyRating[[#This Row],[New Rating]]="Yes"),"No","Yes") -> No | M4: =IF(OR(CtpyRating[[#This Row],[FI_RATING_DATE]]="",CtpyRating[[#This Row],[FI_RATING_DATE]]=_xlfn.XLOOKUP(CtpyRating[[#This Row],[CPTY_NAME]],S:S,V:V,"",0),CtpyRating[[#This Row],[New Rating]]="Yes"),"No","Yes") -> No | N4: =IF(AND(CtpyRating[[#This Row],[FI_RATING]]<>"",_xlfn.XLOOKUP(CtpyRating[[#This Row],[CPTY_NAME]],S:S,U:U,"",0)=""),"Yes","No") -> No | Q4: 8 | R4: 2026 | S4: NGAN HANG TMCP SAI GON HA NOI | T4: SHBV | U4: A | V4: 46211
A5: UNITED OVERSEA BANK LIMITED | B5: UOB_SING | C5: NHNN | H5: Aa1 | I5: 45979 | L5: =IF(OR(CtpyRating[[#This Row],[FI_RATING]]="",_xlfn.XLOOKUP(CtpyRating[[#This Row],[CPTY_NAME]],S:S,U:U,"",0)=CtpyRating[[#This Row],[FI_RATING]],CtpyRating[[#This Row],[New Rating]]="Yes"),"No","Yes") -> No | M5: =IF(OR(CtpyRating[[#This Row],[FI_RATING_DATE]]="",CtpyRating[[#This Row],[FI_RATING_DATE]]=_xlfn.XLOOKUP(CtpyRating[[#This Row],[CPTY_NAME]],S:S,V:V,"",0),CtpyRating[[#This Row],[New Rating]]="Yes"),"No","Yes") -> No | N5: =IF(AND(CtpyRating[[#This Row],[FI_RATING]]<>"",_xlfn.XLOOKUP(CtpyRating[[#This Row],[CPTY_NAME]],S:S,U:U,"",0)=""),"Yes","No") -> No | Q5: 8 | R5: 2026 | S5: NGAN HANG TMCP PHUONG DONG | T5: OCBV | U5: BBB | V5: 46206
A6: TRUNG TAM THONG TIN Y TE QUOC GIA | C6: LHK | D6: AAA | L6: =IF(OR(CtpyRating[[#This Row],[FI_RATING]]="",_xlfn.XLOOKUP(CtpyRating[[#This Row],[CPTY_NAME]],S:S,U:U,"",0)=CtpyRating[[#This Row],[FI_RATING]],CtpyRating[[#This Row],[New Rating]]="Yes"),"No","Yes") -> No | M6: =IF(OR(CtpyRating[[#This Row],[FI_RATING_DATE]]="",CtpyRating[[#This Row],[FI_RATING_DATE]]=_xlfn.XLOOKUP(CtpyRating[[#This Row],[CPTY_NAME]],S:S,V:V,"",0),CtpyRating[[#This Row],[New Rating]]="Yes"),"No","Yes") -> No | N6: =IF(AND(CtpyRating[[#This Row],[FI_RATING]]<>"",_xlfn.XLOOKUP(CtpyRating[[#This Row],[CPTY_NAME]],S:S,U:U,"",0)=""),"Yes","No") -> No | Q6: 8 | R6: 2026 | S6: NGAN HANG TMCP SAI GON | T6: SCBV | U6: CC | V6: 44781
A7: TONG CONG TY CP TAI BAO HIEM HA NOI | B7: TCT_TBHPVI | C7: CTBH | D7: A | E7: 45853 | L7: =IF(OR(CtpyRating[[#This Row],[FI_RATING]]="",_xlfn.XLOOKUP(CtpyRating[[#This Row],[CPTY_NAME]],S:S,U:U,"",0)=CtpyRating[[#This Row],[FI_RATING]],CtpyRating[[#This Row],[New Rating]]="Yes"),"No","Yes") -> No | M7: =IF(OR(CtpyRating[[#This Row],[FI_RATING_DATE]]="",CtpyRating[[#This Row],[FI_RATING_DATE]]=_xlfn.XLOOKUP(CtpyRating[[#This Row],[CPTY_NAME]],S:S,V:V,"",0),CtpyRating[[#This Row],[New Rating]]="Yes"),"No","Yes") -> No | N7: =IF(AND(CtpyRating[[#This Row],[FI_RATING]]<>"",_xlfn.XLOOKUP(CtpyRating[[#This Row],[CPTY_NAME]],S:S,U:U,"",0)=""),"Yes","No") -> No | Q7: 8 | R7: 2026 | S7: NGAN HANG TMCP QUOC DAN | T7: NCBV | U7: D | V7: 45730
A8: TONG CONG TY CP BAO MINH | B8: TCT_CPBM | C8: CTBH | D8: AAA | E8: 45981 | L8: =IF(OR(CtpyRating[[#This Row],[FI_RATING]]="",_xlfn.XLOOKUP(CtpyRating[[#This Row],[CPTY_NAME]],S:S,U:U,"",0)=CtpyRating[[#This Row],[FI_RATING]],CtpyRating[[#This Row],[New Rating]]="Yes"),"No","Yes") -> No | M8: =IF(OR(CtpyRating[[#This Row],[FI_RATING_DATE]]="",CtpyRating[[#This Row],[FI_RATING_DATE]]=_xlfn.XLOOKUP(CtpyRating[[#This Row],[CPTY_NAME]],S:S,V:V,"",0),CtpyRating[[#This Row],[New Rating]]="Yes"),"No","Yes") -> No | N8: =IF(AND(CtpyRating[[#This Row],[FI_RATING]]<>"",_xlfn.XLOOKUP(CtpyRating[[#This Row],[CPTY_NAME]],S:S,U:U,"",0)=""),"Yes","No") -> No | Q8: 8 | R8: 2026 | S8: NGAN HANG TMCP DONG NAM A | T8: SEAV | U8: A | V8: 45919
A9: THE SIAM COMMERCIAL BANK PUBLIC COMPANY LIMITED | B9: SIAMBANK | C9: NHNN | F9: BBB | G9: 45929 | H9: Baa1 | I9: 45995 | L9: =IF(OR(CtpyRating[[#This Row],[FI_RATING]]="",_xlfn.XLOOKUP(CtpyRating[[#This Row],[CPTY_NAME]],S:S,U:U,"",0)=CtpyRating[[#This Row],[FI_RATING]],CtpyRating[[#This Row],[New Rating]]="Yes"),"No","Yes") -> No | M9: =IF(OR(CtpyRating[[#This Row],[FI_RATING_DATE]]="",CtpyRating[[#This Row],[FI_RATING_DATE]]=_xlfn.XLOOKUP(CtpyRating[[#This Row],[CPTY_NAME]],S:S,V:V,"",0),CtpyRating[[#This Row],[New Rating]]="Yes"),"No","Yes") -> No | N9: =IF(AND(CtpyRating[[#This Row],[FI_RATING]]<>"",_xlfn.XLOOKUP(CtpyRating[[#This Row],[CPTY_NAME]],S:S,U:U,"",0)=""),"Yes","No") -> No | Q9: 8 | R9: 2026 | S9: NGAN HANG TMCP KIEN LONG | T9: KIENLONG | U9: BBB | V9: 45929
A10: THE GOVERNOR AND COMPANY OF THE BANK OF IRELAND | B10: IRELANDBANK | C10: NHNN | F10: A+ | G10: 46183 | H10: Aa3 | I10: 46133 | L10: =IF(OR(CtpyRating[[#This Row],[FI_RATING]]="",_xlfn.XLOOKUP(CtpyRating[[#This Row],[CPTY_NAME]],S:S,U:U,"",0)=CtpyRating[[#This Row],[FI_RATING]],CtpyRating[[#This Row],[New Rating]]="Yes"),"No","Yes") -> No | M10: =IF(OR(CtpyRating[[#This Row],[FI_RATING_DATE]]="",CtpyRating[[#This Row],[FI_RATING_DATE]]=_xlfn.XLOOKUP(CtpyRating[[#This Row],[CPTY_NAME]],S:S,V:V,"",0),CtpyRating[[#This Row],[New Rating]]="Yes"),"No","Yes") -> No | N10: =IF(AND(CtpyRating[[#This Row],[FI_RATING]]<>"",_xlfn.XLOOKUP(CtpyRating[[#This Row],[CPTY_NAME]],S:S,U:U,"",0)=""),"Yes","No") -> No | Q10: 8 | R10: 2026 | S10: NGAN HANG TMCP DAI CHUNG VN | T10: PVFC | U10: B | V10: 46218
A11: THE BANK OF NEW YORK MELLON | B11: BNYM | C11: NHNN | F11: AA | G11: 45730 | H11: Aa1 | I11: 45978 | L11: =IF(OR(CtpyRating[[#This Row],[FI_RATING]]="",_xlfn.XLOOKUP(CtpyRating[[#This Row],[CPTY_NAME]],S:S,U:U,"",0)=CtpyRating[[#This Row],[FI_RATING]],CtpyRating[[#This Row],[New Rating]]="Yes"),"No","Yes") -> No | M11: =IF(OR(CtpyRating[[#This Row],[FI_RATING_DATE]]="",CtpyRating[[#This Row],[FI_RATING_DATE]]=_xlfn.XLOOKUP(CtpyRating[[#This Row],[CPTY_NAME]],S:S,V:V,"",0),CtpyRating[[#This Row],[New Rating]]="Yes"),"No","Yes") -> No | N11: =IF(AND(CtpyRating[[#This Row],[FI_RATING]]<>"",_xlfn.XLOOKUP(CtpyRating[[#This Row],[CPTY_NAME]],S:S,U:U,"",0)=""),"Yes","No") -> No | Q11: 8 | R11: 2026 | S11: NGAN HANG TMCP TIEN PHONG | T11: TPBH | U11: A
A12: TCT TAI BAO HIEM QUOC GIA VN | B12: VINARE | C12: CTBH | D12: CC | L12: =IF(OR(CtpyRating[[#This Row],[FI_RATING]]="",_xlfn.XLOOKUP(CtpyRating[[#This Row],[CPTY_NAME]],S:S,U:U,"",0)=CtpyRating[[#This Row],[FI_RATING]],CtpyRating[[#This Row],[New Rating]]="Yes"),"No","Yes") -> No | M12: =IF(OR(CtpyRating[[#This Row],[FI_RATING_DATE]]="",CtpyRating[[#This Row],[FI_RATING_DATE]]=_xlfn.XLOOKUP(CtpyRating[[#This Row],[CPTY_NAME]],S:S,V:V,"",0),CtpyRating[[#This Row],[New Rating]]="Yes"),"No","Yes") -> No | N12: =IF(AND(CtpyRating[[#This Row],[FI_RATING]]<>"",_xlfn.XLOOKUP(CtpyRating[[#This Row],[CPTY_NAME]],S:S,U:U,"",0)=""),"Yes","No") -> No | Q12: 8 | R12: 2026 | S12: NGAN HANG TMCP NAM A | T12: SABH | U12: A | V12: 46141
A13: TCT CP TAI BAO HIEM PVI | B13: TBH_PVI | C13: CTBH | D13: CC | L13: =IF(OR(CtpyRating[[#This Row],[FI_RATING]]="",_xlfn.XLOOKUP(CtpyRating[[#This Row],[CPTY_NAME]],S:S,U:U,"",0)=CtpyRating[[#This Row],[FI_RATING]],CtpyRating[[#This Row],[New Rating]]="Yes"),"No","Yes") -> No | M13: =IF(OR(CtpyRating[[#This Row],[FI_RATING_DATE]]="",CtpyRating[[#This Row],[FI_RATING_DATE]]=_xlfn.XLOOKUP(CtpyRating[[#This Row],[CPTY_NAME]],S:S,V:V,"",0),CtpyRating[[#This Row],[New Rating]]="Yes"),"No","Yes") -> No | N13: =IF(AND(CtpyRating[[#This Row],[FI_RATING]]<>"",_xlfn.XLOOKUP(CtpyRating[[#This Row],[CPTY_NAME]],S:S,U:U,"",0)=""),"Yes","No") -> No | Q13: 8 | R13: 2026 | S13: NGAN HANG TMCP VIET A | T13: VABV | U13: BB | V13: 45792
A14: TCT CP BAO HIEM BUU DIEN PTI | B14: BH_BUUDIEN | C14: CTBH | D14: AAA | E14: 45917 | L14: =IF(OR(CtpyRating[[#This Row],[FI_RATING]]="",_xlfn.XLOOKUP(CtpyRating[[#This Row],[CPTY_NAME]],S:S,U:U,"",0)=CtpyRating[[#This Row],[FI_RATING]],CtpyRating[[#This Row],[New Rating]]="Yes"),"No","Yes") -> No | M14: =IF(OR(CtpyRating[[#This Row],[FI_RATING_DATE]]="",CtpyRating[[#This Row],[FI_RATING_DATE]]=_xlfn.XLOOKUP(CtpyRating[[#This Row],[CPTY_NAME]],S:S,V:V,"",0),CtpyRating[[#This Row],[New Rating]]="Yes"),"No","Yes") -> No | N14: =IF(AND(CtpyRating[[#This Row],[FI_RATING]]<>"",_xlfn.XLOOKUP(CtpyRating[[#This Row],[CPTY_NAME]],S:S,U:U,"",0)=""),"Yes","No") -> No | Q14: 8 | R14: 2026 | S14: NGAN HANG TMCP BAN VIET | T14: VCCB | U14: BB | V14: 46209
A15: TCT CP BAO HIEM BAO LONG | B15: BAOLONG | C15: CTBH | D15: CCC+ | L15: =IF(OR(CtpyRating[[#This Row],[FI_RATING]]="",_xlfn.XLOOKUP(CtpyRating[[#This Row],[CPTY_NAME]],S:S,U:U,"",0)=CtpyRating[[#This Row],[FI_RATING]],CtpyRating[[#This Row],[New Rating]]="Yes"),"No","Yes") -> No | M15: =IF(OR(CtpyRating[[#This Row],[FI_RATING_DATE]]="",CtpyRating[[#This Row],[FI_RATING_DATE]]=_xlfn.XLOOKUP(CtpyRating[[#This Row],[CPTY_NAME]],S:S,V:V,"",0),CtpyRating[[#This Row],[New Rating]]="Yes"),"No","Yes") -> No | N15: =IF(AND(CtpyRating[[#This Row],[FI_RATING]]<>"",_xlfn.XLOOKUP(CtpyRating[[#This Row],[CPTY_NAME]],S:S,U:U,"",0)=""),"Yes","No") -> No | Q15: 8 | R15: 2026 | S15: NGAN HANG TMCP SAI GON CONG THUONG | T15: SGCT | U15: CCC | V15: 46157
A16: TCT BAO VIET NHAN THO | B16: BAOVIETLIF | C16: CTBH | D16: D | L16: =IF(OR(CtpyRating[[#This Row],[FI_RATING]]="",_xlfn.XLOOKUP(CtpyRating[[#This Row],[CPTY_NAME]],S:S,U:U,"",0)=CtpyRating[[#This Row],[FI_RATING]],CtpyRating[[#This Row],[New Rating]]="Yes"),"No","Yes") -> No | M16: =IF(OR(CtpyRating[[#This Row],[FI_RATING_DATE]]="",CtpyRating[[#This Row],[FI_RATING_DATE]]=_xlfn.XLOOKUP(CtpyRating[[#This Row],[CPTY_NAME]],S:S,V:V,"",0),CtpyRating[[#This Row],[New Rating]]="Yes"),"No","Yes") -> No | N16: =IF(AND(CtpyRating[[#This Row],[FI_RATING]]<>"",_xlfn.XLOOKUP(CtpyRating[[#This Row],[CPTY_NAME]],S:S,U:U,"",0)=""),"Yes","No") -> No | Q16: 8 | R16: 2026 | S16: NGAN HANG TMCP BAC A | T16: NABV | U16: BBB | V16: 46146
A17: TCT BAO HIEM PVI | B17: PVI | C17: CTBH | D17: AAA | E17: 45961 | L17: =IF(OR(CtpyRating[[#This Row],[FI_RATING]]="",_xlfn.XLOOKUP(CtpyRating[[#This Row],[CPTY_NAME]],S:S,U:U,"",0)=CtpyRating[[#This Row],[FI_RATING]],CtpyRating[[#This Row],[New Rating]]="Yes"),"No","Yes") -> No | M17: =IF(OR(CtpyRating[[#This Row],[FI_RATING_DATE]]="",CtpyRating[[#This Row],[FI_RATING_DATE]]=_xlfn.XLOOKUP(CtpyRating[[#This Row],[CPTY_NAME]],S:S,V:V,"",0),CtpyRating[[#This Row],[New Rating]]="Yes"),"No","Yes") -> No | N17: =IF(AND(CtpyRating[[#This Row],[FI_RATING]]<>"",_xlfn.XLOOKUP(CtpyRating[[#This Row],[CPTY_NAME]],S:S,U:U,"",0)=""),"Yes","No") -> No | Q17: 8 | R17: 2026 | S17: NGAN HANG TMCP BAO VIET | T17: BVBH | U17: CC | V17: 46189
A18: TCT BAO HIEM PJICO | B18: BH_PJICO | C18: CTBH | D18: CCC+ | L18: =IF(OR(CtpyRating[[#This Row],[FI_RATING]]="",_xlfn.XLOOKUP(CtpyRating[[#This Row],[CPTY_NAME]],S:S,U:U,"",0)=CtpyRating[[#This Row],[FI_RATING]],CtpyRating[[#This Row],[New Rating]]="Yes"),"No","Yes") -> No | M18: =IF(OR(CtpyRating[[#This Row],[FI_RATING_DATE]]="",CtpyRating[[#This Row],[FI_RATING_DATE]]=_xlfn.XLOOKUP(CtpyRating[[#This Row],[CPTY_NAME]],S:S,V:V,"",0),CtpyRating[[#This Row],[New Rating]]="Yes"),"No","Yes") -> No | N18: =IF(AND(CtpyRating[[#This Row],[FI_RATING]]<>"",_xlfn.XLOOKUP(CtpyRating[[#This Row],[CPTY_NAME]],S:S,U:U,"",0)=""),"Yes","No") -> No | Q18: 8 | R18: 2026 | S18: NGAN HANG LIEN DOANH VIET NGA | T18: VRB | U18: BB | V18: 44326
A19: TCT BAO HIEM BAO VIET | B19: BH_BAOVIET | C19: CTBH | D19: D | L19: =IF(OR(CtpyRating[[#This Row],[FI_RATING]]="",_xlfn.XLOOKUP(CtpyRating[[#This Row],[CPTY_NAME]],S:S,U:U,"",0)=CtpyRating[[#This Row],[FI_RATING]],CtpyRating[[#This Row],[New Rating]]="Yes"),"No","Yes") -> No | M19: =IF(OR(CtpyRating[[#This Row],[FI_RATING_DATE]]="",CtpyRating[[#This Row],[FI_RATING_DATE]]=_xlfn.XLOOKUP(CtpyRating[[#This Row],[CPTY_NAME]],S:S,V:V,"",0),CtpyRating[[#This Row],[New Rating]]="Yes"),"No","Yes") -> No | N19: =IF(AND(CtpyRating[[#This Row],[FI_RATING]]<>"",_xlfn.XLOOKUP(CtpyRating[[#This Row],[CPTY_NAME]],S:S,U:U,"",0)=""),"Yes","No") -> No | Q19: 8 | R19: 2026 | S19: NGAN HANG TNHH MTV PUBLIC VN | T19: PBVN | U19: BB | V19: 45782
A20: TAP DOAN BAO VIET | B20: TD_BAOVIET | C20: CTBH | D20: CCC+ | L20: =IF(OR(CtpyRating[[#This Row],[FI_RATING]]="",_xlfn.XLOOKUP(CtpyRating[[#This Row],[CPTY_NAME]],S:S,U:U,"",0)=CtpyRating[[#This Row],[FI_RATING]],CtpyRating[[#This Row],[New Rating]]="Yes"),"No","Yes") -> No | M20: =IF(OR(CtpyRating[[#This Row],[FI_RATING_DATE]]="",CtpyRating[[#This Row],[FI_RATING_DATE]]=_xlfn.XLOOKUP(CtpyRating[[#This Row],[CPTY_NAME]],S:S,V:V,"",0),CtpyRating[[#This Row],[New Rating]]="Yes"),"No","Yes") -> No | N20: =IF(AND(CtpyRating[[#This Row],[FI_RATING]]<>"",_xlfn.XLOOKUP(CtpyRating[[#This Row],[CPTY_NAME]],S:S,U:U,"",0)=""),"Yes","No") -> No | Q20: 8 | R20: 2026 | S20: NGAN HANG TNHH MTV CIMB VN | T20: CIMB-VN | U20: BB | V20: 46169
A21: TAIPEI FUBON COMMERCIAL BANK | C21: NHNN | H21: A1 | I21: 45827 | L21: =IF(OR(CtpyRating[[#This Row],[FI_RATING]]="",_xlfn.XLOOKUP(CtpyRating[[#This Row],[CPTY_NAME]],S:S,U:U,"",0)=CtpyRating[[#This Row],[FI_RATING]],CtpyRating[[#This Row],[New Rating]]="Yes"),"No","Yes") -> No | M21: =IF(OR(CtpyRating[[#This Row],[FI_RATING_DATE]]="",CtpyRating[[#This Row],[FI_RATING_DATE]]=_xlfn.XLOOKUP(CtpyRating[[#This Row],[CPTY_NAME]],S:S,V:V,"",0),CtpyRating[[#This Row],[New Rating]]="Yes"),"No","Yes") -> No | N21: =IF(AND(CtpyRating[[#This Row],[FI_RATING]]<>"",_xlfn.XLOOKUP(CtpyRating[[#This Row],[CPTY_NAME]],S:S,U:U,"",0)=""),"Yes","No") -> No | Q21: 8 | R21: 2026 | S21: NGAN HANG TNHH INDOVINA | T21: IVB | U21: B | V21: 46183
A22: SUMITOMO MITSUI BANKING CORPORATION | B22: SMHN | C22: NHNN | F22: A | G22: 45945 | H22: A1 | I22: 45979 | L22: =IF(OR(CtpyRating[[#This Row],[FI_RATING]]="",_xlfn.XLOOKUP(CtpyRating[[#This Row],[CPTY_NAME]],S:S,U:U,"",0)=CtpyRating[[#This Row],[FI_RATING]],CtpyRating[[#This Row],[New Rating]]="Yes"),"No","Yes") -> No | M22: =IF(OR(CtpyRating[[#This Row],[FI_RATING_DATE]]="",CtpyRating[[#This Row],[FI_RATING_DATE]]=_xlfn.XLOOKUP(CtpyRating[[#This Row],[CPTY_NAME]],S:S,V:V,"",0),CtpyRating[[#This Row],[New Rating]]="Yes"),"No","Yes") -> No | N22: =IF(AND(CtpyRating[[#This Row],[FI_RATING]]<>"",_xlfn.XLOOKUP(CtpyRating[[#This Row],[CPTY_NAME]],S:S,U:U,"",0)=""),"Yes","No") -> No | Q22: 8 | R22: 2026 | S22: CONG TY TAI CHINH CO PHAN DIEN LUC | T22: TC_DIENLUC | U22: AA | V22: 46164
A23: STANDARD CHARTERED BANK | B23: SCHN-LD | C23: NHNN | H23: Aa1 | I23: 45985 | L23: =IF(OR(CtpyRating[[#This Row],[FI_RATING]]="",_xlfn.XLOOKUP(CtpyRating[[#This Row],[CPTY_NAME]],S:S,U:U,"",0)=CtpyRating[[#This Row],[FI_RATING]],CtpyRating[[#This Row],[New Rating]]="Yes"),"No","Yes") -> No | M23: =IF(OR(CtpyRating[[#This Row],[FI_RATING_DATE]]="",CtpyRating[[#This Row],[FI_RATING_DATE]]=_xlfn.XLOOKUP(CtpyRating[[#This Row],[CPTY_NAME]],S:S,V:V,"",0),CtpyRating[[#This Row],[New Rating]]="Yes"),"No","Yes") -> No | N23: =IF(AND(CtpyRating[[#This Row],[FI_RATING]]<>"",_xlfn.XLOOKUP(CtpyRating[[#This Row],[CPTY_NAME]],S:S,U:U,"",0)=""),"Yes","No") -> No | Q23: 8 | R23: 2026 | S23: NGAN HANG TMCP VIET NAM THUONG TIN | T23: VIETBANK | U23: BB | V23: 46128
A24: SAXO BANK A/S | B24: SAXOBANK | C24: NHNN | J24: A- | K24: 45820 | L24: =IF(OR(CtpyRating[[#This Row],[FI_RATING]]="",_xlfn.XLOOKUP(CtpyRating[[#This Row],[CPTY_NAME]],S:S,U:U,"",0)=CtpyRating[[#This Row],[FI_RATING]],CtpyRating[[#This Row],[New Rating]]="Yes"),"No","Yes") -> No | M24: =IF(OR(CtpyRating[[#This Row],[FI_RATING_DATE]]="",CtpyRating[[#This Row],[FI_RATING_DATE]]=_xlfn.XLOOKUP(CtpyRating[[#This Row],[CPTY_NAME]],S:S,V:V,"",0),CtpyRating[[#This Row],[New Rating]]="Yes"),"No","Yes") -> No | N24: =IF(AND(CtpyRating[[#This Row],[FI_RATING]]<>"",_xlfn.XLOOKUP(CtpyRating[[#This Row],[CPTY_NAME]],S:S,U:U,"",0)=""),"Yes","No") -> No | Q24: 8 | R24: 2026 | S24: NGAN HANG TMCP LOC PHAT VN | T24: LVBT | U24: AA | V24: 46199
A25: RAIFFEISEN BANK INTERNATIONAL | B25: RBI | C25: NHNN | D25: BBB | H25: A3 | J25: A- | L25: =IF(OR(CtpyRating[[#This Row],[FI_RATING]]="",_xlfn.XLOOKUP(CtpyRating[[#This Row],[CPTY_NAME]],S:S,U:U,"",0)=CtpyRating[[#This Row],[FI_RATING]],CtpyRating[[#This Row],[New Rating]]="Yes"),"No","Yes") -> No | M25: =IF(OR(CtpyRating[[#This Row],[FI_RATING_DATE]]="",CtpyRating[[#This Row],[FI_RATING_DATE]]=_xlfn.XLOOKUP(CtpyRating[[#This Row],[CPTY_NAME]],S:S,V:V,"",0),CtpyRating[[#This Row],[New Rating]]="Yes"),"No","Yes") -> No | N25: =IF(AND(CtpyRating[[#This Row],[FI_RATING]]<>"",_xlfn.XLOOKUP(CtpyRating[[#This Row],[CPTY_NAME]],S:S,U:U,"",0)=""),"Yes","No") -> No | Q25: 8 | R25: 2026 | S25: NGAN HANG TMCP VIET NAM THINH VUONG | T25: VPVN | U25: AA | V25: 46142
A26: QUOC GIA KYRGYZ REPUBLIC | B26: MFKR | C26: QG | D26: BBB | F26: B | G26: 46132 | H26: B3 | I26: 45849 | J26: B+ | K26: 45744 | L26: No | M26: =IF(OR(CtpyRating[[#This Row],[FI_RATING_DATE]]="",CtpyRating[[#This Row],[FI_RATING_DATE]]=_xlfn.XLOOKUP(CtpyRating[[#This Row],[CPTY_NAME]],S:S,V:V,"",0),CtpyRating[[#This Row],[New Rating]]="Yes"),"No","Yes") -> No | N26: No | Q26: 8 | R26: 2026 | S26: NGAN HANG TMCP NGOAI THUONG VN | T26: VCBH | U26: AAA | V26: 46196
A27: PHONGSAVANH BANK LIMITED | B27: PHONGSAVANH | C27: NHNN | D27: D | E27: 45875 | L27: =IF(OR(CtpyRating[[#This Row],[FI_RATING]]="",_xlfn.XLOOKUP(CtpyRating[[#This Row],[CPTY_NAME]],S:S,U:U,"",0)=CtpyRating[[#This Row],[FI_RATING]],CtpyRating[[#This Row],[New Rating]]="Yes"),"No","Yes") -> No | M27: =IF(OR(CtpyRating[[#This Row],[FI_RATING_DATE]]="",CtpyRating[[#This Row],[FI_RATING_DATE]]=_xlfn.XLOOKUP(CtpyRating[[#This Row],[CPTY_NAME]],S:S,V:V,"",0),CtpyRating[[#This Row],[New Rating]]="Yes"),"No","Yes") -> No | N27: =IF(AND(CtpyRating[[#This Row],[FI_RATING]]<>"",_xlfn.XLOOKUP(CtpyRating[[#This Row],[CPTY_NAME]],S:S,U:U,"",0)=""),"Yes","No") -> No | Q27: 8 | R27: 2026 | S27: NGAN HANG TMCP DAU TU VA PHAT TRIEN VN | T27: BIDV | U27: AAA
A28: NONGHYUP BANK | B28: NONGHYUP | C28: NHNN | F28: A | G28: 45952 | H28: Aa3 | I28: 45953 | L28: =IF(OR(CtpyRating[[#This Row],[FI_RATING]]="",_xlfn.XLOOKUP(CtpyRating[[#This Row],[CPTY_NAME]],S:S,U:U,"",0)=CtpyRating[[#This Row],[FI_RATING]],CtpyRating[[#This Row],[New Rating]]="Yes"),"No","Yes") -> No | M28: =IF(OR(CtpyRating[[#This Row],[FI_RATING_DATE]]="",CtpyRating[[#This Row],[FI_RATING_DATE]]=_xlfn.XLOOKUP(CtpyRating[[#This Row],[CPTY_NAME]],S:S,V:V,"",0),CtpyRating[[#This Row],[New Rating]]="Yes"),"No","Yes") -> No | N28: =IF(AND(CtpyRating[[#This Row],[FI_RATING]]<>"",_xlfn.XLOOKUP(CtpyRating[[#This Row],[CPTY_NAME]],S:S,U:U,"",0)=""),"Yes","No") -> No | Q28: 8 | R28: 2026 | S28: NGAN HANG TMCP CONG THUONG VN | T28: ICBV | U28: AAA | V28: 45859
A29: NGAN HANG TNHH MTV WOORI VIET NAM | B29: HVHB-VN | C29: Local Bank | D29: AA | E29: 46197 | L29: =IF(OR(CtpyRating[[#This Row],[FI_RATING]]="",_xlfn.XLOOKUP(CtpyRating[[#This Row],[CPTY_NAME]],S:S,U:U,"",0)=CtpyRating[[#This Row],[FI_RATING]],CtpyRating[[#This Row],[New Rating]]="Yes"),"No","Yes") -> No | M29: =IF(OR(CtpyRating[[#This Row],[FI_RATING_DATE]]="",CtpyRating[[#This Row],[FI_RATING_DATE]]=_xlfn.XLOOKUP(CtpyRating[[#This Row],[CPTY_NAME]],S:S,V:V,"",0),CtpyRating[[#This Row],[New Rating]]="Yes"),"No","Yes") -> No | N29: =IF(AND(CtpyRating[[#This Row],[FI_RATING]]<>"",_xlfn.XLOOKUP(CtpyRating[[#This Row],[CPTY_NAME]],S:S,U:U,"",0)=""),"Yes","No") -> No | Q29: 8 | R29: 2026 | S29: NGAN HANG TMCP QUAN DOI | T29: MCSB | U29: AAA | V29: 46136
