Workbook
Name AL: 'His53'!$AG$2
Name as: FNRP!$D$2
Name F: AllDealps!#REF!
Name ITB_Amt: Summary!$DB$1
Name Last14D: Runtool!$C$6
Name Lastmonth: Runtool!$C$4
Name lastweek: Runtool!$C$17
Name Lastyear: Runtool!$C$5
Name LIQ03_: GL!$K$6
Name Quarter1: Runtool!$C$21
Name Quarter2: Runtool!$C$22
Name Quarter3: Runtool!$C$23
Name Quarter4: Runtool!$C$24
Name RPT: Runtool!$C$2
Name u: Dao_han[PRODUCT_CODE]
Name Yesterday: Runtool!$C$3

Sheet Scripts
A1: Query Name | B1: M Code
A2: Param | B2: let_x000D_ Source = (TableName,RowNumber) => let Source = Excel.CurrentWorkbook(){[Name=TableName]}[Content], value = Source{RowNumber-1}[Values] in value_x000D_ in_x000D_ Source
A3: FNRP_FIbond | B3: let_x000D_ Source = Csv.Document(File.Contents(Param("Input",8)),[Delimiter=",", Columns=87, Encoding=1252, QuoteStyle=QuoteStyle.None]),_x000D_ #"Changed Type" = Table.TransformColumnTypes(Source,{{"Column1", type text}, {"Column2", type text}, {"Column3", type text}, {"Column4", type text}, {"Column5", type text}, {"Column6", type text}, {"Column7", type text}, {"Column8", type text}, {"Column9", type text}, {"Column10", type number}, {"Column11", type number}, {"Column12", Int64.Type}, {"Column13", Int64.Type}, {"Column14", Int64.Type}, {"Column15", type number}, {"Column16", type number}, {"Column17", type number}, {"Column18", Int64.Type}, {"Column19", Int64.Type}, {"Column20", Int64.Type}, {"Column21", type number}, {"Column22", type number}, {"Column23", type number}, {"Column24", type number}, {"Column25", type number}, {"Column26", type number}, {"Column27", type number}, {"Column28", type number}, {"Column29", type number}, {"Column30", Int64.Type}, {"Column31", Int64.Type}, {"Column32", type number}, {"Column33", Int64.Type}, {"Column34", type number}, {"Column35", type number}, {"Column36", type number}, {"Column37", Int64.Type}, {"Column38", type number}, {"Column39", type number}, {"Column40", type number}, {"Column41", type number}, {"Column42", Int64.Type}, {"Column43", type number}, {"Column44", type number}, {"Column45", type number}, {"Column46", type number}, {"Column47", type number}, {"Column48", Int64.Type}, {"Column49", type number}, {"Column50", Int64.Type}, {"Column51", Int64.Type}, {"Column52", Int64.Type}, {"Column53", type text}, {"Column54", type text}, {"Column55", type text}, {"Column56", type text}, {"Column57", type text}, {"Column58", Int64.Type}, {"Column59", Int64.Type}, {"Column60", Int64.Type}, {"Column61", Int64.Type}, {"Column62", Int64.Type}, {"Column63", Int64.Type}, {"Column64", Int64.Type}, {"Column65", Int64.Type}, {"Column66", Int64.Type}, {"Column67", Int64.Type}, {"Column68", Int64.Type}, {"Column69", Int64.Type}, {"Column70", Int64.Type}, {"Column71", Int64.Type}, {"Column72", type number}, {"Column73", Int64.Type}, {"Column74", type text}, {"Column75", type text}, {"Column76", type text}, {"Column77", type text}, {"Column78", type text}, {"Column79", type text}, {"Column80", type text}, {"Column81", type number}, {"Column82", type number}, {"Column83", type number}, {"Column84", type number}, {"Column85", type number}, {"Column86", type number}, {"Column87", Int64.Type}}),_x000D_ #"Renamed Columns" = Table.RenameColumns(#"Changed Type",{{"Column1", "Currency"}, {"Column2", "Duration_range"}, {"Column3", "Short Name"}, {"Column5", "Type of Instr."}, {"Column8", "Mat. Date"}, {"Column9", "Open Pos"}, {"Column10", "Price"}, {"Column11", "Clean Price"}, {"Column14", "Quantity"}, {"Column15", "Nominal"}, {"Column16", "Orig. Nominal"}, {"Column17", "Avg Price"}, {"Column20", "Flt. Spread"}, {"Column21", "Pos. Yield"}, {"Column22", "Pos. True Yield"}, {"Column23", "Avg Yield"}, {"Column24", "Market Value"}, {"Column25", "Cpn Rate"}, {"Column26", "Accr Int"}, {"Column27", "% Sec"}, {"Column28", "Cpn Cumul"}, {"Column29", "Cpn Reinvested"}, {"Column32", "Cost of Carry"}, {"Column34", "Var. Accr"}, {"Column35", "Global Carry"}, {"Column36", "Net Carry"}, {"Column43", "Mod Dur"}, {"Column44", "Dur."}, {"Column45", "Cnvx."}, {"Column47", "BPV (K)"}, {"Column81", "Realized Cur"}, {"Column82", "Unrealized Cur"}, {"Column83", "P/L Clean Price"}, {"Column84", "P/L Currency"}, {"Column85", "P/L Local"}, {"Column86", "P/L Report"}}),_x000D_ #"Removed Other Columns" = Table.SelectColumns(#"Renamed Columns",{"Currency", "Duration_range", "Short Name", "Type of Instr.", "Mat. Date", "Open Pos", "Clean Price", "Quantity", "Nominal", "Orig. Nominal", "Avg Price", "Flt. Spread", "Pos. Yield", "Pos. True Yield", "Avg Yield", "Market Value", "Cpn Rate", "Accr Int", "% Sec", "Cpn Cumul", "Cpn Reinvested", "Cost of Carry", "Var. Accr", "Global Carry", "Net Carry", "Mod Dur", "Dur.", "Cnvx.", "BPV (K)", "Realized Cur", "Unrealized Cur", "P/L Clean Price"}),_x000D_ #"Filtered Rows" = Table.SelectRows(#"Removed Other Columns", each not Text.Contains([Short Name], "MSB"))_x000D_ in_x000D_ #"Filtered Rows"
A4: FNRP_PPCD | B4: let_x000D_ Source = Csv.Document(File.Contents(Param("Input",9)),[Delimiter=",", Columns=87, Encoding=1252, QuoteStyle=QuoteStyle.None]),_x000D_ #"Changed Type" = Table.TransformColumnTypes(Source,{{"Column1", type text}, {"Column2", type text}, {"Column3", type text}, {"Column4", type text}, {"Column5", type text}, {"Column6", type text}, {"Column7", type text}, {"Column8", type text}, {"Column9", type text}, {"Column10", type text}, {"Column11", type text}, {"Column12", type number}, {"Column13", type text}, {"Column14", type number}, {"Column15", type text}, {"Column16", type text}, {"Column17", type text}, {"Column18", type number}, {"Column19", Int64.Type}, {"Column20", Int64.Type}, {"Column21", Int64.Type}, {"Column22", Int64.Type}, {"Column23", Int64.Type}, {"Column24", Int64.Type}, {"Column25", type number}, {"Column26", type number}, {"Column27", type number}, {"Column28", Int64.Type}, {"Column29", Int64.Type}, {"Column30", type number}, {"Column31", type number}, {"Column32", Int64.Type}, {"Column33", type number}, {"Column34", type number}, {"Column35", type number}, {"Column36", type number}, {"Column37", Int64.Type}, {"Column38", type number}, {"Column39", type number}, {"Column40", type number}, {"Column41", type number}, {"Column42", type number}, {"Column43", type number}, {"Column44", Int64.Type}, {"Column45", type number}, {"Column46", Int64.Type}, {"Column47", Int64.Type}, {"Column48", Int64.Type}, {"Column49", type number}, {"Column50", type number}, {"Column51", type number}, {"Column52", Int64.Type}}),_x000D_ #"Renamed Columns" = Table.RenameColumns(#"Changed Type",{{"Column2", "Book"}, {"Column3", "Duration_range"}, {"Column4", "Short Name"}, {"Column7", "Instrument"}, {"Column8", "Type of Instr."}, {"Column10", "Mat. Date"}, {"Column11", "Type Rate"}, {"Column12", "Cpn Rate"}, {"Column13", "Open Pos"}, {"Column14", "Clean Price"}, {"Column18", "Nominal"}, {"Column25", "Market Value"}, {"Column26", "Cpn Cumul"}, {"Column27", "Cpn Reinvested"}, {"Column30", "Cost of Carry"}, {"Column34", "Accrued"}, {"Column38", "Mod Dur"}, {"Column39", "Dur."}, {"Column40", "Cnvx."}, {"Column49", "P/L Currency"}, {"Column50", "P/L Local"}, {"Column51", "P/L Report"}}),_x000D_ #"Removed Other Columns" = Table.SelectColumns(#"Renamed Columns",{"Book", "Duration_range", "Short Name", "Instrument", "Type of Instr.", "Mat. Date", "Type Rate", "Cpn Rate", "Open Pos", "Clean Price", "Nominal", "Market Value", "Cpn Cumul", "Cpn Reinvested", "Cost of Carry", "Mod Dur", "Dur.", "Cnvx.", "P/L Currency", "P/L Local", "P/L Report"}),_x000D_ #"Filtered Rows" = Table.SelectRows(#"Removed Other Columns", each not Text.Contains([Short Name], "MSB"))_x000D_ in_x000D_ #"Filtered Rows"
A5: Reconcile | B5: let_x000D_ Source = Csv.Document(File.Contents(Param("Input",11)),[Delimiter=" ", Columns=12, Encoding=1200, QuoteStyle=QuoteStyle.None]),_x000D_ #"Renamed Columns1" = Table.RenameColumns(Source,{{"Column8", "GL"}, {"Column9", "Kondor"}, {"Column10", "Diff"}, {"Column1", "Report Date"}, {"Column3", "Product Group"}, {"Column2", "Reconcile Type"}, {"Column4", "Product"}, {"Column11", "Add Infor 1"}}),_x000D_ #"Filtered Rows" = Table.SelectRows(#"Renamed Columns1", each ([Product Group] = "BOND" or [Product Group] = "PAPER")),_x000D_ #"Changed Type" = Table.TransformColumnTypes(#"Filtered Rows",{{"Diff", Int64.Type}, {"Kondor", Int64.Type}, {"GL", Int64.Type}, {"Report Date", type datetime}}),_x000D_ #"Changed Type1" = Table.TransformColumnTypes(#"Changed Type",{{"Report Date", type date}}),_x000D_ #"Removed Columns" = Table.RemoveColumns(#"Changed Type1",{"Column5", "Column6", "Column7", "Column12"})_x000D_ in_x000D_ #"Removed Columns"
A6: BS | B6: let_x000D_ Source = Excel.Workbook(File.Contents(Param("Input",15)), null, true),_x000D_ Navigation = Source{[Item="Can doi noi bang chi tiet - ngu",Kind="Sheet"]}[Data],_x000D_ #"Promoted Headers" = Table.PromoteHeaders(Navigation, [PromoteAllScalars=true]),_x000D_ #"Changed Type" = Table.TransformColumnTypes(#"Promoted Headers",{{"CURRENCY_CODE", type text}, {"Total(ACY_DR_BAL)", type number}, {"Total(ACY_CR_BAL)", type number}, {"Total(ACY_TOVER_DR)", type number}, {"Total(ACY_TOVER_CR)", type number}, {"Total(TO_ACY_DR_BAL)", type number}, {"Total(TO_ACY_CR_BAL)", type number}, {"GL Level 02", type text}, {"GL_LEVEL1_CODE", Int64.Type}, {"GL Level 1", type text}, {"GL_LEVEL2_CODE", Int64.Type}, {"GL Level 2", type text}, {"GL_LEVEL3_CODE", Int64.Type}, {"GL Level 3", type text}, {"GL_CODE", Int64.Type}, {"TÊN TÀI KHOẢN", type text}, {"SHORT_NAME", type text}, {"NỢ", type number}, {"CÓ", type number}, {"NỢ_1", type number}, {"CÓ_2", type number}, {"NỢ_3", type number}, {"CÓ_4", type number}, {"DiffPSNo", Int64.Type}}),_x000D_ #"Filtered Rows" = Table.SelectRows(#"Changed Type", each ([GL_CODE] = 130203001 or [GL_CODE] = 130204001 or [GL_CODE] = 130205001 or [GL_CODE] = 130206001 or [GL_CODE] = 130208001)),_x000D_ #"Removed Columns" = Table.RemoveColumns(#"Filtered Rows",{"CURRENCY_CODE", "Total(ACY_DR_BAL)", "Total(ACY_CR_BAL)", "Total(ACY_TOVER_DR)", "Total(ACY_TOVER_CR)", "Total(TO_ACY_DR_BAL)", "Total(TO_ACY_CR_BAL)", "DiffPSNo", "NỢ", "CÓ", "NỢ_1", "CÓ_2", "GL Level 02", "GL_LEVEL1_CODE", "GL Level 1", "GL_LEVEL2_CODE", "GL Level 2", "GL_LEVEL3_CODE", "GL Level 3", "TÊN TÀI KHOẢN"}),_x000D_ #"Renamed Columns" = Table.RenameColumns(#"Removed Columns",{{"NỢ_3", "NỢ_CK"}, {"CÓ_4", "CÓ_CK"}})_x000D_ in_x000D_ #"Renamed Columns"
A7: LIQ03 | B7: let_x000D_ Source = Excel.Workbook(File.Contents(Param("Input",13)), null, true),_x000D_ #"LIQ03 - Báo cáo tài sản thanh k_Sheet" = Source{[Item="LIQ03 - Báo cáo tài sản thanh k",Kind="Sheet"]}[Data],_x000D_ #"Promoted Headers" = Table.PromoteHeaders(#"LIQ03 - Báo cáo tài sản thanh k_Sheet", [PromoteAllScalars=true]),_x000D_ #"Filtered Rows" = Table.SelectRows(#"Promoted Headers", each ([Product Code] = "CD" or [Product Code] = "FI_CORP_L" or [Product Code] = "FI_CORP_U") and ([Book Flag] = "B")),_x000D_ #"Removed Other Columns" = Table.SelectColumns(#"Filtered Rows",{"Asset Code", "Product Code","Book Flag","Porfolio (Bond Holding)"}),_x000D_ #"Changed Type" = Table.TransformColumnTypes(#"Removed Other Columns",{{"Porfolio (Bond Holding)", Int64.Type}}),_x000D_ #"Sorted Rows" = Table.Sort(#"Changed Type",{{"Asset Code", Order.Ascending}})_x000D_ in_x000D_ #"Sorted Rows"
A8: Dealps | B8: let_x000D_ Source = Excel.Workbook(File.Contents(Param("Input",14)), null, true),_x000D_ #"FIBond Transaction_Sheet" = Source{[Item="FIBond_Transaction",Kind="Table"]}[Data],_x000D_ #"Changed Type" = Table.TransformColumnTypes(#"FIBond Transaction_Sheet",{{"POSTED_DT", type date}, {"DEAL_ID", Int64.Type}, {"PAPER_CODE", type text}, {"CPTY_CODE_ISSUER", type text}, {"CPTY_CODE", type text}, {"PRODUCT_CODE", type text}, {"FOLDERS_CODE", type text}, {"DEAL_TYPE", type text}, {"CAPTURE_DATE", type date}, {"TRADING_DATE", type date}, {"VALUE_DATE", type date}, {"MATURITY_DATE", type date}, {"QUANTITY", Int64.Type}, {"FACE_AMOUNT", type number}, {"PRICE", type number}, {"ACCRUED", Int64.Type}, {"GROSS_AMOUNT", type number}, {"YIELD", type number}, {"MONEY_MARKET_YIELD", type number}})_x000D_ in_x000D_ #"Changed Type"
A9: Dealps deleted | B9: let_x000D_ Source = Excel.Workbook(File.Contents(Param("Input",14)), null, true),_x000D_ FIBond_CD_delete_Table = Source{[Item="FIBond_CD_delete",Kind="Table"]}[Data],_x000D_ #"Changed Type" = Table.TransformColumnTypes(FIBond_CD_delete_Table,{{"POSTED_DT", type date}, {"DEAL_ID", Int64.Type}, {"BOND_CODE", type text}, {"DEAL_TYPE", type text}, {"FACE_AMOUNT", Int64.Type}, {"FOLDERS_CODE", type text}, {"PRODUCT_CODE", type text}}),_x000D_ #"Filtered Rows" = Table.SelectRows(#"Changed Type", each not Text.Contains([BOND_CODE], "MSB"))_x000D_ in_x000D_ #"Filtered Rows"
A10: Dealps fixed | B10: let_x000D_ Source = Excel.Workbook(File.Contents(Param("Input",14)), null, true),_x000D_ FIBond_CD_fix_Table = Source{[Item="FIBond_CD_fix",Kind="Table"]}[Data],_x000D_ #"Changed Type" = Table.TransformColumnTypes(FIBond_CD_fix_Table,{{"POSTED_DT", type date}, {"DEAL_ID", Int64.Type}, {"AMOUNT_RPT", Int64.Type}, {"AMOUNT_YESTERDAY", Int64.Type}})_x000D_ in_x000D_ #"Changed Type"
A11: Yield VBMA | B11: let_x000D_ Source = Sql.Database("10.1.77.53,8888", "GS_RRTT", [Query="select RptDate, Tenor, Average#(lf)from All_Marketdata_Historical#(lf)where Indicators like '%FI%'"]),_x000D_ #"Changed Type" = Table.TransformColumnTypes(Source,{{"RptDate", type date}}),_x000D_ #"Pivoted Column" = Table.Pivot(#"Changed Type", List.Distinct(#"Changed Type"[Tenor]), "Tenor", "Average", List.Sum),_x000D_ #"Reordered Columns" = Table.ReorderColumns(#"Pivoted Column",{"RptDate", "3M", "6M", "9M", "1Y", "1.25Y", "1.5Y", "1.75Y", "2Y", "2.25Y", "2.5Y", "2.75Y", "3Y"}),_x000D_ #"Filtered Rows" = Table.SelectRows(#"Reordered Columns", each [RptDate] >= #date(2024, 12, 31))_x000D_ in_x000D_ #"Filtered Rows"
A12: His53 | B12: let_x000D_ Source = Sql.Database("10.1.77.53,8888", "GS_RRTT", [Query="select RptDate, Product, Indicators, Actual#(lf)from FIBond_Historical#(lf)where Indicators in ('Face value','Market value','Coupon rate binh quan')#(lf)and Issuer = '' and Tenor = ''#(lf)and (Product = '' or Product = 'FI Bond Listed' or Product = 'FI Bond Unlisted' or Product = 'CD' or Product = 'FI Bond')"]),_x000D_ #"Changed Type" = Table.TransformColumnTypes(Source,{{"RptDate", type date}})_x000D_ in_x000D_ #"Changed Type"
... A18: DataTT ps | B18: let_x000D_ Source = Excel.Workbook(File.Contents(Param("Input",19)), null, true),_x000D_ #"Thống kê GD_Sheet" = Source{[Item="Thống kê GD",Kind="Sheet"]}[Data],_x000D_ #"Filtered Rows" = Table.SelectRows(#"Thống kê GD_Sheet", each ([Column1] <> null)),_x000D_ #"Promoted Headers" = Table.PromoteHeaders(#"Filtered Rows", [PromoteAllScalars=true]),_x000D_ #"Changed Type" = Table.TransformColumnTypes(#"Promoted Headers",{{"TCPH", type text}, {"Ngành", type text}, {"Mã GD", type text}, {"Kỳ hạn còn lại", type text}, {"Giá TH gần nhất", Int64.Type}, {"KLTH gần nhất", Int64.Type}, {"Giá TH cao nhất", Int64.Type}, {"KL TH tại mức giá cao nhất", Int64.Type}, {"Giá TH thấp nhất", Int64.Type}, {"KL TH tại mức giá thấp nhất", Int64.Type}, {"KLGD", Int64.Type}, {"GTGD (VNĐ)", Int64.Type}, {"Column13", type any}, {"Column14", type any}, {"Column15", type any}, {"Column16", type any}, {"Column17", type any}}),_x000D_ #"Removed Other Columns" = Table.SelectColumns(#"Changed Type",{"TCPH", "Ngành", "Mã GD", "Kỳ hạn còn lại", "Giá TH gần nhất", "KLTH gần nhất", "Giá TH cao nhất", "KL TH tại mức giá cao nhất", "Giá TH thấp nhất", "KL TH tại mức giá thấp nhất", "KLGD", "GTGD (VNĐ)"}),_x000D_ #"Filtered Rows1" = Table.SelectRows(#"Removed Other Columns", each ([Ngành] <> null))_x000D_ in_x000D_ #"Filtered Rows1"

Sheet Ref
A1: Min (year) | B1: Max (year) | C1: Tenor chuẩn | D1: số ngày chuẩn | F1: TCPH | G1: Ngành1 | H1: Ngành2 | J1: Working date | K1: Gap | M1: Deal đối ứng | N1: BondsDeals_Id | O1: Bonds_ShortName | P1: Issuer | Q1: FaceAmount | R1: Outs | S1: Thời gian đáo hạn | T1: <= Mua | U1: Bán => | V1: BondsDeals_Id | W1: Bonds_ShortName | X1: FaceAmount | Z1: Tỷ giá | AA1: Rptdate | AB1: Indicators | AC1: Average
A2: 0 | B2: 0.4 | C2: 3M | D2: 90 | F2: CTCP CMC | G2: CÔNG NGHIỆP | H2: =IF(OR(G2="TÀI CHÍNH",G2="NGÂN HÀNG",G2="CHỨNG KHOÁN"),"FI BOND","Others") -> Others | J2: 45989 | K2: =J3-J2 -> 3 | N2: 3005 | O2: OCBCD241126 | P2: =_xlfn.XLOOKUP(N2,AllDealps!B:B,AllDealps!D:D,,0) -> OCBV | Q2: 1000000000000 | R2: 1000000000000 | S2: =_xlfn.XLOOKUP(O2,FNRP!AS:AS,FNRP!AV:AV,,0) -> 46350 | V2: 1965 | W2: MSBCD252603 | X2: 700000000000 | AA2: 46262 | AB2: GBP | AC2: 35538.803
A3: 0.4 | B3: 0.75 | C3: 6M | D3: 180 | F3: CTCP Đầu tư và Phát triển du lịch Phú Quốc | G3: TIÊU DÙNG | H3: =IF(OR(G3="TÀI CHÍNH",G3="NGÂN HÀNG",G3="CHỨNG KHOÁN"),"FI BOND","Others") -> Others | J3: 45992 | K3: =J4-J3 -> 1 | N3: 3004 | O3: OCBCD241126 | P3: OCBV | Q3: 1000000000000 | R3: 1000000000000 | S3: =_xlfn.XLOOKUP(O3,FNRP!AS:AS,FNRP!AV:AV,,0) -> 46350 | V3: 1966 | W3: MSBCD252603 | X3: 700000000000 | AA3: 46262 | AB3: USD | AC3: 26073
A4: 0.75 | B4: 1.5 | C4: 1Y | D4: 365 | F4: NHTMCP Phát triển thành phố Hồ Chí Minh ( HDBANK) | G4: NGÂN HÀNG | H4: =IF(OR(G4="TÀI CHÍNH",G4="NGÂN HÀNG",G4="CHỨNG KHOÁN"),"FI BOND","Others") -> FI BOND | J4: 45993 | K4: =J5-J4 -> 1 | O4: BAB12601 | P4: NABV | Q4: 2000000000000 | R4: 2000000000000 | S4: =_xlfn.XLOOKUP(O4,FNRP_FIbond[Short Name],FNRP_FIbond[Mat. Date],0) -> 46498 | V4: 1954 | W4: MSBCD252602 | X4: 500000000000 | AA4: 46262 | AB4: JPY | AC4: 164.00175
A5: =B4 -> 1.5 | B5: =B4+1 -> 2.5 | C5: 2Y | D5: 730 | F5: CTCP Sunbay Ninh Thuận | G5: TIÊU DÙNG | H5: =IF(OR(G5="TÀI CHÍNH",G5="NGÂN HÀNG",G5="CHỨNG KHOÁN"),"FI BOND","Others") -> Others | J5: 45994 | K5: =J6-J5 -> 1 | O5: BAB12603 | P5: NABV | Q5: 1000000000000 | R5: 1000000000000 | S5: =_xlfn.XLOOKUP(O5,FNRP_FIbond[Short Name],FNRP_FIbond[Mat. Date],0) -> 46520 | V5: 1955 | W5: MSBCD252602 | X5: 500000000000 | AA5: 46262 | AB5: AUD | AC5: 18723.021
A6: =B5 -> 2.5 | B6: =B5+1 -> 3.5 | C6: 3Y | D6: 1095 | F6: CTCP ĐẦU TƯ VÀ QUẢN LÝ KHÁCH SẠN TNH | G6: BẤT ĐỘNG SẢN | H6: =IF(OR(G6="TÀI CHÍNH",G6="NGÂN HÀNG",G6="CHỨNG KHOÁN"),"FI BOND","Others") -> Others | J6: 45995 | K6: =J7-J6 -> 1 | O6: HDB12M261126 | P6: HDBV | Q6: 1500000000000 | R6: 1500000000000 | S6: =_xlfn.XLOOKUP(O6,FNRP!AS:AS,FNRP!AV:AV,,0) -> 46352 | V6: 1979 | W6: MSBCD252604 | X6: 1000000000000 | AA6: 46262 | AB6: CHF | AC6: 32453.325
A7: =B6 -> 3.5 | B7: =B6+1 -> 4.5 | C7: 4Y | D7: 1460 | F7: CTCP Bất động sản Hano-vid | G7: BẤT ĐỘNG SẢN | H7: =IF(OR(G7="TÀI CHÍNH",G7="NGÂN HÀNG",G7="CHỨNG KHOÁN"),"FI BOND","Others") -> Others | J7: 45996 | K7: 1 | V7: 1945 | W7: MSBCD012025 | X7: 800000000000 | AA7: 46262 | AB7: CAD | AC7: 18805.583
A8: =B7 -> 4.5 | B8: =B7+1 -> 5.5 | C8: 5Y | D8: 1825 | F8: CTCP Tập đoàn Masan | G8: TIÊU DÙNG | H8: =IF(OR(G8="TÀI CHÍNH",G8="NGÂN HÀNG",G8="CHỨNG KHOÁN"),"FI BOND","Others") -> Others | J8: 45999 | K8: =J9-J8 -> 1 | V8: 1946 | W8: MSBCD012025 | X8: 700000000000 | AA8: 46262 | AB8: EUR | AC8: 30435.013
A9: =B8 -> 5.5 | B9: =B8+2 -> 7.5 | C9: 7Y | D9: 2555 | F9: CTCP đầu tư phát triển bất động sản TNR holdings Việt Nam | G9: BẤT ĐỘNG SẢN | H9: =IF(OR(G9="TÀI CHÍNH",G9="NGÂN HÀNG",G9="CHỨNG KHOÁN"),"FI BOND","Others") -> Others | J9: 46000 | K9: =J10-J9 -> 1 | V9: 1952 | W9: MSBCD252602 | X9: 500000000000 | AA9: 46262 | AB9: HKD | AC9: 3326.0408
A10: =B9 -> 7.5 | B10: =B9+3 -> 10.5 | C10: 10Y | D10: 3650 | F10: CTCP NĂNG LƯỢNG BẮC HÀ | G10: NĂNG LƯỢNG | H10: =IF(OR(G10="TÀI CHÍNH",G10="NGÂN HÀNG",G10="CHỨNG KHOÁN"),"FI BOND","Others") -> Others | J10: 46001 | K10: =J11-J10 -> 1 | V10: 1953 | W10: MSBCD252602 | X10: 500000000000 | AA10: 46262 | AB10: SGD | AC10: 20530.73
A11: =B10 -> 10.5 | B11: =B10+5 -> 15.5 | C11: 15Y | D11: 5475 | F11: CTCP bất động sản Mỹ | G11: BẤT ĐỘNG SẢN | H11: =IF(OR(G11="TÀI CHÍNH",G11="NGÂN HÀNG",G11="CHỨNG KHOÁN"),"FI BOND","Others") -> Others | J11: 46002 | K11: =J12-J11 -> 1 | V11: 3002 | W11: MSBCD252607 | X11: 2000000000000 | AA11: 46262 | AB11: THB | AC11: 795.7578
A12: =B11 -> 15.5 | B12: =B11+5 -> 20.5 | C12: 20Y | D12: 7300 | F12: CTCP In và Bao bì Goldsun | G12: CÔNG NGHIỆP | H12: =IF(OR(G12="TÀI CHÍNH",G12="NGÂN HÀNG",G12="CHỨNG KHOÁN"),"FI BOND","Others") -> Others | J12: 46003 | K12: =J13-J12 -> 3 | V12: 3042 | W12: MSBCD252608 | X12: 1500000000000 | AA12: 46262 | AB12: NOK | AC12: 2789.4525
A13: =B12 -> 20.5 | B13: =B12+20 -> 40.5 | C13: 30Y | D13: 10955 | F13: CTCP Crystal Bay | G13: TIÊU DÙNG | H13: =IF(OR(G13="TÀI CHÍNH",G13="NGÂN HÀNG",G13="CHỨNG KHOÁN"),"FI BOND","Others") -> Others | J13: 46006 | K13: =J14-J13 -> 1 | AA13: 46262 | AB13: SEK | AC13: 2747.7513
F14: CTCP Tập đoàn Đầu tư I.P.A | G14: TÀI CHÍNH | H14: =IF(OR(G14="TÀI CHÍNH",G14="NGÂN HÀNG",G14="CHỨNG KHOÁN"),"FI BOND","Others") -> FI BOND | J14: 46007 | K14: =J15-J14 -> 1 | AA14: 46262 | AB14: XAU | AC14: 1485000
F15: CTCP Chứng khoán Tiên Phong | G15: CHỨNG KHOÁN | H15: =IF(OR(G15="TÀI CHÍNH",G15="NGÂN HÀNG",G15="CHỨNG KHOÁN"),"FI BOND","Others") -> FI BOND | J15: 46008 | K15: =J16-J15 -> 1 | AA15: 46262 | AB15: DKK | AC15: 4071.1709
F16: CTCP Dịch vụ Giải trí Hưng Thịnh Quy Nhơn | G16: BẤT ĐỘNG SẢN | H16: =IF(OR(G16="TÀI CHÍNH",G16="NGÂN HÀNG",G16="CHỨNG KHOÁN"),"FI BOND","Others") -> Others | J16: 46009 | K16: =J17-J16 -> 1 | AA16: 46262 | AB16: CNY | AC16: 3879.595
F17: CTCP Hưng Thịnh Land | G17: BẤT ĐỘNG SẢN | H17: =IF(OR(G17="TÀI CHÍNH",G17="NGÂN HÀNG",G17="CHỨNG KHOÁN"),"FI BOND","Others") -> Others | J17: 46010 | K17: =J18-J17 -> 3 | AA17: 46262 | AB17: NZD | AC17: 15530.382
F18: CTCP Đầu tư thương mại dịch vụ Gia Khang | G18: BẤT ĐỘNG SẢN | H18: =IF(OR(G18="TÀI CHÍNH",G18="NGÂN HÀNG",G18="CHỨNG KHOÁN"),"FI BOND","Others") -> Others | J18: 46013 | K18: =J19-J18 -> 1 | AA18: 46262 | AB18: TWD | AC18: 819.9574
F19: CTCP TẬP ĐOÀN XÂY DỰNG TRACODI ( TÊN CŨ: CTCP ĐẦU TƯ PHÁT TRIỂN CÔNG NGHIỆP VÀ VẬN TẢI) | G19: XÂY DỰNG | H19: =IF(OR(G19="TÀI CHÍNH",G19="NGÂN HÀNG",G19="CHỨNG KHOÁN"),"FI BOND","Others") -> Others | J19: 46014 | K19: =J20-J19 -> 1 | AA19: 46262 | AB19: UV1 | AC19: 26073
F20: CTCP Tập đoàn R&H | G20: BẤT ĐỘNG SẢN | H20: =IF(OR(G20="TÀI CHÍNH",G20="NGÂN HÀNG",G20="CHỨNG KHOÁN"),"FI BOND","Others") -> Others | J20: 46015 | K20: =J21-J20 -> 1 | AA20: 46262 | AB20: UV2 | AC20: 26080
F21: CTCP BCG LAND | G21: BẤT ĐỘNG SẢN | H21: =IF(OR(G21="TÀI CHÍNH",G21="NGÂN HÀNG",G21="CHỨNG KHOÁN"),"FI BOND","Others") -> Others | J21: 46016 | K21: =J22-J21 -> 1 | AA21: 46262 | AB21: MYR | AC21: 6480.9907
F22: CTCP SẢN XUẤT VÀ KINH DOANH VINFAST | G22: CÔNG NGHIỆP | H22: =IF(OR(G22="TÀI CHÍNH",G22="NGÂN HÀNG",G22="CHỨNG KHOÁN"),"FI BOND","Others") -> Others | J22: 46017 | K22: =J23-J22 -> 3 | AA22: 46262 | AB22: KRW | AC22: 18.83615
F23: CTCP đầu tư và dịch vụ HELIOS | G23: LĨNH VỰC KHÁC | H23: =IF(OR(G23="TÀI CHÍNH",G23="NGÂN HÀNG",G23="CHỨNG KHOÁN"),"FI BOND","Others") -> Others | J23: 46020 | K23: =J24-J23 -> 1 | AA23: 46262 | AB23: RUB | AC23: 309.80275
F24: TỔNG CT ĐẦU TƯ VÀ PHÁT TRIỂN CÔNG NGHIỆP - CTCP | G24: BẤT ĐỘNG SẢN | H24: =IF(OR(G24="TÀI CHÍNH",G24="NGÂN HÀNG",G24="CHỨNG KHOÁN"),"FI BOND","Others") -> Others | J24: 46021 | K24: =J25-J24 -> 1 | AA24: 46262 | AB24: TRY | AC24: 541.994
F25: NHTMCP Đầu tư và Phát triển Việt Nam | G25: NGÂN HÀNG | H25: =IF(OR(G25="TÀI CHÍNH",G25="NGÂN HÀNG",G25="CHỨNG KHOÁN"),"FI BOND","Others") -> FI BOND | J25: 46022 | K25: =J26-J25 -> 5 | AA25: 46262 | AB25: LKR | AC25: 79.3578
... F39: CTCP TIẾP VẬN VÀ BẤT ĐỘNG SẢN TÂN LIÊN PHÁT TÂN CẢNG | G39: BẤT ĐỘNG SẢN | H39: =IF(OR(G39="TÀI CHÍNH",G39="NGÂN HÀNG",G39="CHỨNG KHOÁN"),"FI BOND","Others") -> Others | J39: 46044 | K39: =J40-J39 -> 1 | AA39: 46262 | AB39: KGS | AC39: 298.055
F40: CTCP Tập Đoàn ĐẠT PHƯƠNG | G40: XÂY DỰNG | H40: =IF(OR(G40="TÀI CHÍNH",G40="NGÂN HÀNG",G40="CHỨNG KHOÁN"),"FI BOND","Others") -> Others | J40: 46045 | K40: =J41-J40 -> 3
F41: CT TNHH MỘT THÀNH VIÊN ĐẦU TƯ VÀ PHÁT TRIỂN DB | G41: BẤT ĐỘNG SẢN | H41: =IF(OR(G41="TÀI CHÍNH",G41="NGÂN HÀNG",G41="CHỨNG KHOÁN"),"FI BOND","Others") -> Others | J41: 46048 | K41: =J42-J41 -> 1
F42: CTCP Đầu tư Nam Long | G42: BẤT ĐỘNG SẢN | H42: =IF(OR(G42="TÀI CHÍNH",G42="NGÂN HÀNG",G42="CHỨNG KHOÁN"),"FI BOND","Others") -> Others | J42: 46049 | K42: =J43-J42 -> 1
F43: NHTMCP Phương Đông | G43: NGÂN HÀNG | H43: =IF(OR(G43="TÀI CHÍNH",G43="NGÂN HÀNG",G43="CHỨNG KHOÁN"),"FI BOND","Others") -> FI BOND | J43: 46050 | K43: =J44-J43 -> 1
F44: CTCP Masan High-tech Materials | G44: NGUYÊN VẬT LIỆU | H44: =IF(OR(G44="TÀI CHÍNH",G44="NGÂN HÀNG",G44="CHỨNG KHOÁN"),"FI BOND","Others") -> Others | J44: 46051 | K44: =J45-J44 -> 1
F45: Tập đoàn Geleximco - CT CP | G45: CÔNG NGHIỆP | H45: =IF(OR(G45="TÀI CHÍNH",G45="NGÂN HÀNG",G45="CHỨNG KHOÁN"),"FI BOND","Others") -> Others | J45: 46052 | K45: =J46-J45 -> 3
F46: CTCP chứng khoán Kỹ thương | G46: CHỨNG KHOÁN | H46: =IF(OR(G46="TÀI CHÍNH",G46="NGÂN HÀNG",G46="CHỨNG KHOÁN"),"FI BOND","Others") -> FI BOND | J46: 46055 | K46: =J47-J46 -> 1
F47: NHTMCP Quốc tế Việt Nam | G47: NGÂN HÀNG | H47: =IF(OR(G47="TÀI CHÍNH",G47="NGÂN HÀNG",G47="CHỨNG KHOÁN"),"FI BOND","Others") -> FI BOND | J47: 46056 | K47: =J48-J47 -> 1
F48: NHTMCP Á Châu | G48: NGÂN HÀNG | H48: =IF(OR(G48="TÀI CHÍNH",G48="NGÂN HÀNG",G48="CHỨNG KHOÁN"),"FI BOND","Others") -> FI BOND | J48: 46057 | K48: =J49-J48 -> 1
F49: NHTMCP An Bình (ABBANK) | G49: NGÂN HÀNG | H49: =IF(OR(G49="TÀI CHÍNH",G49="NGÂN HÀNG",G49="CHỨNG KHOÁN"),"FI BOND","Others") -> FI BOND | J49: 46058 | K49: =J50-J49 -> 1
F50: CTCP Phú Thọ Land | G50: BẤT ĐỘNG SẢN | H50: =IF(OR(G50="TÀI CHÍNH",G50="NGÂN HÀNG",G50="CHỨNG KHOÁN"),"FI BOND","Others") -> Others | J50: 46059 | K50: =J51-J50 -> 3
F51: CTCP TẬP ĐOÀN PC1 | G51: NĂNG LƯỢNG | H51: =IF(OR(G51="TÀI CHÍNH",G51="NGÂN HÀNG",G51="CHỨNG KHOÁN"),"FI BOND","Others") -> Others | J51: 46062 | K51: =J52-J51 -> 1
... F64: CTCP KHU CÔNG NGHIỆP THÀNH THÀNH CÔNG | G64: BẤT ĐỘNG SẢN | H64: =IF(OR(G64="TÀI CHÍNH",G64="NGÂN HÀNG",G64="CHỨNG KHOÁN"),"FI BOND","Others") -> Others | J64: 46086 | K64: =J65-J64 -> 1
F65: CTCP Phát triển Bất động sản Nhật Quang | G65: BẤT ĐỘNG SẢN | H65: =IF(OR(G65="TÀI CHÍNH",G65="NGÂN HÀNG",G65="CHỨNG KHOÁN"),"FI BOND","Others") -> Others | J65: 46087 | K65: 1
...

Sheet Log&Process
A1: Log | B1: Ngày | C1: Note/Log | D1: PIC | E1: Status | G1: Data Flow | M1: Guide
B2: 45638 | C2: Tìm và đánh giá nguồn dữ liệu giao dịch thị trường của FIBond: HNX, VBMA | D2: thaottp14 thaovt1 | E2: Done
B4: 45639 | C4: Viết code SQL để truy vấn các dealps của FIBond từ bảng Bond_Transaction ở DB basel máy 65, thêm query vào file rawdata lấy đầu ngày | D4: thaottp14 | E4: Done
B7: 45642 | C7: Tạo query input: FNRP, GL, Yield (His53), Dealps (Basel), RPBOD03 (Kondor), Data TT (HNX-VBMA) | D7: thaottp14 | E7: Done
B9: 45643 | C9: Đối chiếu dữ liệu các nguồn tại sheet GL | D9: thaottp14 | E9: Done
B10: 45643 | C10: Thêm sheet Summary tính toán các chỉ số - Dữ liệu giao dịch thị trường - Position theo FV và MV - Dealps - Breakdown On/Off BS, PTCK | D10: thaottp14 | E10: Done
B15: 45644 | C15: Thêm thông tin tham chiếu để phân loại kỳ hạn, viết process, thêm công thức cross check các nguồn | D15: thaottp14 | E15: Done
B17: 45698 | C17: Trao đổi với ĐVKD: không có rule riêng cho FIBond mà giống như với GovBond (map deal, cherry picking) | D17: thaottp14 | E17: Done
B19: 45699 | C19: Lưu backup cho file này để tiện check sau này. | D19: thaottp14 | E19: Done
B20: 45702 | C20: Trao đổi với team Finastra support lỗi hệ thống Kondor không trả dữ liệu Market value, do ĐVKD để sai trường Retrieve Price From là Manual Entry, đã báo ĐVKD sửa thành Yield Curve | D20: thaottp14 | E20: Done
B21: 45705 | C21: Xây mặt báo cáo để gửi mail nội bộ bao gồm các chỉ số, chart, note PPL => Gửi báo cáo T6 hàng tuần | D21: thaottp14 thaovt1 | E21: Done
B22: 45716 | C22: Market value hệ thống Kondor đang tính bằng cách chiếu khấu dùng yield curve = govbond yield curve + 50bps. Cách tính này chưa phù hợp do FIBond từ các ĐCTC khác nhau nên mức độ rủi ro tín dụng và đối tác khác nhau không thể dùng 1 yield curve để định giá cho tất cả các mã. Hiện tại chưa xây được mô hình định giá cho từng mã bond nên đang dùng tạm số hệ thống tính. => Nghiên cứu thêm | D22: thaottp14 | E22: Pending
B23: 45727 | C23: Tạo bảng trên DB 53, folder GS_RRTT bảng để lưu trữ thông tin chuỗi FIBond_Historical | D23: thaottp14 | E23: Done
... B48: 45953 | C48: Thêm cảnh báo ở sheet Runtool để quan sát hạn mức chạm limit | D48: thaottp14 | E48: Done
B49: 45953 | C49: Điều chỉnh trạng thái = trạng thái mở - amt đối ứng, exclude các deal bị âm trạng thái | D49: thaottp14 | E49: Done | F49: Tương tác FO
B50: 45958 | C50: Sửa lại bảng Rating, k kéo từ Available bond từ LR nữa mà từ tạo bảng từ LIQ03 và dữ liệu Rating trên 53 | D50: thaottp14 | E50: Done
B51: 45965 | C51: Code 130203001 lệch 2,500 tỷ 4-5/11 | D51: thaottp14 | E51: Done
B52: 45978 | C52: Deal đối ứng 1,500 tỷ đáo hạn | D52: thaottp14 | E52: Done
B53: 45979 | C53: Code 130203001 lệch 1,500 tỷ 18/11 | D53: thaottp14 | E53: Done
B54: 45986 | C54: Code 130203001 lệch 2,000 tỷ 25/11 | D54: thaottp14 | E54: Done
B55: 45988 | C55: Điều chỉnh giảm 3,500 tỷ deal đối ứng | D55: thaottp14 | E55: Done
B56: 45992 | C56: GL lệch 400 tỷ | D56: thaottp14 | E56: Done
B57: 45996 | C57: GL lệch 1000 tỷ do kế toán hạch toán thiếu deal mua sơ cấp, lỗi từ cuối năm 2024. Deal mua CD sơ cấp sẽ bị hạch toán trễ 1 ngày | D57: thaottp14 | E57: Done
B58: 46006 | C58: GL lệch 200 tỷ do đáo hạn vào chủ nhật ngày 14/12, tiền thanh toán gốc đáo hạn của issuer chưa về nên 15/12 GL code 130203001 vẫn ghi nhận phần 200 tỷ | D58: thaottp14 | E58: Done
B59: 46006 | C59: Bổ sung 1 bảng đáo hạn | D59: thaottp14 | E59: Done
B60: 46009 | C60: Báo cáo RPBOD3 thừa 150 tỷ do BO sửa deal => GL cũng sai theo | D60: thaottp14 | E60: Done
B61: 46013 | C61: Sửa công thức, include cả âm trạng thái | D61: thaottp14 | E61: Done
... B75: 46176 | C75: Tạo thêm bảng upload RPBOD03 của FIBond lên DB53 Code: CREATE TABLE dbo.FIBond_RPBOD03 ( RptDate DATE NOT NULL, BondsDeals_Id INT NOT NULL, Folder NVARCHAR(50), Bonds_ShortName NVARCHAR(50), Issuer NVARCHAR(50), Quantity FLOAT, FaceValue FLOAT, Face_Amount FLOAT, Gross_Amount FLOAT, ValueDate DATE, IssueDate DATE, FirstCouponDate DATE, MaturityDate DATE, TenorBond FLOAT, FirstCouponRate FLOAT, ThisCouponRate FLOAT, Discount FLOAT, Premium FLOAT, Discount_Remain FLOAT, Premium_Remain FLOAT, ValueDate_Accred DATE, Accr FLOAT, TypeOfInstr_ShortName NVARCHAR(50), Yield_Amount FLOAT, Coupon_Amount FLOAT ); | D75: lampd3 | E75: Done

Sheet Runtool
A1: STT | B1: Chỉ tiêu | C1: Values | E1: Process: | F1: Done step: Upload RPBOD03 | H1: Double check | I1: STT | J1: Indicator | K1: Signal | L1: Link/Số | M1: đvt | O1: List kéo cthức | P1: Sheet | Q1: Bảng | R1: Tham chiếu | S1: Count | T1: Apply cth | V1: List bảng | W1: STT | X1: Sheet | Y1: Tên bảng
A2: 1 | B2: Report date | C2: 46262 | I2: 1 | J2: Số tổng FV = số thành phần theo Tenor | K2: =IF(L2=0,"OK","CHECK") -> OK | L2: =Upload53!G2-SUM(Upload53!G3:G14) -> 0 | O2: =COUNTA(P:P)-1 -> 8 | P2: His53 | Q2: His53_DataTT | R2: AG2 | S2: =COUNTA('His53'!AD:AD) -> 820 | T2: =R2&":"&LEFT(R2,LEN(R2)-1)&S2 -> AG2:AG820 | V2: =COUNTA(W:W)-1 -> 25 | W2: 1 | X2: FNRP | Y2: FNRP_FIbond
A3: 2 | B3: Yesterday | C3: {=INDEX(Ref!J:J,MATCH(RPT,Ref!J:J,0)-1)} -> 46261 | I3: 2 | J3: Số tổng FV = số thành phần theo sản phẩm | K3: =IF(SUM(Upload53!G15:G17)= (SUMIFS(FNRP!AN:AN,FNRP!AI:AI,">0")+SUMIFS(FNRP!BP:BP,FNRP!BL:BL,">0"))/10^9,"OK","CHECK") -> OK | L3: =SUM(Upload53!G15:G17)- (SUMIFS(FNRP!AN:AN,FNRP!AI:AI,">0")+SUMIFS(FNRP!BP:BP,FNRP!BL:BL,">0"))/10^9 -> 0 | P3: FNRP | Q3: FNRP_FIbond | R3: AH2:AL2 | S3: =COUNTA(FNRP!D:D) -> 16 | T3: =LEFT(R3,LEN(R3)-1)&S3 -> AH2:AL16 | W3: 2 | X3: FNRP | Y3: FNRP_PPCD
A4: 3 | B4: Last month | C4: =_xlfn.XLOOKUP(EOMONTH(RPT,-1),Ref!J:J,Ref!J:J,_xlfn.XLOOKUP(EOMONTH(RPT,-1),Ref!J:J,Ref!J:J,,-1),0) -> 46234 | I4: 3 | J4: Số tổng MV = số thành phần theo Tenor | K4: =IF(L4=0,"OK","CHECK") -> OK | L4: =Upload53!G29-SUM(Upload53!G30:G41) -> 0 | P4: FNRP | Q4: FNRP_PPCD | R4: BJ2:BN2 | S4: =COUNTA(FNRP!AS:AS) -> 41 | T4: =LEFT(R4,LEN(R4)-1)&S4 -> BJ2:BN41 | W4: 3 | X4: FNRP | Y4: FNRP_MSB
A5: 4 | B5: Last year | C5: =WORKDAY(EOMONTH(DATE(YEAR(RPT),1,1),-1),0,0) -> 46022 | I5: 4 | J5: Số tổng FV = số thành phần theo Tenor (CD) | K5: =IF(SUM(Upload53!G42:G48)=Upload53!G15,"OK","CHECK") -> OK | P5: FNRP | Q5: FNRP_MSB | R5: CS2:CU2 | S5: =COUNTA(FNRP!CB:CB) -> 12 | T5: =LEFT(R5,LEN(R5)-1)&S5 -> CS2:CU12 | W5: 4 | X5: GL | Y5: offBS
A6: 5 | B6: Last 370 days | C6: =RPT-370 -> 45892 | I6: 5 | J6: Check đối chiếu các nguồn | K6: =IF(SUM(GL!G:G)<>0,"CHECK","OK") -> CHECK | L6: GL!A1 | P6: AllDealps | Q6: Dealps | R6: T2:Z2 | S6: =COUNTA(AllDealps!B:B) -> 817 | T6: =LEFT(R6,LEN(R6)-1)&S6 -> T2:Z817 | W6: 5 | X6: GL | Y6: BS
A7: 6 | B7: Lastest 1Y | C7: =RPT-370 -> 45892 | I7: 6 | J7: Số CD+FI Bond bảng rating = GL | K7: =IF(L7=0,"OK","CHECK") -> CHECK | L7: =ROUND((SUM(Rating!B:B)/2-GL!C17-ITB_Amt),1) -> 3218 | P7: AllDealps | Q7: Dealps_MSB | R7: BU2 | S7: =COUNTA(AllDealps!BD:BD) -> 568 | T7: =R7&":"&LEFT(R7,LEN(R7)-1)&S7 -> BU2:BU568 | W7: 6 | X7: His53 | Y7: Yield_VBMA
A8: 7 | B8: Tool_name | C8: ="01.RptTool_FIBond_"&TEXT(RPT,"yyyy.mm.dd")&".xlsb" -> 01.RptTool_FIBond_2026.08.28.xlsb | I8: 7 | J8: Check GL Bond KGS | K8: =IF(L8=0,"OK","CHECK") -> OK | L8: =GL!B27 -> 0 | P8: RPBOD3 | Q8: RPBOD_B003 | R8: X2 | S8: =COUNTA(RPBOD3!A:A) -> 92 | T8: =R8&":"&LEFT(R8,LEN(R8)-1)&S8 -> X2:X92 | W8: 7 | X8: His53 | Y8: His53_
A9: 8 | B9: FNRP FI Bond | C9: ="\\filesrv01.msb.com.vn\06.Khoi Quan Ly Rui Ro\02.Trung Tam QLRR Thi Truong\02.Phong GSRRTT\05.Report\01.Daily Report\"&TEXT(RPT,"yyyy.mm.dd")&"\00.Input\01.DataFile53\BondFIBS2.BondsSynthetic.csv" -> \\filesrv01.msb.com.vn\06.Khoi Quan Ly Rui Ro\02.Trung Tam QLRR Thi Truong\02.Phong GSRRTT\05.Report\01.Daily Report\2026.08.28\00.Input\01.DataFile53\BondFIBS2.BondsSynthetic.csv | I9: 8 | J9: Số ngày RPT = RPT (D-1) + phát sinh - xóa + sửa - đáo hạn | K9: =IF(ABS(L9)<=1, "OK", "CHECK") -> OK | L9: =ROUND(Summary!BI7-((SUMIFS(FNRP!J:J,FNRP!AI:AI,">0")-SUM(FNRP_FIbond[Đối ứng]))+SUMIFS(FNRP!BP:BP,FNRP!BL:BL,">0"))/10^9-ITB_Amt,1) -> 0 | P9: DataTT | Q9: DataTT_ps | R9: M2 | S9: =COUNTA(DataTT!A:A) -> 147 | T9: =R9&":"&LEFT(R9,LEN(R9)-1)&S9 -> M2:M147 | W9: 8 | X9: His53 | Y9: Yield_BidAsk
A10: 9 | B10: FNRP CD | C10: ="\\filesrv01.msb.com.vn\06.Khoi Quan Ly Rui Ro\02.Trung Tam QLRR Thi Truong\02.Phong GSRRTT\05.Report\01.Daily Report\"&TEXT(RPT,"yyyy.mm.dd")&"\00.Input\01.DataFile53\PPCD.FI.BS2.PaperCDSynthetic.csv" -> \\filesrv01.msb.com.vn\06.Khoi Quan Ly Rui Ro\02.Trung Tam QLRR Thi Truong\02.Phong GSRRTT\05.Report\01.Daily Report\2026.08.28\00.Input\01.DataFile53\PPCD.FI.BS2.PaperCDSynthetic.csv | I10: 9 | J10: Data thị trường có cty nào chưa có ngành k | K10: =IF(COUNTBLANK(DataTT_ps[[#All],[Phân loại]])>0,"CHECK","OK") -> OK | L10: DataTT!A1 | W10: 9 | X10: His53 | Y10: His53_DataTT
A11: 10 | B11: Available bond LR | C11: ="\\filesrv01.msb.com.vn\06.Khoi Quan Ly Rui Ro\02.Trung Tam QLRR Thi Truong\03.Phong QLRRTK\Daily Report\LR_"&TEXT(C18,"yyyy.mm.dd")&"\MCO Report\Available bond_v5_"&TEXT($C$18,"yyyy.mm.dd")&".xlsm" -> \\filesrv01.msb.com.vn\06.Khoi Quan Ly Rui Ro\02.Trung Tam QLRR Thi Truong\03.Phong QLRRTK\Daily Report\LR_2026.08.30\MCO Report\Available bond_v5_2026.08.30.xlsm | I11: 10 | J11: Số tổng FV On Off Ngoai BS | K11: =IF(SUM(Upload53!G15:G17)=SUM(Upload53!G19:G27),"OK","CHECK") -> OK | L11: =SUM(Upload53!G15:G18)-SUM(Upload53!G19:G28) -> 0 | W11: 10 | X11: His53 | Y11: GovBond_BS
A12: 11 | B12: Reconcile MR10 | C12: \\filesrv01.msb.com.vn\06.Khoi Quan Ly Rui Ro\02.Trung Tam QLRR Thi Truong\02.Phong GSRRTT\05.Report\Theo doi\Capital charge\Input_data\MR10 - Reconcile (All).csv | I12: 11 | J12: Check số tổng data thị trường và số thành phần | K12: =IF(Upload53!G72+Upload53!G73=SUM(DataTT!L:L)/10^9,"OK","CHECK") -> OK | W12: 11 | X12: AllDealps | Y12: Dealps
A13: 12 | B13: RPBOD_B003 | C13: ="\\filesrv01.msb.com.vn\06.Khoi Quan Ly Rui Ro\02.Trung Tam QLRR Thi Truong\02.Phong GSRRTT\05.Report\01.Daily Report\"&TEXT(RPT,"yyyy.mm.dd")&"\00.Input\02.Kondor\RPBOD_B003.xlsx" -> \\filesrv01.msb.com.vn\06.Khoi Quan Ly Rui Ro\02.Trung Tam QLRR Thi Truong\02.Phong GSRRTT\05.Report\01.Daily Report\2026.08.28\00.Input\02.Kondor\RPBOD_B003.xlsx | I13: 12 | J13: Check số PTCK của FIBond trên GL và RPBOD3 | K13: {=IF(ABS( SUM(SUMIFS(GL!M:M,GL!J:J,{"130205001","130208001"}))-SUMIFS(GL!N:N,GL!J:J,"130204001") -(SUM(RPBOD3!S:S)-SUM(RPBOD3!R:R))) <1000,"OK", "CHECK")} -> CHECK | L13: {=SUM(SUMIFS(GL!L:L,GL!J:J,{"130205001","130208001","130204001"}))-(SUMIFS(RPBOD3!T:T,RPBOD3!D:D,"<>MFKR")-SUMIFS(RPBOD3!S:S,RPBOD3!D:D,"<>MFKR"))} -> 3.8100415e+09 | M13: vnd | W13: 12 | X13: AllDealps | Y13: Dealps_deleted
A14: 13 | B14: LIQ3 | C14: ="\\filesrv01.msb.com.vn\06.Khoi Quan Ly Rui Ro\02.Trung Tam QLRR Thi Truong\03.Phong QLRRTK\Daily Report\LR_"&TEXT(RPT,"yyyy.mm.dd")&"\Input Data\LIQ03.xlsx" -> \\filesrv01.msb.com.vn\06.Khoi Quan Ly Rui Ro\02.Trung Tam QLRR Thi Truong\03.Phong QLRRTK\Daily Report\LR_2026.08.28\Input Data\LIQ03.xlsx | I14: 13 | J14: Chech deal đối ứng nào đáo hạn | K14: =IF(L14=0,"OK","CHECK") -> OK | L14: =SUMIFS(FNRP!BO:BO,FNRP!BL:BL,"<=0")/10^9 -> 0 | M14: tỷ | W14: 13 | X14: AllDealps | Y14: Dealps_fixed
A15: 14 | B15: Raw data | C15: ="\\filesrv01.msb.com.vn\06.Khoi Quan Ly Rui Ro\02.Trung Tam QLRR Thi Truong\02.Phong GSRRTT\05.Report\01.Daily Report\"&TEXT(RPT,"yyyy.mm.dd")&"\00.Input\00.Raw_Data.xlsm" -> \\filesrv01.msb.com.vn\06.Khoi Quan Ly Rui Ro\02.Trung Tam QLRR Thi Truong\02.Phong GSRRTT\05.Report\01.Daily Report\2026.08.28\00.Input\00.Raw_Data.xlsm | I15: 14 | J15: Có mã nào bị âm trạng thái không | K15: =IF(L15>0,"CHECK","OK") -> OK | L15: =COUNTIF(FNRP!J:J,"<0")+COUNTIF(FNRP!BA:BA,"<0") -> 0 | M15: mã | W15: 14 | X15: AllDealps | Y15: Dealps_MSB
A16: 15 | B16: GL nội bảng | C16: ="\\filesrv01.msb.com.vn\06.Khoi Quan Ly Rui Ro\02.Trung Tam QLRR Thi Truong\03.Phong QLRRTK\Daily Report\LR_"&TEXT(RPT,"yyyy.mm.dd")&"\Input Data\GL\Can doi noi bang chi tiet - nguyen te (chitiet).xlsx" -> \\filesrv01.msb.com.vn\06.Khoi Quan Ly Rui Ro\02.Trung Tam QLRR Thi Truong\03.Phong QLRRTK\Daily Report\LR_2026.08.28\Input Data\GL\Can doi noi bang chi tiet - nguyen te (chitiet).xlsx | I16: 15 | J16: Có giao dịch mua CD sơ cấp không | K16: =IF(L16=0,"OK","CHECK") -> OK | L16: =SUMIFS(AllDealps!V:V,AllDealps!Z:Z,"Yes",AllDealps!F:F,"CD",AllDealps!I:I,RPT)/10^9 -> 0 | M16: tỷ | W16: 15 | X16: AllDealps | Y16: Dao_han
A17: 16 | B17: Last week | C17: =RPT-WEEKDAY(RPT, 2)-2 -> 46255 | I17: 16 | J17: Số tổng FIBond = số thành phần theo listed/unlisted +adj đối ứng | K17: =IF(L17=0,"OK","CHECK") -> OK | L17: =ROUND(Upload53!G2-Upload53!G16-Upload53!G17-Upload53!G18,1) -> 0 | M17: tỷ | W17: 16 | X17: RPBOD3 | Y17: RPBOD_B003
A18: 17 | B18: Today - 1 | C18: =IF(WEEKDAY(RPT)=6,RPT+2,RPT) -> 46264 | E18: Bảng cảnh báo tuân thủ | G18: Limit | I18: 17 | J18: Check GL ngoại bảng = dữ liệu Baselmart (gồm cả gov+fi bond) | K18: =IF(L18=0,"OK","CHECK") -> CHECK | L18: =GL!B23 -> 2547 | M18: tỷ | W18: 17 | X18: Repo | Y18: Repo
A19: 18 | B19: Tool Yesterday | C19: ="\\filesrv01.msb.com.vn\06.Khoi Quan Ly Rui Ro\02.Trung Tam QLRR Thi Truong\02.Phong GSRRTT\05.Report\01.Daily Report\"&TEXT(Yesterday,"yyyy.mm.dd")&"\02.FI Bond\01.RptTool_FIBond_"&TEXT(Yesterday,"yyyy.mm.dd")&".xlsb" -> \\filesrv01.msb.com.vn\06.Khoi Quan Ly Rui Ro\02.Trung Tam QLRR Thi Truong\02.Phong GSRRTT\05.Report\01.Daily Report\2026.08.27\02.FI Bond\01.RptTool_FIBond_2026.08.27.xlsb | E19: FIBond&CD (Face value) | G19: =Report!K10 -> 0.89258951 | I19: 18 | J19: Có dealps đầu tư nước ngoài mới không | K19: {=IF(ISNUMBER(Dealps_ITB[BondsDeals_Id]),"CHECK","OK")} -> OK | W19: 18 | X19: DataTT | Y19: DataTT_ps
A20: 19 | B20: Data TT ngày RPT | C20: ="\\filesrv01.msb.com.vn\06.Khoi Quan Ly Rui Ro\02.Trung Tam QLRR Thi Truong\02.Phong GSRRTT\05.Report\01.Daily Report\"&TEXT(RPT,"yyyy.mm.dd")&"\00.Input\05.Outlook&HNX\Corporate bond trading "&TEXT(RPT,"dd-mm-yyyy")&".xlsx" -> \\filesrv01.msb.com.vn\06.Khoi Quan Ly Rui Ro\02.Trung Tam QLRR Thi Truong\02.Phong GSRRTT\05.Report\01.Daily Report\2026.08.28\00.Input\05.Outlook&HNX\Corporate bond trading 28-08-2026.xlsx | E20: Cơ cấu đầu tư từ BBB | G20: =Report!K13 -> 0.48509398 | I20: 19 | J20: Có deal xóa sửa không | K20: =IF(L20=0,"OK","CHECK") -> OK | L20: =COUNTA(AllDealps!AC:AC)-1 -> 0 | W20: 19 | X20: Upload53 RPBOD03 | Y20: Upload53_RPBOD03
A21: 20 | B21: 1st Quarter | C21: 46112 | I21: 20 | J21: Check yield có lỗi không | K21: =IF(COUNTIF(Summary!CL:CL,"#N/A")>0,"CHECK","OK") -> OK | W21: 20 | X21: FNRP | Y21: FNRP_ITB_2
A22: 21 | B22: 2nd Quarter | C22: 46203 | W22: 21 | X22: Ref | Y22: Tygia
A23: 22 | B23: 3rd Quarter | C23: 46295 | W23: 22 | X23: AllDealps | Y23: Dealps_ITB
A24: 23 | B24: 4th Quarter | C24: 46387 | W24: 23 | X24: Rating | Y24: Portfolio_rating
A25: 24 | B25: GL ngoại bảng | C25: ="\\filesrv01.msb.com.vn\06.Khoi Quan Ly Rui Ro\02.Trung Tam QLRR Thi Truong\03.Phong QLRRTK\Daily Report\LR_"&TEXT(RPT,"yyyy.mm.dd")&"\Input Data\GL\Can doi ngoai bang chi tiet - nguyen te (chitiet).xlsx" -> \\filesrv01.msb.com.vn\06.Khoi Quan Ly Rui Ro\02.Trung Tam QLRR Thi Truong\03.Phong QLRRTK\Daily Report\LR_2026.08.28\Input Data\GL\Can doi ngoai bang chi tiet - nguyen te (chitiet).xlsx | W25: 24 | X25: GL | Y25: BS_KGS
A26: 25 | B26: FNRP BB MSB | C26: ="\\filesrv01.msb.com.vn\06.Khoi Quan Ly Rui Ro\02.Trung Tam QLRR Thi Truong\02.Phong GSRRTT\05.Report\01.Daily Report\"&TEXT(RPT,"yyyy.mm.dd")&"\00.Input\01.DataFile53\BondAllBS2BK.BondsSynthetic.csv" -> \\filesrv01.msb.com.vn\06.Khoi Quan Ly Rui Ro\02.Trung Tam QLRR Thi Truong\02.Phong GSRRTT\05.Report\01.Daily Report\2026.08.28\00.Input\01.DataFile53\BondAllBS2BK.BondsSynthetic.csv | W26: 25 | X26: GL | Y26: offBS_KGS
A27: 26 | B27: Alldealps ITB | C27: ="\\filesrv01.msb.com.vn\06.Khoi Quan Ly Rui Ro\02.Trung Tam QLRR Thi Truong\02.Phong GSRRTT\05.Report\01.Daily Report\"&TEXT(RPT,"yyyy.mm.dd")&"\00.Input\01.DataFile53\RPBOD_B002.RPBOD_B002_I0.csv" -> \\filesrv01.msb.com.vn\06.Khoi Quan Ly Rui Ro\02.Trung Tam QLRR Thi Truong\02.Phong GSRRTT\05.Report\01.Daily Report\2026.08.28\00.Input\01.DataFile53\RPBOD_B002.RPBOD_B002_I0.csv
A28: 27 | B28: Tỷ giá | C28: ="\\filesrv01.msb.com.vn\06.Khoi Quan Ly Rui Ro\02.Trung Tam QLRR Thi Truong\02.Phong GSRRTT\05.Report\01.Daily Report\"&YEAR(RPT)&"."&TEXT(MONTH(RPT),"00")&"."&TEXT(DAY(RPT),"00")&"\00.Input\01.DataFile53\RP_CUR_RAT.RP_CUR_RAT_I0.csv" -> \\filesrv01.msb.com.vn\06.Khoi Quan Ly Rui Ro\02.Trung Tam QLRR Thi Truong\02.Phong GSRRTT\05.Report\01.Daily Report\2026.08.28\00.Input\01.DataFile53\RP_CUR_RAT.RP_CUR_RAT_I0.csv

Sheet Upload53
A1: RptDate | B1: Indicators | C1: Product | D1: Issuer | E1: Tenor | F1: Type | G1: Actual | H1: Units | I1: Note | J1: =COUNTA(B:B)-1 -> 196 | N1: Nối 3 cột thành 1 cột | O1: Split | P1: TEXTSPLIT(N3,"/")
A2: =RPT -> 46262 | B2: Face value | C2: FI Bond | G2: =Summary!J3+Summary!DB1 -> 12967.428 | H2: Bio VND | K2: {="Face value/FI Bond/" & _xlfn.UNIQUE(_xlfn._xlws.FILTER(FNRP_FIbond[Issuer],FNRP_FIbond[Days]>0))} -> Face value/FI Bond/LVBT | L2: {="Market value/FI Bond/" & _xlfn.UNIQUE(_xlfn._xlws.FILTER(FNRP_FIbond[Issuer],FNRP_FIbond[Days]>0))} -> Market value/FI Bond/LVBT | M2: {="Face value/CD/" & _xlfn.UNIQUE(_xlfn._xlws.FILTER(FNRP_PPCD[Issuer],FNRP_PPCD[Issuer]<>""))} -> Face value/CD/VIETBANK | N2: {=_xlfn.FILTERXML("<t><s>" & _xlfn.TEXTJOIN("</s><s>", TRUE,_xlfn.ANCHORARRAY( K2),_xlfn.ANCHORARRAY( L2),_xlfn.ANCHORARRAY( M2)) & "</s></t>", "//s")} -> Face value/FI Bond/LVBT | O2: =TRIM(LEFT(N2,FIND("/",N2&"/")-1)) -> Face value | P2: =TRIM(MID(N2,FIND("/",N2)+1,FIND("/",N2&"/",FIND("/",N2)+1)-FIND("/",N2)-1)) -> FI Bond | Q2: =TRIM(RIGHT(N2,LEN(N2)-FIND("@",SUBSTITUTE(N2,"/","@",LEN(N2)-LEN(SUBSTITUTE(N2,"/","")))))) -> LVBT
A3: =RPT -> 46262 | B3: Face value | C3: FI Bond | E3: 3M | G3: =_xlfn.XLOOKUP(E3,Summary!$K$1:$S$1,Summary!$K$3:$S$3) -> 1000 | H3: Bio VND | K3: Face value/FI Bond/TC_SHINSEI | L3: Market value/FI Bond/TC_SHINSEI | M3: Face value/CD/HCVN | N3: Face value/FI Bond/TC_SHINSEI | O3: =TRIM(LEFT(N3,FIND("/",N3&"/")-1)) -> Face value | P3: =TRIM(MID(N3,FIND("/",N3)+1,FIND("/",N3&"/",FIND("/",N3)+1)-FIND("/",N3)-1)) -> FI Bond | Q3: =TRIM(RIGHT(N3,LEN(N3)-FIND("@",SUBSTITUTE(N3,"/","@",LEN(N3)-LEN(SUBSTITUTE(N3,"/","")))))) -> TC_SHINSEI
A4: =RPT -> 46262 | B4: Face value | C4: FI Bond | E4: 6M | G4: =_xlfn.XLOOKUP(E4,Summary!$K$1:$S$1,Summary!$K$3:$S$3) -> 400 | H4: Bio VND | K4: Face value/FI Bond/NABV | L4: Market value/FI Bond/NABV | M4: Face value/CD/SGTT | N4: Face value/FI Bond/NABV | O4: =TRIM(LEFT(N4,FIND("/",N4&"/")-1)) -> Face value | P4: =TRIM(MID(N4,FIND("/",N4)+1,FIND("/",N4&"/",FIND("/",N4)+1)-FIND("/",N4)-1)) -> FI Bond | Q4: =TRIM(RIGHT(N4,LEN(N4)-FIND("@",SUBSTITUTE(N4,"/","@",LEN(N4)-LEN(SUBSTITUTE(N4,"/","")))))) -> NABV
A5: =RPT -> 46262 | B5: Face value | C5: FI Bond | E5: 1Y | G5: =_xlfn.XLOOKUP(E5,Summary!$K$1:$S$1,Summary!$K$3:$S$3) -> 3400 | H5: Bio VND | K5: Face value/FI Bond/HCVN | L5: Market value/FI Bond/HCVN | M5: Face value/CD/EIBV | N5: Face value/FI Bond/HCVN | O5: =TRIM(LEFT(N5,FIND("/",N5&"/")-1)) -> Face value | P5: =TRIM(MID(N5,FIND("/",N5)+1,FIND("/",N5&"/",FIND("/",N5)+1)-FIND("/",N5)-1)) -> FI Bond | Q5: =TRIM(RIGHT(N5,LEN(N5)-FIND("@",SUBSTITUTE(N5,"/","@",LEN(N5)-LEN(SUBSTITUTE(N5,"/","")))))) -> HCVN
A6: =RPT -> 46262 | B6: Face value | C6: FI Bond | E6: 2Y | G6: =_xlfn.XLOOKUP(E6,Summary!$K$1:$S$1,Summary!$K$3:$S$3) -> 700 | H6: Bio VND | K6: Face value/FI Bond/VBAH | L6: Market value/FI Bond/VBAH | M6: Face value/CD/ABBV | N6: Face value/FI Bond/VBAH | O6: =TRIM(LEFT(N6,FIND("/",N6&"/")-1)) -> Face value | P6: =TRIM(MID(N6,FIND("/",N6)+1,FIND("/",N6&"/",FIND("/",N6)+1)-FIND("/",N6)-1)) -> FI Bond | Q6: =TRIM(RIGHT(N6,LEN(N6)-FIND("@",SUBSTITUTE(N6,"/","@",LEN(N6)-LEN(SUBSTITUTE(N6,"/","")))))) -> VBAH
A7: =RPT -> 46262 | B7: Face value | C7: FI Bond | E7: 3Y | G7: =_xlfn.XLOOKUP(E7,Summary!$K$1:$S$1,Summary!$K$3:$S$3) -> 3000 | H7: Bio VND | K7: Face value/FI Bond/HDBV | L7: Market value/FI Bond/HDBV | M7: Face value/CD/TCBV-HO | N7: Face value/FI Bond/HDBV | O7: =TRIM(LEFT(N7,FIND("/",N7&"/")-1)) -> Face value | P7: =TRIM(MID(N7,FIND("/",N7)+1,FIND("/",N7&"/",FIND("/",N7)+1)-FIND("/",N7)-1)) -> FI Bond | Q7: =TRIM(RIGHT(N7,LEN(N7)-FIND("@",SUBSTITUTE(N7,"/","@",LEN(N7)-LEN(SUBSTITUTE(N7,"/","")))))) -> HDBV
A8: =RPT -> 46262 | B8: Face value | C8: FI Bond | E8: 4Y | G8: =_xlfn.XLOOKUP(E8,Summary!$K$1:$S$1,Summary!$K$3:$S$3) -> 0 | H8: Bio VND | K8: Face value/FI Bond/SHBV | L8: Market value/FI Bond/SHBV | M8: Face value/CD/OCBV | N8: Face value/FI Bond/SHBV | O8: =TRIM(LEFT(N8,FIND("/",N8&"/")-1)) -> Face value | P8: =TRIM(MID(N8,FIND("/",N8)+1,FIND("/",N8&"/",FIND("/",N8)+1)-FIND("/",N8)-1)) -> FI Bond | Q8: =TRIM(RIGHT(N8,LEN(N8)-FIND("@",SUBSTITUTE(N8,"/","@",LEN(N8)-LEN(SUBSTITUTE(N8,"/","")))))) -> SHBV
A9: =RPT -> 46262 | B9: Face value | C9: FI Bond | E9: 5Y | G9: =_xlfn.XLOOKUP(E9,Summary!$K$1:$S$1,Summary!$K$3:$S$3) -> 0 | H9: Bio VND | K9: Face value/FI Bond/MCSB | L9: Market value/FI Bond/MCSB | M9: Face value/CD/VCCB | N9: Face value/FI Bond/MCSB | O9: =TRIM(LEFT(N9,FIND("/",N9&"/")-1)) -> Face value | P9: =TRIM(MID(N9,FIND("/",N9)+1,FIND("/",N9&"/",FIND("/",N9)+1)-FIND("/",N9)-1)) -> FI Bond | Q9: =TRIM(RIGHT(N9,LEN(N9)-FIND("@",SUBSTITUTE(N9,"/","@",LEN(N9)-LEN(SUBSTITUTE(N9,"/","")))))) -> MCSB
A10: =RPT -> 46262 | B10: Face value | C10: FI Bond | E10: 7Y | G10: =_xlfn.XLOOKUP(E10,Summary!$K$1:$S$1,Summary!$K$3:$S$3)+Summary!DB1 -> 4467.4278 | H10: Bio VND | K10: Face value/FI Bond/TCBV-HO | L10: Market value/FI Bond/TCBV-HO | M10: Face value/CD/HDBV | N10: Face value/FI Bond/TCBV-HO | O10: =TRIM(LEFT(N10,FIND("/",N10&"/")-1)) -> Face value | P10: =TRIM(MID(N10,FIND("/",N10)+1,FIND("/",N10&"/",FIND("/",N10)+1)-FIND("/",N10)-1)) -> FI Bond | Q10: =TRIM(RIGHT(N10,LEN(N10)-FIND("@",SUBSTITUTE(N10,"/","@",LEN(N10)-LEN(SUBSTITUTE(N10,"/","")))))) -> TCBV-HO
A11: =RPT -> 46262 | B11: Face value | C11: FI Bond | E11: 10Y | G11: =_xlfn.XLOOKUP(E11,Summary!$K$1:$S$1,Summary!$K$2:$S$2) -> 0 | H11: Bio VND | K11: Face value/FI Bond/PVFC | L11: Market value/FI Bond/PVFC | M11: Face value/CD/LVBT | N11: Face value/FI Bond/PVFC | O11: =TRIM(LEFT(N11,FIND("/",N11&"/")-1)) -> Face value | P11: =TRIM(MID(N11,FIND("/",N11)+1,FIND("/",N11&"/",FIND("/",N11)+1)-FIND("/",N11)-1)) -> FI Bond | Q11: =TRIM(RIGHT(N11,LEN(N11)-FIND("@",SUBSTITUTE(N11,"/","@",LEN(N11)-LEN(SUBSTITUTE(N11,"/","")))))) -> PVFC
A12: =RPT -> 46262 | B12: Face value | C12: FI Bond | E12: 15Y | G12: =HLOOKUP(Upload53!E12,Summary!$K$1:$V$3,3,0) -> 0 | H12: Bio VND | K12: Face value/FI Bond/SGTT | L12: Market value/FI Bond/SGTT | M12: Face value/CD/SABH | N12: Face value/FI Bond/SGTT | O12: =TRIM(LEFT(N12,FIND("/",N12&"/")-1)) -> Face value | P12: =TRIM(MID(N12,FIND("/",N12)+1,FIND("/",N12&"/",FIND("/",N12)+1)-FIND("/",N12)-1)) -> FI Bond | Q12: =TRIM(RIGHT(N12,LEN(N12)-FIND("@",SUBSTITUTE(N12,"/","@",LEN(N12)-LEN(SUBSTITUTE(N12,"/","")))))) -> SGTT
A13: =RPT -> 46262 | B13: Face value | C13: FI Bond | E13: 20Y | G13: =HLOOKUP(Upload53!E13,Summary!$K$1:$V$3,3,0) -> 0 | H13: Bio VND | M13: Face value/CD/BIDV | N13: Market value/FI Bond/LVBT | O13: =TRIM(LEFT(N13,FIND("/",N13&"/")-1)) -> Market value | P13: =TRIM(MID(N13,FIND("/",N13)+1,FIND("/",N13&"/",FIND("/",N13)+1)-FIND("/",N13)-1)) -> FI Bond | Q13: =TRIM(RIGHT(N13,LEN(N13)-FIND("@",SUBSTITUTE(N13,"/","@",LEN(N13)-LEN(SUBSTITUTE(N13,"/","")))))) -> LVBT
A14: =RPT -> 46262 | B14: Face value | C14: FI Bond | E14: 30Y | G14: =HLOOKUP(Upload53!E14,Summary!$K$1:$V$3,3,0) -> 0 | H14: Bio VND | M14: Face value/CD/TC_DIENLUC | N14: Market value/FI Bond/TC_SHINSEI | O14: =TRIM(LEFT(N14,FIND("/",N14&"/")-1)) -> Market value | P14: =TRIM(MID(N14,FIND("/",N14)+1,FIND("/",N14&"/",FIND("/",N14)+1)-FIND("/",N14)-1)) -> FI Bond | Q14: =TRIM(RIGHT(N14,LEN(N14)-FIND("@",SUBSTITUTE(N14,"/","@",LEN(N14)-LEN(SUBSTITUTE(N14,"/","")))))) -> TC_SHINSEI
A15: =RPT -> 46262 | B15: Face value | C15: CD | G15: =Summary!AO3 -> 27199.1 | H15: Bio VND | M15: Face value/CD/MCSB | N15: Market value/FI Bond/NABV | O15: =TRIM(LEFT(N15,FIND("/",N15&"/")-1)) -> Market value | P15: =TRIM(MID(N15,FIND("/",N15)+1,FIND("/",N15&"/",FIND("/",N15)+1)-FIND("/",N15)-1)) -> FI Bond | Q15: =TRIM(RIGHT(N15,LEN(N15)-FIND("@",SUBSTITUTE(N15,"/","@",LEN(N15)-LEN(SUBSTITUTE(N15,"/","")))))) -> NABV
A16: =RPT -> 46262 | B16: Face value | C16: FI Bond Listed | G16: =SUMIFS(FNRP!J:J,FNRP!E:E,"FI_CORP_L",FNRP!AI:AI,"<>0")/10^9 -> 397.6106 | H16: Bio VND | M16: Face value/CD/TC_SHINSEI | N16: Market value/FI Bond/HCVN | O16: =TRIM(LEFT(N16,FIND("/",N16&"/")-1)) -> Market value | P16: =TRIM(MID(N16,FIND("/",N16)+1,FIND("/",N16&"/",FIND("/",N16)+1)-FIND("/",N16)-1)) -> FI Bond | Q16: =TRIM(RIGHT(N16,LEN(N16)-FIND("@",SUBSTITUTE(N16,"/","@",LEN(N16)-LEN(SUBSTITUTE(N16,"/","")))))) -> HCVN
A17: =RPT -> 46262 | B17: Face value | C17: FI Bond Unlisted | G17: =SUMIFS(AllDealps!$U:$U,AllDealps!$F:$F,"FI_CORP_U")/10^9-SUM(FNRP_FIbond[Đối ứng])/10^9 -> 12000 | H17: Bio VND | M17: Face value/CD/VPVN | N17: Market value/FI Bond/VBAH | O17: =TRIM(LEFT(N17,FIND("/",N17&"/")-1)) -> Market value | P17: =TRIM(MID(N17,FIND("/",N17)+1,FIND("/",N17&"/",FIND("/",N17)+1)-FIND("/",N17)-1)) -> FI Bond | Q17: =TRIM(RIGHT(N17,LEN(N17)-FIND("@",SUBSTITUTE(N17,"/","@",LEN(N17)-LEN(SUBSTITUTE(N17,"/","")))))) -> VBAH
A18: =RPT -> 46262 | B18: Face value | C18: TPCP KGS | G18: =Summary!DB1 -> 569.8172 | H18: Bio VND | M18: Face value/CD/ACBV | N18: Market value/FI Bond/HDBV
A19: =RPT -> 46262 | B19: Face value | C19: CD On BS | G19: =Summary!BM7-SUM(FNRP_PPCD[[#All],[Đối ứng]])/10^9 -> 16861.1 | H19: Bio VND | M19: Face value/CD/OJBV | N19: Market value/FI Bond/SHBV | O19: =TRIM(LEFT(N19,FIND("/",N19&"/")-1)) -> Market value | P19: =TRIM(MID(N19,FIND("/",N19)+1,FIND("/",N19&"/",FIND("/",N19)+1)-FIND("/",N19)-1)) -> FI Bond | Q19: =TRIM(RIGHT(N19,LEN(N19)-FIND("@",SUBSTITUTE(N19,"/","@",LEN(N19)-LEN(SUBSTITUTE(N19,"/","")))))) -> SHBV
A20: =RPT -> 46262 | B20: Face value | C20: FI Bond Listed On BS | G20: =Summary!BM6 -> 397.6106 | H20: Bio VND | M20: Face value/CD/VABV | N20: Market value/FI Bond/MCSB | O20: =TRIM(LEFT(N20,FIND("/",N20&"/")-1)) -> Market value | P20: =TRIM(MID(N20,FIND("/",N20)+1,FIND("/",N20&"/",FIND("/",N20)+1)-FIND("/",N20)-1)) -> FI Bond | Q20: =TRIM(RIGHT(N20,LEN(N20)-FIND("@",SUBSTITUTE(N20,"/","@",LEN(N20)-LEN(SUBSTITUTE(N20,"/","")))))) -> MCSB
A21: =RPT -> 46262 | B21: Face value | C21: FI Bond Unlisted On BS | G21: =Summary!BM5-SUM(FNRP_FIbond[Đối ứng])/10^9 -> 12000 | H21: Bio VND | N21: Market value/FI Bond/TCBV-HO | O21: =TRIM(LEFT(N21,FIND("/",N21&"/")-1)) -> Market value | P21: =TRIM(MID(N21,FIND("/",N21)+1,FIND("/",N21&"/",FIND("/",N21)+1)-FIND("/",N21)-1)) -> FI Bond | Q21: =TRIM(RIGHT(N21,LEN(N21)-FIND("@",SUBSTITUTE(N21,"/","@",LEN(N21)-LEN(SUBSTITUTE(N21,"/","")))))) -> TCBV-HO
A22: =RPT -> 46262 | B22: Face value | C22: CD Off BS | G22: =Summary!BN7 -> 0 | H22: Bio VND | N22: Market value/FI Bond/PVFC | O22: =TRIM(LEFT(N22,FIND("/",N22&"/")-1)) -> Market value | P22: =TRIM(MID(N22,FIND("/",N22)+1,FIND("/",N22&"/",FIND("/",N22)+1)-FIND("/",N22)-1)) -> FI Bond | Q22: =TRIM(RIGHT(N22,LEN(N22)-FIND("@",SUBSTITUTE(N22,"/","@",LEN(N22)-LEN(SUBSTITUTE(N22,"/","")))))) -> PVFC
A23: =RPT -> 46262 | B23: Face value | C23: FI Bond Listed Off BS | G23: =Summary!BN6 -> 0 | H23: Bio VND | N23: Market value/FI Bond/SGTT | O23: =TRIM(LEFT(N23,FIND("/",N23&"/")-1)) -> Market value | P23: =TRIM(MID(N23,FIND("/",N23)+1,FIND("/",N23&"/",FIND("/",N23)+1)-FIND("/",N23)-1)) -> FI Bond | Q23: =TRIM(RIGHT(N23,LEN(N23)-FIND("@",SUBSTITUTE(N23,"/","@",LEN(N23)-LEN(SUBSTITUTE(N23,"/","")))))) -> SGTT
A24: =RPT -> 46262 | B24: Face value | C24: FI Bond Unlisted Off BS | G24: =Summary!BN5 -> 0 | H24: Bio VND | N24: Face value/CD/VIETBANK | O24: =TRIM(LEFT(N24,FIND("/",N24&"/")-1)) -> Face value | P24: =TRIM(MID(N24,FIND("/",N24)+1,FIND("/",N24&"/",FIND("/",N24)+1)-FIND("/",N24)-1)) -> CD | Q24: =TRIM(RIGHT(N24,LEN(N24)-FIND("@",SUBSTITUTE(N24,"/","@",LEN(N24)-LEN(SUBSTITUTE(N24,"/","")))))) -> VIETBANK
A25: =RPT -> 46262 | B25: Face value | C25: CD Ngoai BS | G25: =Summary!BO7 -> 10338 | H25: Bio VND | N25: Face value/CD/HCVN | O25: =TRIM(LEFT(N25,FIND("/",N25&"/")-1)) -> Face value | P25: =TRIM(MID(N25,FIND("/",N25)+1,FIND("/",N25&"/",FIND("/",N25)+1)-FIND("/",N25)-1)) -> CD | Q25: =TRIM(RIGHT(N25,LEN(N25)-FIND("@",SUBSTITUTE(N25,"/","@",LEN(N25)-LEN(SUBSTITUTE(N25,"/","")))))) -> HCVN
A26: =RPT -> 46262 | B26: Face value | C26: FI Bond Listed Ngoai BS | G26: =Summary!BO6 -> 0 | H26: Bio VND | N26: Face value/CD/SGTT | O26: =TRIM(LEFT(N26,FIND("/",N26&"/")-1)) -> Face value | P26: =TRIM(MID(N26,FIND("/",N26)+1,FIND("/",N26&"/",FIND("/",N26)+1)-FIND("/",N26)-1)) -> CD | Q26: =TRIM(RIGHT(N26,LEN(N26)-FIND("@",SUBSTITUTE(N26,"/","@",LEN(N26)-LEN(SUBSTITUTE(N26,"/","")))))) -> SGTT
A27: =RPT -> 46262 | B27: Face value | C27: FI Bond Unlisted Ngoai BS | G27: =Summary!BO5 -> 0 | H27: Bio VND | N27: Face value/CD/EIBV | O27: =TRIM(LEFT(N27,FIND("/",N27&"/")-1)) -> Face value | P27: =TRIM(MID(N27,FIND("/",N27)+1,FIND("/",N27&"/",FIND("/",N27)+1)-FIND("/",N27)-1)) -> CD | Q27: =TRIM(RIGHT(N27,LEN(N27)-FIND("@",SUBSTITUTE(N27,"/","@",LEN(N27)-LEN(SUBSTITUTE(N27,"/","")))))) -> EIBV
A28: =RPT -> 46262 | B28: Face value | C28: FIBond KGS | G28: =Summary!DB1 -> 569.8172 | H28: Bio VND | N28: Face value/CD/ABBV
A29: =RPT -> 46262 | B29: Market value | C29: FI Bond | G29: {=Summary!Y3+SUM(FNRP_ITB_2[MarketValue_VND]/10^9)} -> 13363.559 | H29: Bio VND | I29: Dinh gia dung Yield Curve = Yield GovBond + 50bps | N29: Face value/CD/TCBV-HO | O29: =TRIM(LEFT(N29,FIND("/",N29&"/")-1)) -> Face value | P29: =TRIM(MID(N29,FIND("/",N29)+1,FIND("/",N29&"/",FIND("/",N29)+1)-FIND("/",N29)-1)) -> CD | Q29: =TRIM(RIGHT(N29,LEN(N29)-FIND("@",SUBSTITUTE(N29,"/","@",LEN(N29)-LEN(SUBSTITUTE(N29,"/","")))))) -> TCBV-HO
A30: =RPT -> 46262 | B30: Market value | C30: FI Bond | E30: 3M | G30: =HLOOKUP(E30,Summary!$Z$1:$AK$3,3,0) -> 5.3590433 | H30: Bio VND | N30: Face value/CD/OCBV | O30: =TRIM(LEFT(N30,FIND("/",N30&"/")-1)) -> Face value | P30: =TRIM(MID(N30,FIND("/",N30)+1,FIND("/",N30&"/",FIND("/",N30)+1)-FIND("/",N30)-1)) -> CD | Q30: =TRIM(RIGHT(N30,LEN(N30)-FIND("@",SUBSTITUTE(N30,"/","@",LEN(N30)-LEN(SUBSTITUTE(N30,"/","")))))) -> OCBV
A31: =RPT -> 46262 | B31: Market value | C31: FI Bond | E31: 6M | G31: =HLOOKUP(E31,Summary!$Z$1:$AK$3,3,0) -> 404.03697 | H31: Bio VND | N31: Face value/CD/VCCB | O31: =TRIM(LEFT(N31,FIND("/",N31&"/")-1)) -> Face value | P31: =TRIM(MID(N31,FIND("/",N31)+1,FIND("/",N31&"/",FIND("/",N31)+1)-FIND("/",N31)-1)) -> CD | Q31: =TRIM(RIGHT(N31,LEN(N31)-FIND("@",SUBSTITUTE(N31,"/","@",LEN(N31)-LEN(SUBSTITUTE(N31,"/","")))))) -> VCCB
A32: =RPT -> 46262 | B32: Market value | C32: FI Bond | E32: 1Y | G32: =HLOOKUP(E32,Summary!$Z$1:$AK$3,3,0) -> 3593.0459 | H32: Bio VND | N32: Face value/CD/HDBV | O32: =TRIM(LEFT(N32,FIND("/",N32&"/")-1)) -> Face value | P32: =TRIM(MID(N32,FIND("/",N32)+1,FIND("/",N32&"/",FIND("/",N32)+1)-FIND("/",N32)-1)) -> CD | Q32: =TRIM(RIGHT(N32,LEN(N32)-FIND("@",SUBSTITUTE(N32,"/","@",LEN(N32)-LEN(SUBSTITUTE(N32,"/","")))))) -> HDBV
A33: =RPT -> 46262 | B33: Market value | C33: FI Bond | E33: 2Y | G33: =HLOOKUP(E33,Summary!$Z$1:$AK$3,3,0) -> 743.41603 | H33: Bio VND | N33: Face value/CD/LVBT | O33: =TRIM(LEFT(N33,FIND("/",N33&"/")-1)) -> Face value | P33: =TRIM(MID(N33,FIND("/",N33)+1,FIND("/",N33&"/",FIND("/",N33)+1)-FIND("/",N33)-1)) -> CD | Q33: =TRIM(RIGHT(N33,LEN(N33)-FIND("@",SUBSTITUTE(N33,"/","@",LEN(N33)-LEN(SUBSTITUTE(N33,"/","")))))) -> LVBT
A34: =RPT -> 46262 | B34: Market value | C34: FI Bond | E34: 3Y | G34: =HLOOKUP(E34,Summary!$Z$1:$AK$3,3,0) -> 3357.4955 | H34: Bio VND | N34: Face value/CD/SABH | O34: =TRIM(LEFT(N34,FIND("/",N34&"/")-1)) -> Face value | P34: =TRIM(MID(N34,FIND("/",N34)+1,FIND("/",N34&"/",FIND("/",N34)+1)-FIND("/",N34)-1)) -> CD | Q34: =TRIM(RIGHT(N34,LEN(N34)-FIND("@",SUBSTITUTE(N34,"/","@",LEN(N34)-LEN(SUBSTITUTE(N34,"/","")))))) -> SABH
A35: =RPT -> 46262 | B35: Market value | C35: FI Bond | E35: 4Y | G35: =HLOOKUP(E35,Summary!$Z$1:$AK$3,3,0) -> 0 | H35: Bio VND | N35: Face value/CD/BIDV | O35: =TRIM(LEFT(N35,FIND("/",N35&"/")-1)) -> Face value | P35: =TRIM(MID(N35,FIND("/",N35)+1,FIND("/",N35&"/",FIND("/",N35)+1)-FIND("/",N35)-1)) -> CD | Q35: =TRIM(RIGHT(N35,LEN(N35)-FIND("@",SUBSTITUTE(N35,"/","@",LEN(N35)-LEN(SUBSTITUTE(N35,"/","")))))) -> BIDV
A36: =RPT -> 46262 | B36: Market value | C36: FI Bond | E36: 5Y | G36: =HLOOKUP(E36,Summary!$Z$1:$AK$3,3,0) -> 0 | H36: Bio VND | N36: Face value/CD/TC_DIENLUC | O36: =TRIM(LEFT(N36,FIND("/",N36&"/")-1)) -> Face value | P36: =TRIM(MID(N36,FIND("/",N36)+1,FIND("/",N36&"/",FIND("/",N36)+1)-FIND("/",N36)-1)) -> CD | Q36: =TRIM(RIGHT(N36,LEN(N36)-FIND("@",SUBSTITUTE(N36,"/","@",LEN(N36)-LEN(SUBSTITUTE(N36,"/","")))))) -> TC_DIENLUC
A37: =RPT -> 46262 | B37: Market value | C37: FI Bond | E37: 7Y | G37: =HLOOKUP(E37,Summary!$Z$1:$AK$3,3,0)+SUM(FNRP_ITB_2[MarketValue_VND])/10^9 -> 5260.2057 | H37: Bio VND | N37: Face value/CD/MCSB | O37: =TRIM(LEFT(N37,FIND("/",N37&"/")-1)) -> Face value | P37: =TRIM(MID(N37,FIND("/",N37)+1,FIND("/",N37&"/",FIND("/",N37)+1)-FIND("/",N37)-1)) -> CD | Q37: =TRIM(RIGHT(N37,LEN(N37)-FIND("@",SUBSTITUTE(N37,"/","@",LEN(N37)-LEN(SUBSTITUTE(N37,"/","")))))) -> MCSB
