Workbook

Sheet Cap deal
A1: Deal S | B1: Deal B | C1: Ma TP | D1: Doi tac | E1: Coupon (%) | F1: Menh gia (ty) | G1: Chan thanh toan truoc | H1: Ky han (ngay) | I1: Settlement S | J1: Settlement B | K1: CaptureDate S | L1: CaptureDate B | M1: Gross S (VND) | N1: Gross B (VND) | O1: Lai/lo (VND) | P1: Lai/lo (trieu) | Q1: %/nam | R1: Dau | S1: Nhom | T1: Tach chan | U1: Yield S | V1: Yield B | W1: Dyield (bp) | X1: Folder S | Y1: Folder B
A2: 49944 | B2: 49945 | C2: TD2454043 | D2: CK_SGHN | E2: 2.8 | F2: 250 | G2: Sell (repo) | H2: 1 | I2: 46183 | J2: 46184 | K2: 46181 | L2: 46181 | M2: 180077500000 | N2: 180102500000 | O2: -25000000 | P2: -25 | Q2: -0.050672627 | R2: am | S2: Vay tien | U2: 4.7 | V2: 4.7 | W2: 0 | X2: AFS-DCM | Y2: AFS-DCM
A3: 49946 | B3: 49947 | C3: TD2353151 | D3: CK_SGHN | E3: 4.2 | F3: 150 | G3: Sell (repo) | H3: 1 | I3: 46183 | J3: 46184 | K3: 46181 | L3: 46181 | M3: 156219000000 | N3: 156111000000 | O3: 108000000 | P3: 108 | Q3: 0.25233806 | R3: duong | S3: Cho vay bond | U3: 4 | V3: 4.005 | W3: 0.5 | X3: AFS-DCM | Y3: AFS-DCM
A4: 49948 | B4: 49949 | C4: TD2434024 | D4: CK_SGHN | E4: 2.7 | F4: 100 | G4: Sell (repo) | H4: 1 | I4: 46183 | J4: 46184 | K4: 46181 | L4: 46181 | M4: 100285000000 | N4: 100293000000 | O4: -8000000 | P4: -8 | Q4: -0.029117017 | R4: am | S4: Vay tien | U4: 3 | V4: 3 | W4: 0 | X4: AFS-HUONG | Y4: AFS-HUONG
A5: 49950 | B5: 49951 | C5: TD1429095 | D5: CK_SGHN | E5: 7 | F5: 39 | G5: Sell (repo) | H5: 1 | I5: 46183 | J5: 46184 | K5: 46181 | L5: 46181 | M5: 44404230000 | N5: 44406960000 | O5: -2730000 | P5: -2.73 | Q5: -0.02244043 | R5: am | S5: Vay tien | U5: 3.971 | V5: 3.9725 | W5: 0.15 | X5: AFS-DCM | Y5: AFS-DCM
A6: 49952 | B6: 49953 | C6: TD1429095 | D6: CK_VNDIREC | E6: 7 | F6: 51 | G6: Sell (repo) | H6: 1 | I6: 46183 | J6: 46184 | K6: 46181 | L6: 46181 | M6: 58067070000 | N6: 58073190000 | O6: -6120000 | P6: -6.12 | Q6: -0.038469308 | R6: am | S6: Vay tien | U6: 3.971 | V6: 3.9711 | W6: 0.01 | X6: AFS-DCM | Y6: AFS-DCM
A7: 49954 | B7: 49955 | C7: TD2434026 | D7: CK_VNDIREC | E7: 2.6 | F7: 150 | G7: Sell (repo) | H7: 1 | I7: 46183 | J7: 46184 | K7: 46181 | L7: 46181 | M7: 148171500000 | N7: 148123500000 | O7: 48000000 | P7: 48 | Q7: 0.11824136 | R7: duong | S7: Cho vay bond | U7: 3.02 | V7: 3.0256 | W7: 0.56 | X7: AFS-HUONG | Y7: AFS-HUONG
A8: 49956 | B8: 49957 | C8: TD1646503 | D8: CK_VIETIN | E8: 7.9 | F8: 80 | G8: Sell (repo) | H8: 3 | I8: 46188 | J8: 46191 | K8: 46181 | L8: 46181 | M8: 125485600000 | N8: 125514400000 | O8: -28800000 | P8: -28.8 | Q8: -0.027923523 | R8: am | S8: Vay tien | U8: 4.1079 | V8: 4.1088 | W8: 0.09 | X8: AFS-DCM | Y8: AFS-DCM
A9: 49958 | B9: 49959 | C9: TD2252132 | D9: CK_VIETIN | E9: 2.9 | F9: 201 | G9: Sell (repo) | H9: 3 | I9: 46195 | J9: 46198 | K9: 46181 | L9: 46181 | M9: 160261320000 | N9: 160289460000 | O9: -28140000 | P9: -28.14 | Q9: -0.021363233 | R9: am | S9: Vay tien | U9: 4.305 | V9: 4.306 | W9: 0.1 | X9: AFS-DCM | Y9: AFS-DCM
A10: 49960 | B10: 49961 | C10: TL1545363 | D10: CK_VIETIN | E10: 8 | F10: 20 | G10: Sell (repo) | H10: 3 | I10: 46195 | J10: 46198 | K10: 46181 | L10: 46181 | M10: 31087600000 | N10: 31103200000 | O10: -15600000 | P10: -15.6 | Q10: -0.061053282 | R10: am | S10: Vay tien | U10: 4.1027 | V10: 4.1012 | W10: -0.15 | X10: AFS-DCM | Y10: AFS-DCM
A11: 49962 | B11: 49963 | C11: TD2050035 | D11: CK_VNDIREC | E11: 3.8 | F11: 270 | G11: Sell (repo) | H11: 1 | I11: 46184 | J11: 46185 | K11: 46181 | L11: 46181 | M11: 246912300000 | N11: 246863700000 | O11: 48600000 | P11: 48.6 | Q11: 0.071843323 | R11: duong | S11: Cho vay bond | U11: 4.5 | V11: 4.5022 | W11: 0.22 | X11: AFS-DCM | Y11: AFS-DCM
A12: 49972 | B12: 49973 | C12: TD2434024 | D12: CK_VFS | E12: 2.7 | F12: 100 | G12: Sell (repo) | H12: 3 | I12: 46185 | J12: 46188 | K12: 46182 | L12: 46182 | M12: 100301000000 | N12: 100281000000 | O12: 20000000 | P12: 20 | Q12: 0.02426031 | R12: duong | S12: Cho vay bond | U12: 3 | V12: 3.0064 | W12: 0.64 | X12: AFS-HUONG | Y12: AFS-HUONG
A13: 49974 | B13: 49975 | C13: TD2333117 | D13: CK_VIETCAP | E13: 4.2 | F13: 100 | G13: Sell (repo) | H13: 1 | I13: 46189 | J13: 46190 | K13: 46183 | L13: 46183 | M13: 108897000000 | N13: 108720000000 | O13: 177000000 | P13: 177 | Q13: 0.59326703 | R13: duong | S13: Cho vay bond | U13: 2.96 | V13: 2.99 | W13: 3 | X13: AFS-DCM | Y13: AFS-DCM
... A28: 50006 | B28: 50007 | C28: TD1646503 | D28: CK_VIETIN | E28: 7.9 | F28: 165 | G28: Sell (repo) | H28: 3 | I28: 46196 | J28: 46199 | K28: 46185 | L28: 46185 | M28: 262312050000 | N28: 262363200000 | O28: -51150000 | P28: -51.15 | Q28: -0.023724606 | R28: am | S28: Vay tien | U28: 4 | V28: 4.0011 | W28: 0.11 | X28: AFS-DCM | Y28: AFS-DCM
A29: 50010 | B29: 50009 | C29: TD2237126 | D29: QLQ_BAOVIE | E29: 4.9 | F29: 900 | G29: Buy (reverse repo) | H29: 141 | I29: 46330 | J29: 46189 | K29: 46185 | L29: 46185 | M29: 959445000000 | N29: 944847000000 | O29: 14598000000 | P29: 14598 | Q29: 0.039994993 | R29: duong | S29: Cho vay tien | T29: Co | U29: 4.6776 | V29: 4.65 | W29: -2.76 | X29: AFS-DCM | Y29: AFS-DCM
A30: 50011 | B30: 50009 | C30: TD2237126 | D30: QLQ_BAOVIE | E30: 4.9 | F30: 64 | G30: Buy (reverse repo) | H30: 141 | I30: 46330 | J30: 46189 | K30: 46185 | L30: 46185 | M30: 68227200000 | N30: 67189120000 | O30: 1038080000 | P30: 1038.08 | Q30: 0.039994993 | R30: duong | S30: Cho vay tien | U30: 4.6776 | V30: 4.65 | W30: -2.76 | X30: AFS-DCM | Y30: AFS-DCM
A31: 50011 | B31: 50008 | C31: TD2237126 | D31: QLQ_BAOVIE | E31: 4.9 | F31: 900 | G31: Buy (reverse repo) | H31: 141 | I31: 46330 | J31: 46189 | K31: 46185 | L31: 46185 | M31: 959445000000 | N31: 944847000000 | O31: 14598000000 | P31: 14598 | Q31: 0.039994993 | R31: duong | S31: Cho vay tien | T31: Co | U31: 4.6776 | V31: 4.65 | W31: -2.76 | X31: AFS-DCM | Y31: AFS-DCM
A32: 50012 | B32: 50013 | C32: TD2131012 | D32: CK_SSI | E32: 2.2 | F32: 50 | G32: Sell (repo) | H32: 8 | I32: 46190 | J32: 46198 | K32: 46185 | L32: 46185 | M32: 46565500000 | N32: 46606000000 | O32: -40500000 | P32: -40.5 | Q32: -0.039682007 | R32: am | S32: Vay tien | U32: 4.1 | V32: 4.1002 | W32: 0.02 | X32: AFS-DCM | Y32: AFS-DCM
A33: 50014 | B33: 50015 | C33: TD2434024 | D33: CK_SSI | E33: 2.7 | F33: 100 | G33: Sell (repo) | H33: 8 | I33: 46190 | J33: 46198 | K33: 46185 | L33: 46185 | M33: 99507000000 | N33: 99574000000 | O33: -67000000 | P33: -67 | Q33: -0.030720201 | R33: am | S33: Vay tien | U33: 3.1199 | V33: 3.12 | W33: 0.01 | X33: AFS-DCM | Y33: AFS-DCM
A34: 50016 | B34: 50017 | C34: TD2535028 | D34: CK_SSI | E34: 3.3 | F34: 250 | G34: Sell (repo) | H34: 8 | I34: 46190 | J34: 46198 | K34: 46185 | L34: 46185 | M34: 253607500000 | N34: 253797500000 | O34: -190000000 | P34: -190 | Q34: -0.034181757 | R34: am | S34: Vay tien | U34: 3.48 | V34: 3.4801 | W34: 0.01 | X34: AFS-DCM | Y34: AFS-DCM
A35: 50018 | B35: 50019 | C35: TD2535028 | D35: CK_SSI | E35: 3.3 | F35: 100 | G35: Sell (repo) | H35: 8 | I35: 46190 | J35: 46198 | K35: 46185 | L35: 46185 | M35: 101443000000 | N35: 101519000000 | O35: -76000000 | P35: -76 | Q35: -0.034181757 | R35: am | S35: Vay tien | U35: 3.48 | V35: 3.4801 | W35: 0.01 | X35: AFS-HUY | Y35: AFS-HUONG
A36: 50020 | B36: 50021 | C36: TD2333117 | D36: CK_SSI | E36: 4.2 | F36: 100 | G36: Sell (repo) | H36: 3 | I36: 46195 | J36: 46198 | K36: 46185 | L36: 46185 | M36: 108764000000 | N36: 108786000000 | O36: -22000000 | P36: -22 | Q36: -0.024609859 | R36: am | S36: Vay tien | U36: 2.9899 | V36: 2.9906 | W36: 0.07 | X36: AFS-DCM | Y36: AFS-DCM
A37: 50022 | B37: 50023 | C37: TD2333120 | D37: CK_SSI | E37: 2.4 | F37: 200 | G37: Sell (repo) | H37: 3 | I37: 46195 | J37: 46198 | K37: 46185 | L37: 46185 | M37: 197100000000 | N37: 197148000000 | O37: -48000000 | P37: -48 | Q37: -0.02962963 | R37: am | S37: Vay tien | U37: 3 | V37: 3 | W37: 0 | X37: AFS-DCM | Y37: AFS-DCM
A38: 50035 | B38: 50036 | C38: TD2353151 | D38: CK_THIENVI | E38: 4.2 | F38: 70 | G38: Sell (repo) | H38: 1 | I38: 46191 | J38: 46192 | K38: 46188 | L38: 46188 | M38: 72965200000 | N38: 72972900000 | O38: -7700000 | P38: -7.7 | Q38: -0.038518362 | R38: am | S38: Vay tien | U38: 4 | V38: 4 | W38: 0 | X38: AFS-DCM | Y38: AFS-DCM
A39: 50037 | B39: 50038 | C39: TD2535023 | D39: CK_THIENVI | E39: 2.9 | F39: 150 | G39: Sell (repo) | H39: 1 | I39: 46191 | J39: 46192 | K39: 46188 | L39: 46188 | M39: 144658500000 | N39: 144607500000 | O39: 51000000 | P39: 51 | Q39: 0.12868238 | R39: duong | S39: Cho vay bond | U39: 3.5 | V39: 3.506 | W39: 0.6 | X39: AFS-DCM | Y39: AFS-DCM
A40: 50039 | B40: 50040 | C40: TD1631461 | D40: CK_HDB | E40: 7.6 | F40: 366 | G40: Sell (repo) | H40: 8 | I40: 46195 | J40: 46203 | K40: 46188 | L40: 46188 | M40: 439251240000 | N40: 439210980000 | O40: 40260000 | P40: 40.26 | Q40: 0.0041818038 | R40: duong | S40: Cho vay bond | U40: 3.58 | V40: 3.6028 | W40: 2.28 | X40: AFS-DCM | Y40: AFS-DCM
A41: 50041 | B41: 50042 | C41: TL1545363 | D41: CK_HDB | E41: 8 | F41: 58 | G41: Sell (repo) | H41: 8 | I41: 46195 | J41: 46203 | K41: 46188 | L41: 46188 | M41: 91263000000 | N41: 91225880000 | O41: 37120000 | P41: 37.12 | Q41: 0.018557356 | R41: duong | S41: Cho vay bond | U41: 3.9958 | V41: 4.0069 | W41: 1.11 | X41: AFS-DCM | Y41: AFS-DCM
A42: 50043 | B42: 50044 | C42: TD2535024 | D42: CK_OCBS | E42: 2.9 | F42: 50 | G42: Sell (repo) | H42: 1 | I42: 46190 | J42: 46191 | K42: 46188 | L42: 46188 | M42: 48477500000 | N42: 48482000000 | O42: -4500000 | P42: -4.5 | Q42: -0.033881698 | R42: am | S42: Vay tien | U42: 3.41 | V42: 3.41 | W42: 0 | X42: AFS-HUONG | Y42: AFS-HUONG
A43: 50045 | B43: 50046 | C43: TD2434026 | D43: CK_OCBS | E43: 2.6 | F43: 150 | G43: Sell (repo) | H43: 1 | I43: 46190 | J43: 46191 | K43: 46188 | L43: 46188 | M43: 148042500000 | N43: 147996000000 | O43: 46500000 | P43: 46.5 | Q43: 0.11464613 | R43: duong | S43: Cho vay bond | U43: 3.04 | V43: 3.0456 | W43: 0.56 | X43: AFS-HUONG | Y43: AFS-HUONG
... A46: 50052 | B46: 50051 | C46: TL1535300 | D46: QLQ_BAOVIE | E46: 7.75 | F46: 848 | G46: Buy (reverse repo) | H46: 42 | I46: 46232 | J46: 46190 | K46: 46189 | L46: 46189 | M46: 1115925600000 | N46: 1110812160000 | O46: 5113440000 | P46: 5113.44 | Q46: 0.040005169 | R46: duong | S46: Cho vay tien | U46: 4.4565 | V46: 4.45 | W46: -0.65 | X46: AFS-DCM | Y46: AFS-DCM
A47: 50055 | B47: 50054 | C47: TD2050036 | D47: QLQ_BAOVIE | E47: 3.2 | F47: 250 | G47: Buy (reverse repo) | H47: 111 | I47: 46301 | J47: 46190 | K47: 46189 | L47: 46189 | M47: 201045000000 | N47: 198630000000 | O47: 2415000000 | P47: 2415 | Q47: 0.039979944 | R47: duong | S47: Cho vay tien | T47: Co | U47: 4.8148 | V47: 4.8 | W47: -1.48 | X47: AFS-DCM | Y47: AFS-DCM
A48: 50055 | B48: 50053 | C48: TD2050036 | D48: QLQ_BAOVIE | E48: 3.2 | F48: 270 | G48: Buy (reverse repo) | H48: 111 | I48: 46301 | J48: 46190 | K48: 46189 | L48: 46189 | M48: 217128600000 | N48: 214520400000 | O48: 2608200000 | P48: 2608.2 | Q48: 0.039979944 | R48: duong | S48: Cho vay tien | U48: 4.8148 | V48: 4.8 | W48: -1.48 | X48: AFS-DCM | Y48: AFS-DCM
A49: 50056 | B49: 50053 | C49: TD2050036 | D49: QLQ_BAOVIE | E49: 3.2 | F49: 250 | G49: Buy (reverse repo) | H49: 111 | I49: 46301 | J49: 46190 | K49: 46189 | L49: 46189 | M49: 201045000000 | N49: 198630000000 | O49: 2415000000 | P49: 2415 | Q49: 0.039979944 | R49: duong | S49: Cho vay tien | T49: Co | U49: 4.8148 | V49: 4.8 | W49: -1.48 | X49: AFS-DCM | Y49: AFS-DCM
A50: 50061 | B50: 50058 | C50: TD2237126 | D50: QLQ_BAOVIE | E50: 4.9 | F50: 167 | G50: Buy (reverse repo) | H50: 145 | I50: 46335 | J50: 46190 | K50: 46189 | L50: 46189 | M50: 178128880000 | N50: 175343320000 | O50: 2785560000 | P50: 2785.56 | Q50: 0.039989701 | R50: duong | S50: Cho vay tien | T50: Co | U50: 4.6785 | V50: 4.65 | W50: -2.85 | X50: AFS-DCM | Y50: AFS-DCM
A51: 50061 | B51: 50057 | C51: TD2237126 | D51: QLQ_BAOVIE | E51: 4.9 | F51: 554 | G51: Buy (reverse repo) | H51: 145 | I51: 46335 | J51: 46190 | K51: 46189 | L51: 46189 | M51: 590918560000 | N51: 581677840000 | O51: 9240720000 | P51: 9240.72 | Q51: 0.039989701 | R51: duong | S51: Cho vay tien | U51: 4.6785 | V51: 4.65 | W51: -2.85 | X51: AFS-DCM | Y51: AFS-DCM
A52: 50062 | B52: 50057 | C52: TD2237126 | D52: QLQ_BAOVIE | E52: 4.9 | F52: 167 | G52: Buy (reverse repo) | H52: 145 | I52: 46335 | J52: 46190 | K52: 46189 | L52: 46189 | M52: 178128880000 | N52: 175343320000 | O52: 2785560000 | P52: 2785.56 | Q52: 0.039989701 | R52: duong | S52: Cho vay tien | T52: Co | U52: 4.6785 | V52: 4.65 | W52: -2.85 | X52: AFS-DCM | Y52: AFS-DCM
A53: 50063 | B53: 50060 | C53: TD2141039 | D53: QLQ_BAOVIE | E53: 2.7 | F53: 200 | G53: Buy (reverse repo) | H53: 145 | I53: 46335 | J53: 46190 | K53: 46189 | L53: 46189 | M53: 162294000000 | N53: 159756000000 | O53: 2538000000 | P53: 2538 | Q53: 0.039990727 | R53: duong | S53: Cho vay tien | T53: Co | U53: 4.7221 | V53: 4.7 | W53: -2.21 | X53: AFS-DCM | Y53: AFS-DCM
A54: 50064 | B54: 50060 | C54: TD2141039 | D54: QLQ_BAOVIE | E54: 2.7 | F54: 50 | G54: Buy (reverse repo) | H54: 145 | I54: 46335 | J54: 46190 | K54: 46189 | L54: 46189 | M54: 40573500000 | N54: 39939000000 | O54: 634500000 | P54: 634.5 | Q54: 0.039990727 | R54: duong | S54: Cho vay tien | U54: 4.7221 | V54: 4.7 | W54: -2.21 | X54: AFS-DCM | Y54: AFS-DCM
A55: 50064 | B55: 50059 | C55: TD2141039 | D55: QLQ_BAOVIE | E55: 2.7 | F55: 200 | G55: Buy (reverse repo) | H55: 145 | I55: 46335 | J55: 46190 | K55: 46189 | L55: 46189 | M55: 162294000000 | N55: 159756000000 | O55: 2538000000 | P55: 2538 | Q55: 0.039990727 | R55: duong | S55: Cho vay tien | T55: Co | U55: 4.7221 | V55: 4.7 | W55: -2.21 | X55: AFS-DCM | Y55: AFS-DCM
A56: 50065 | B56: 50066 | C56: TD2434026 | D56: CK_LPBS | E56: 2.6 | F56: 150 | G56: Sell (repo) | H56: 3 | I56: 46192 | J56: 46195 | K56: 46189 | L56: 46189 | M56: 147961500000 | N56: 147939000000 | O56: 22500000 | P56: 22.5 | Q56: 0.018501434 | R56: duong | S56: Cho vay bond | U56: 3.05 | V56: 3.0555 | W56: 0.55 | X56: AFS-HUONG | Y56: AFS-DCM
...

Sheet Chan le
A1: Deal id | B1: Loai | C1: Ma TP | D1: Doi tac | E1: Coupon (%) | F1: Quantity | G1: FaceValue | H1: Gross da chuan hoa (VND) | I1: Gross goc la CHU? | J1: Settlement | K1: CaptureDate | L1: Folder | M1: Yield
A2: 49972 | B2: S | C2: TD2434024 | D2: CK_VFS | E2: 2.7 | F2: 1000000 | G2: 100000 | H2: 100301000000 | J2: 46185 | K2: 46182 | L2: AFS-HUONG | M2: 3
A3: 49973 | B3: B | C3: TD2434024 | D3: CK_VFS | E3: 2.7 | F3: 1000000 | G3: 100000 | H3: 100281000000 | J3: 46188 | K3: 46182 | L3: AFS-HUONG | M3: 3.0064
A4: 49993 | B4: B | C4: TD2353151 | D4: CK_LPBS | E4: 4.2 | F4: 700000 | G4: 100000 | H4: 72888900000 | J4: 46188 | K4: 46184 | L4: AFS-DCM | M4: 4.0045
A5: 50204 | B5: S | C5: TD2454043 | D5: CK_SGHN | E5: 2.8 | F5: 2250000 | G5: 100000 | H5: 171364500000 | J5: 46225 | K5: 46223 | L5: AFS-DCM | M5: 4.4007
A6: 50205 | B6: B | C6: TD2454043 | D6: CK_SGHN | E6: 2.8 | F6: 2250000 | G6: 100000 | H6: 171333000000 | J6: 46226 | K6: 46223 | L6: AFS-DCM | M6: 4.4025
A7: 50206 | B7: S | C7: TD2353151 | D7: CK_SGHN | E7: 4.2 | F7: 320000 | G7: 100000 | H7: 33477440000 | J7: 46225 | K7: 46223 | L7: AFS-DCM | M7: 4
A8: 50207 | B8: B | C8: TD2353151 | D8: CK_SGHN | E8: 4.2 | F8: 320000 | G8: 100000 | H8: 33467840000 | J8: 46226 | K8: 46223 | L8: AFS-DCM | M8: 4.0025
A9: 50222 | B9: S | C9: TD2353151 | D9: CK_BIDV | E9: 4.2 | F9: 4500000 | G9: 100000 | H9: 429574500000 | J9: 46239 | K9: 46225 | L9: AFS-DCM | M9: 4.6
A10: 50223 | B10: B | C10: TD2353151 | D10: CK_BIDV | E10: 4.2 | F10: 4500000 | G10: 100000 | H10: 431001000000 | J10: 46272 | K10: 46225 | L10: AFS-DCM | M10: 4.605
A11: 50224 | B11: S | C11: TD2353151 | D11: CK_BIDV | E11: 4.2 | F11: 2000000 | G11: 100000 | H11: 190922000000 | J11: 46239 | K11: 46225 | L11: AFS-DCM | M11: 4.6
A12: 50225 | B12: B | C12: TD2353151 | D12: CK_BIDV | E12: 4.2 | F12: 2000000 | G12: 100000 | H12: 191514000000 | J12: 46272 | K12: 46225 | L12: AFS-DCM | M12: 4.6064
A13: 50226 | B13: S | C13: TD2353151 | D13: CK_BIDV | E13: 4.2 | F13: 3000000 | G13: 100000 | H13: 286455000000 | J13: 46241 | K13: 46225 | L13: AFS-DCM | M13: 4.6
... A34: 50218 | B34: S | C34: TD2252132 | D34: QLQ_BAOVIE | E34: 2.9 | F34: 3370000 | G34: 100000 | H34: 250539280000 | J34: 46386 | K34: 46224 | L34: AFS-DCM | M34: 4.8953
A35: 50217 | B35: S | C35: TD1747409 | D35: QLQ_BAOVIE | E35: 7.9 | F35: 8620000 | G35: 100000 | H35: 1262166260000 | I35: CHU (x1000) | J35: 46386 | K35: 46224 | L35: AFS-DCM | M35: 4.83295
A36: 50216 | B36: S | C36: TD1747409 | D36: QLQ_BAOVIE | E36: 7.9 | F36: 2000000 | G36: 100000 | H36: 292846000000 | J36: 46386 | K36: 46224 | L36: AFS-DCM | M36: 4.83295
A37: 50215 | B37: B | C37: TD2252132 | D37: QLQ_BAOVIE | E37: 2.9 | F37: 1000000 | G37: 100000 | H37: 73094000000 | J37: 46226 | K37: 46224 | L37: AFS-DCM | M37: 4.87
A38: 50214 | B38: B | C38: TD2252132 | D38: QLQ_BAOVIE | E38: 2.9 | F38: 3370000 | G38: 100000 | H38: 246326780000 | J38: 46226 | K38: 46224 | L38: AFS-DCM | M38: 4.87
A39: 50213 | B39: B | C39: TD1747409 | D39: QLQ_BAOVIE | E39: 7.9 | F39: 8620000 | G39: 100000 | H39: 1240952440000 | I39: CHU (x1000) | J39: 46226 | K39: 46224 | L39: AFS-DCM | M39: 4.8
A40: 50212 | B40: B | C40: TD1747409 | D40: QLQ_BAOVIE | E40: 7.9 | F40: 2000000 | G40: 100000 | H40: 287924000000 | J40: 46226 | K40: 46224 | L40: AFS-DCM | M40: 4.8
A41: 50211 | B41: B | C41: TD2131012 | D41: CK_TCBS | E41: 2.2 | F41: 1000000 | G41: 100000 | H41: 92735000000 | J41: 46231 | K41: 46224 | L41: AFS-DCM | M41: 4.3155
A42: 50210 | B42: S | C42: TD2131012 | D42: CK_TCBS | E42: 2.2 | F42: 1000000 | G42: 100000 | H42: 93511000000 | J42: 46227 | K42: 46224 | L42: AFS-DCM | M42: 4.1
A43: 50209 | B43: B | C43: TL1535300 | D43: CK_TCBS | E43: 7.75 | F43: 8480000 | G43: 100000 | H43: 1116256320000 | I43: CHU (x1000) | J43: 46231 | K43: 46224 | L43: AFS-DCM | M43: 4.45
A44: 50208 | B44: S | C44: TL1535300 | D44: CK_TCBS | E44: 7.75 | F44: 8480000 | G44: 100000 | H44: 1115722080000 | I44: CHU (x1000) | J44: 46227 | K44: 46224 | L44: AFS-DCM | M44: 4.45
A45: 50203 | B45: S | C45: TL1545363 | D45: QLQ_BAOVIE | E45: 8 | F45: 8200000 | G45: 100000 | H45: 1202571000000 | I45: CHU (x1000) | J45: 46378 | K45: 46223 | L45: AFS-DCM | M45: 4.8326
A46: 50301 | B46: S | C46: TD1646468 | D46: CK_THIENVI | E46: 8 | F46: 335000 | G46: 100000 | H46: 50269765000 | J46: 46244 | K46: 46239 | L46: AFS-DCM | M46: 4.4349
A47: 50302 | B47: B | C47: TD1646468 | D47: CK_THIENVI | E47: 8 | F47: 335000 | G47: 100000 | H47: 50260050000 | J47: 46245 | K47: 46239 | L47: AFS-DCM | M47: 4.4377
A48: 50303 | B48: S | C48: TD2434022 | D48: CK_AGRIBAN | E48: 2.7 | F48: 1000000 | G48: 100000 | H48: 98924000000 | J48: 46245 | K48: 46239 | L48: AFS-DCM | M48: 2.91
A49: 50304 | B49: B | C49: TD2434022 | D49: CK_AGRIBAN | E49: 2.7 | F49: 1000000 | G49: 100000 | H49: 98927000000 | J49: 46259 | K49: 46239 | L49: AFS-DCM | M49: 2.9254
A50: 50305 | B50: S | C50: TD1631461 | D50: CK_AGRIBAN | E50: 7.6 | F50: 850000 | G50: 100000 | H50: 101669350000 | J50: 46244 | K50: 46239 | L50: AFS-DCM | M50: 3.8001
A51: 50306 | B51: S | C51: TD1631461 | D51: CK_AGRIBAN | E51: 7.6 | F51: 450000 | G51: 100000 | H51: 53824950000 | J51: 46244 | K51: 46239 | L51: AFS-DCM | M51: 3.8001
A52: 50307 | B52: B | C52: TD1631461 | D52: CK_AGRIBAN | E52: 7.6 | F52: 850000 | G52: 100000 | H52: 101671900000 | J52: 46245 | K52: 46239 | L52: AFS-DCM | M52: 3.8022
A53: 50308 | B53: S | C53: TD2535023 | D53: CK_BIDV | E53: 2.9 | F53: 1600000 | G53: 100000 | H53: 152331200000 | J53: 46248 | K53: 46239 | L53: AFS-DCM | M53: 3.75
A54: 50309 | B54: B | C54: TD2535023 | D54: CK_BIDV | E54: 2.9 | F54: 1600000 | G54: 100000 | H54: 152481600000 | J54: 46260 | K54: 46239 | L54: AFS-DCM | M54: 3.7531
A55: 50202 | B55: S | C55: TL1545363 | D55: QLQ_BAOVIE | E55: 8 | F55: 8000000 | G55: 100000 | H55: 1173240000000 | I55: CHU (x1000) | J55: 46378 | K55: 46223 | L55: AFS-DCM | M55: 4.8326
A56: 50201 | B56: B | C56: TL1545363 | D56: QLQ_BAOVIE | E56: 8 | F56: 8200000 | G56: 100000 | H56: 1183227200000 | I56: CHU (x1000) | J56: 46225 | K56: 46223 | L56: AFS-DCM | M56: 4.8
A57: 50200 | B57: B | C57: TL1545363 | D57: QLQ_BAOVIE | E57: 8 | F57: 8000000 | G57: 100000 | H57: 1154368000000 | I57: CHU (x1000) | J57: 46225 | K57: 46223 | L57: AFS-DCM | M57: 4.8
A58: 50199 | B58: B | C58: TD2252132 | D58: CK_VFS | E58: 2.9 | F58: 620000 | G58: 100000 | H58: 48043800000 | J58: 46225 | K58: 46220 | L58: AFS-DCM | M58: 4.5025
A59: 50198 | B59: S | C59: TD2252132 | D59: CK_VFS | E59: 2.9 | F59: 620000 | G59: 100000 | H59: 48053720000 | J59: 46224 | K59: 46220 | L59: AFS-DCM | M59: 4.5005
A60: 50194 | B60: B | C60: TD2434021 | D60: CK_SSI | E60: 2.4 | F60: 1000000 | G60: 100000 | H60: 95030000000 | J60: 46232 | K60: 46217 | L60: AFS-DCM | M60: 3.2452
...

Sheet Doi chieu
A1: Noi dung | B1: Cong thuc tinh song | C1: Phai ra
A2: A. TONG QUAT
A3: So cap da ghep | B3: =COUNTA('Cap deal'!A2:A199) | C3: 198
A4: So chan le nguon (sau loc folder) | B4: =COUNTA('Chan le'!A2:A375) | C4: 374
A6: B. KHOI LUONG PHAI OFFSET HET
A7: Sum Quantity chan S | B7: =SUMIF('Chan le'!B2:B375,"S",'Chan le'!F2:F375) | C7: 353.844.000
A8: Sum Quantity chan B | B8: =SUMIF('Chan le'!B2:B375,"B",'Chan le'!F2:F375) | C8: phai BANG dong tren
A9: Lech | B9: =B6-B7 | C9: 0
A11: C. LAI/LO - TIE HAI CHIEU
A12: Tu CHAN LE: Sum Gross(S) - Sum Gross(B) | B12: =SUMIF('Chan le'!B2:B375,"S",'Chan le'!H2:H375)-SUMIF('Chan le'!B2:B375,"B",'Chan le'!H2:H375) | C12: 263.574.510.000
A13: Tu CAP DEAL: Sum cot Lai/lo (VND) | B13: =SUM('Cap deal'!O2:O199) | C13: phai BANG dong tren
A14: Lech | B14: =B11-B12 | C14: 0 <- khac 0 la co van de
A16: D. MENH GIA
A17: Tu CHAN LE: Sum Quantity(S) x FaceValue / 1e9 | B17: =SUMIF('Chan le'!B2:B375,"S",'Chan le'!F2:F375)*100000/1000000000 | C17: 35.384,4 ty
A18: Tu CAP DEAL: Sum cot Menh gia | B18: =SUM('Cap deal'!F2:F199) | C18: phai BANG dong tren
A19: Lech | B19: =B16-B17 | C19: 0
A21: E. PHAN BO 4 NHOM (so cap)
A22: Vay tien | B22: =COUNTIF('Cap deal'!S2:S199,"Vay tien") | C22: 102
A23: Cho vay bond | B23: =COUNTIF('Cap deal'!S2:S199,"Cho vay bond") | C23: 59
A24: Cho vay tien | B24: =COUNTIF('Cap deal'!S2:S199,"Cho vay tien") | C24: 37
A25: Vay bond | B25: =COUNTIF('Cap deal'!S2:S199,"Vay bond") | C25: 0
A26: Tong | B26: =SUM(B21:B24) | C26: 198
A28: F. KIEM TRA LOGIC PHAN LOAI (dem dong SAI, phai = 0)
A29: Sell truoc + am ma KHONG phai "Vay tien" | B29: =SUMPRODUCT(('Cap deal'!G2:G199="Sell (repo)")*('Cap deal'!O2:O199<0)*('Cap deal'!S2:S199<>"Vay tien")) | C29: 0
A30: Sell truoc + duong ma KHONG phai "Cho vay bond" | B30: =SUMPRODUCT(('Cap deal'!G2:G199="Sell (repo)")*('Cap deal'!O2:O199>0)*('Cap deal'!S2:S199<>"Cho vay bond")) | C30: 0
A31: Buy truoc + duong ma KHONG phai "Cho vay tien" | B31: =SUMPRODUCT(('Cap deal'!G2:G199="Buy (reverse repo)")*('Cap deal'!O2:O199>0)*('Cap deal'!S2:S199<>"Cho vay tien")) | C31: 0
A32: Buy truoc + am ma KHONG phai "Vay bond" | B32: =SUMPRODUCT(('Cap deal'!G2:G199="Buy (reverse repo)")*('Cap deal'!O2:O199<0)*('Cap deal'!S2:S199<>"Vay bond")) | C32: 0
A34: G. KY HAN = KHOANG CACH 2 SETTLEMENT (dem dong SAI, phai = 0)
A35: So dong lech | B35: =SUMPRODUCT((ABS('Cap deal'!J2:J199-'Cap deal'!I2:I199)<>'Cap deal'!H2:H199)*1) | C35: 0
