Workbook
Name BOND.1: Code!$D$3
Name BOND.10: Code!$D$12
Name BOND.11: Code!$D$13
Name BOND.12: Code!$D$14
Name BOND.13: Code!$D$15
Name BOND.2: Code!$D$4
Name BOND.3: Code!$D$5
Name BOND.4: Code!$D$6
Name BOND.5: Code!$D$7
Name BOND.6: Code!$D$8
Name BOND.7: Code!$D$9
Name BOND.8: Code!$D$10
Name BOND.9: Code!$D$11
Name Lastmonth: 'Run Tool'!$B$4
Name Lastquater: 'Run Tool'!$B$8
Name Lastweek: 'Run Tool'!$B$6
Name Lastyear: 'Run Tool'!$B$5
Name May53.: Code!$A$1
Name MK.1: Code!$D$16
Name MK.2: Code!$D$17
Name MK.3: Code!$D$18
Name MK.4: Code!$D$19
Name RPT: 'Run Tool'!$B$2
Name RPT_LR: 'Run Tool'!$B$12
Name RPT_LR1: 'Run Tool'!$B$13
Name Yesterday: 'Run Tool'!$B$3

Sheet Run Tool
A1: Item | B1: Values | D1: Check | E1: Value | G1: Comment
A2: Rpt Date | B2: 46290 | D2: Có dữ liệu Bond ngày báo cáo chưa? | E2: =IF( AND(DATEVALUE(BOND!A4)=RPT,DATEVALUE(BOND!G4)=RPT,DATEVALUE(BOND!M4)=RPT,DATEVALUE(BOND!R4)=RPT,DATEVALUE(BOND!X4)=RPT,DATEVALUE(BOND!X4)=RPT,DATEVALUE(BOND!AC4)=RPT,DATEVALUE(BOND!AH4)=RPT,DATEVALUE(BOND!AN4)=RPT,DATEVALUE(BOND!AS4)=RPT,DATEVALUE(BOND!BB4)=RPT,DATEVALUE(BOND!BF4)=RPT,DATEVALUE(BOND!BJ4)=RPT,BOND!AX4=RPT_LR),"OK","CHECK") -> CHECK | G2: Executive Msg | H2: Executive Messages: (1) Chỉ số lỗ MtM của danh mục Bond Trading giữ mức 1.634 tỷ. Nếu yield tăng thêm 1 bps (~0.01%) ở tất cả các kỳ hạn, mức lỗ sẽ gia tăng thêm 11 tỷ. (2) Trạng thái danh mục GBond duy trì mức 17.513 tỷ - 88% hạn mức; Trạng thái danh mục FIBond & CD (bao gồm cả TPCP nước ngoài Kyrgyzstan) duy trì mức 39.414 tỷ - 88% hạn mức. (3) Lãi suất LNH kỳ ON tiếp tục giảm xuống 0.7% trong khi các kỳ dài hơn từ 1W-1M vẫn quanh mức 5-6%. Lưu ý rủi ro lỗ NIM vẫn tiềm ẩn do lãi suất có khả năng biến động mạnh. (4) Khe hở thanh khoản lũy kế - Gap 3M đang ở mức -25,2k tỷ, có xu hướng tăng chiều âm trong tháng 9, chủ yếu do giảm cho vay LNH kì 1-3M trong khi tăng huy động LNH kì dưới 3M
A3: Yesterday | B3: =WORKDAY(B2,-1,0) -> 46289 | D3: Có dữ liệu Market info ngày báo cáo chưa? | E3: =IF(AND(Market!A4=RPT,Market!E4=RPT,Market!I4=RPT,Market!M4=RPT),"OK","CHECK") -> CHECK | G3: Tiêu đề 1 | H3: Phân tách lại danh mục TD và BK GovBond
A4: Last month | B4: 46262 | C4: =WORKDAY(EOMONTH(RPT,-1)+1, -1) -> 46265 | D4: Có dữ liệu QLHS chưa? | E4: =IF(MAX(BOND!BN:BN)=Lastmonth,"OK","CHECK") -> OK | G4: Nội dung 1 | H4: Kể từ ngày báo cáo 10/08/2026, QLRR đã điều chỉnh danh mục Trading và Banking book theo bóc tách lại phần Danh mục Banking Gbond phù hợp với số vốn được Pool tài trợ 12k tỷ) từ DCM. Theo đó: (1) Danh mục theo mệnh giá của Trading book và Banking book tương ứng là: 17.413 tỷ và 10.848 tỷ. (2) Ngay tại thời điểm bóc tách lại (10/08), Lỗ MtM của danh mục Trading điều chỉnh tăng thêm 23 tỷ.
A5: last Year | B5: 45657 | D5: ItD của Trading Bond (limit 400 tỷ) | E5: =-SUMIFS(BOND!$AA:$AA,BOND!$Z:$Z,"",BOND!$X:$X,RPT) -> 1633.9373 | F5: =E5+SUMIFS(BOND!$AA:$AA,BOND!$Z:$Z,"",BOND!$X:$X,Yesterday) -> -0.36099488 | G5: Tiêu đề 2 | H5: Thay đổi ngưỡng mục tiêu bộ đệm thanh khoản
A6: Last week | B6: =RPT-WEEKDAY(RPT)-1 -> 46283 | D6: Trạng thái danh mục FIBond&CD (limit 44k, warning 40k) | E6: =SUMIFS(BOND!$AQ:$AQ,BOND!$AN:$AN,RPT) -> 39414.405 | F6: =E6-SUMIFS(BOND!$AQ:$AQ,BOND!$AN:$AN,Yesterday) -> -0.44888721 | G6: Nội dung 2 | H6: Sau bóc tách lại danh mục TD & BK, ngưỡng mục tiêu bộ đệm thanh khoản điều chỉnh từ 11.440 tỷ về 10.400 tỷ. QLRR lưu ý: (1) Banking Gbond dự phòng cần được sử dụng/tối ưu có chọn lọc trong điều kiện bình thường, nhằm tránh làm suy giảm năng lực ứng phó khi thị trường xuất hiện cú sốc nguồn vốn.
A7: Available bond | B7: ="\\filesrv01.msb.com.vn\06.Khoi Quan Ly Rui Ro\02.Trung Tam QLRR Thi Truong\03.Phong QLRRTK\Daily Report\LR_"&TEXT(RPT_LR,"yyyy.mm.dd")&"\MCO Report\Available bond_v5_"&TEXT(RPT_LR,"yyyy.mm.dd")&".xlsm" -> \\filesrv01.msb.com.vn\06.Khoi Quan Ly Rui Ro\02.Trung Tam QLRR Thi Truong\03.Phong QLRRTK\Daily Report\LR_2026.09.28\MCO Report\Available bond_v5_2026.09.28.xlsm | D7: Bộ đệm thanh khoản Available Bond | E7: =ROUND(SUMIFS(BOND!$AZ:$AZ,BOND!AY:AY,"Face_HLA",BOND!AX:AX,RPT_LR),0) -> 10769 | F7: =ROUND(SUMIFS(BOND!$AZ:$AZ,BOND!$AY:$AY,"Face_HLA",BOND!$AX:$AX,RPT_LR)-SUMIFS(BOND!$AZ:$AZ,BOND!$AY:$AY,"Face_HLA",BOND!$AX:$AX,RPT_LR1),0) -> -4560 | G7: Tiêu đề 3 | H7: Giám sát tình trạng NGOẠI LỆ vượt hạn mức lỗ mtm
A8: Last quarter | B8: 46203 | D8: Hạn mức bộ đệm thanh khoản | E8: =Executive!D78 -> 10300 | F8: =E7/E8 -> 1.045534 | G8: Nội dung 3 | H8: Danh mục Trading Gbond hiện ghi nhận lỗ MtM quanh 1.640 tỷ đồng (xu hướng tăng gần đây do yield tăng liên tục tuần qua) trên quy mô trạng thái rủi ro 17.413 tỷ đồng, vượt hạn mức 400 tỷ đồng và đang trong quá trình phê duyệt ngoại lệ. => QLRR khuyến nghị FI/DCM duy trì báo cáo định kỳ cấp có thẩm quyền, vẫn tiếp tục tìm kiếm các biện pháp giảm thiểu/xử lý lỗ và kiểm soát không để rủi ro tiếp tục gia tăng; báo cáo xin ý kiến cấp có thẩm quyền trong t/h phát sinh các nhân tố có thể làm leo thang đáng kể tình trạng lỗ mtm.
A9: QLHS | B9: \\filesrv01.msb.com.vn\06.Khoi Quan Ly Rui Ro\02.Trung Tam QLRR Thi Truong\02.Phong GSRRTT\05.Report\01.Daily Report\03. QLHS & VTC\00.Summary_EXCO FI.xlsx | D9: Trạng thái GovBond Trading | E9: =Executive!D19 -> 17513 | F9: =E9/20000 -> 0.87565 | G9: Tiêu đề 4 | H9: Rủi ro LỖ KÉP tiếp tục là ÁP LỰC CHÍNH
A10: BS FI | B10: ="\\filesrv01.msb.com.vn\06.Khoi Quan Ly Rui Ro\02.Trung Tam QLRR Thi Truong\03.Phong QLRRTK\Daily Report\LR_"&TEXT(RPT_LR,"yyyy.mm.dd")&"\MCO Report\BalanceSheet_FI_v2_"&TEXT(RPT_LR,"yyyy.mm.dd")&".xlsm" -> \\filesrv01.msb.com.vn\06.Khoi Quan Ly Rui Ro\02.Trung Tam QLRR Thi Truong\03.Phong QLRRTK\Daily Report\LR_2026.09.28\MCO Report\BalanceSheet_FI_v2_2026.09.28.xlsm | G10: Nội dung 4 | H10: Trong bối cảnh lợi suất trái phiếu tăng từ đầu tháng và chi phí vốn duy trì ở mức cao, các danh mục Banking Gbond, FIBond và Trading Gbond đang chịu đồng thời hai áp lực: lỗ đánh giá lại MtM và suy giảm NIM => Đây không chỉ là rủi ro thị trường ngắn hạn, mà là vấn đề cần được cân nhắc trong chiến lược phân bổ bảng cân đối (danh quy mô DM đầu tư) và tối ưu hiệu quả vốn.
A11: File csv | B11: ="\\filesrv01.msb.com.vn\06.Khoi Quan Ly Rui Ro\02.Trung Tam QLRR Thi Truong\02.Phong GSRRTT\05.Report\01.Daily Report\"&TEXT(RPT,"yyyy.mm.dd")&"\DAILY MR REPORT\Import_data.csv" -> \\filesrv01.msb.com.vn\06.Khoi Quan Ly Rui Ro\02.Trung Tam QLRR Thi Truong\02.Phong GSRRTT\05.Report\01.Daily Report\2026.09.25\DAILY MR REPORT\Import_data.csv | G11: Note | H11: Hệ thống tài trợ 12k tỷ để dự phòng thanh khoản cho kịch bản rút tiền gửi, tương ứng 10.848 tỷ theo mệnh giá.
A12: Reportdate LR | B12: =TODAY()-1 -> 46293
A13: Reportdate LR-1 | B13: =IF(WEEKDAY(RPT_LR)=1,RPT_LR-3,RPT_LR-1) -> 46292
A14: Daily tool | B14: ="Daily market risk report_"&TEXT(RPT,"yyyy.mm.dd")&".xlsb" -> Daily market risk report_2026.09.25.xlsb

Sheet Log
A1: RPT | B1: Nội dung | C1: PIC
A2: 45495 | B2: Bổ sung trạng thái đồng CNY | C2: tranglt38
A3: 45525 | B3: Bổ sung công thức On/off BS | C3: tranglt38
A4: 45554 | B4: Bổ sung note dự phóng vốn MR bộ SBV theo mục tiêu CAR | C4: tranglt38
A5: 45555 | B5: Bổ sung ngày kịch bản VaR Bond | C5: tranglt38
A6: 45587 | B6: Sửa lại công thức biến động yield kịch bản BB 95% do đang refer nhầm sang ngày của kịch bản TB 95% | C6: tranglt38
A7: 45604 | B7: Sử dụng công thức để sort kịch bản VaR thay cho việc vào sort tay; bỏ các doublecheck không cần thiết cho việc sort tay do không cần sort tay nữa. | C7: tranglt38
A8: 45623 | B8: Sửa lại bảng group tenor, đổi kì hạn <1M thành 0-1M Sửa công thức ghi nhận trạng thái IR kì hạn ON trong bảng trạng thái IR của FXDR (bổ sung bao gồm ON và Today tại bảng FX) | C8: tranglt38
A9: 45630 | B9: Sửa công thức PV01 Bond TB (công thức ngày T-1 và M-1 đang tham chiếu sai ngày) | C9: tranglt38
A10: 45636 | B10: Sửa công thức VaR Bond Bổ sung ngày kịch bản cho VaR FXDR Bổ sung các chỉ số VaR 99 cho Bond và FXDR (sửa code lấy dữ liệu + bổ sung trên bảng trình bày) | C10: tranglt38
A11: 45311 | B11: Bổ sung kịch bản Bond sum 10D | C11: tranglt38
A12: 45335 | B12: Sửa công thức trạng thái IR sản phẩm forward các kì dài hơn ON do tham chiếu sai cột group tenor | C12: tranglt38
A13: 45709 | B13: Thêm input vốn tự có trong input sheet FX, thêm công thức tính hạn mức trạng thái FX | C13: thaottp14
... A18: 45790 | B18: Sửa công thức tính biến động gapls kì 3-5Y tại kịch bản cho FXDR | C18: tranglt38
A19: 45806 | B19: Không chạy được báo cáo daily do mất kết nối tới server 53 - IT đổi IP của các thành viên trong phòng --> không gửi báo cáo
A20: 45820 | B20: Bổ sung hạn mức NTK/Tổng trạng thái | C20: tranglt38
A21: 45841 | B21: Bổ sung chú giải tác động yếu tố rủi ro tới danh mục | C21: tranglt38
A22: 45852 | B22: Bổ sung số liệu và chart PnL theo QLHS cho Bond và FXDR | C22: tranglt38
A23: 45854 | B23: Bổ sung 3 hạn mức BB Bond còn thiếu | C23: tranglt38
A24: 45855 | B24: Thêm hạn mức pos banking bond 17,000 | C24: thaottp14
A25: 45859 | B25: Kéo thêm dữ liệu FIBond, bổ sung hạn mức mới | C25: tranglt38
A26: 45869 | B26: Sửa lại các link đường dẫn do chuyển ổ chung toàn hàng | C26: tranglt38
A27: 45880 | B27: Sửa lại code kéo chỉ số tập trung của bond banking | C27: tranglt38
A28: 45896 | B28: Sửa code itd unrealized pnl của bond do bond điều chỉnh itd unrealized pnl cho công nợ KH | C28: tranglt38
A29: 45946 | B29: Sửa code vốn để kéo thêm vốn option. Bổ sung trình bày vốn option cả 2 bộ sổ | C29: tranglt38
A30: 45951 | B30: Bổ sung lại tính toán trigger và rule đèn cảnh báo. Bổ sung doublecheck các chỉ số vượt trigger 80% limit | C30: tranglt38
A31: 45978 | B31: Thêm bảng connection dữ liệu trạng thái USD theo sản phẩm | C31: thaottp14
... A42: 46259 | B42: Sửa lại công thức trong import từ công thức của AI | C42: thaottp14

Sheet Import
A1: Date | B1: Key | C1: Value | D1: Group: AI Module | E1: Description | F1: How to use
A2: =RPT -> 46290 | B2: moduleNav_aiRecommend | C2: ='AI module'!B2 -> Góc tham khảo: AI sẽ nói gì về MLIR hôm nay :)? | D2: AI Module | E2: Tên tab menu module AI | F2: Sửa cột Value rồi import sheet Data Import vào HTML. Các key format dùng giá trị CSS như #RRGGBB, px, số độ đậm, hoặc font-family.
A3: =RPT -> 46290 | B3: aiRecommendModuleTitle | C3: ='AI module'!B3 -> AI khuyến nghị hành động trong ngày | D3: AI Module | E3: Tên module AI
A4: =RPT -> 46290 | B4: aiRecommendModuleDesc | C4: ='AI module'!B4 -> Tự động rà soát dữ liệu hiện có sau import để tạo checklist ngắn gọn theo từng góc nhìn quản trị. | D4: AI Module | E4: Mô tả module AI
A5: =RPT -> 46290 | B5: aiRecommendModuleBadge | C5: ='AI module'!B5 -> Market Risk AI | D5: AI Module | E5: Badge nhỏ trong module AI
A6: =RPT -> 46290 | B6: aiRecommendTitle | C6: ='AI module'!B6 -> What does AI recommend for risk Today? | D6: AI Module | E6: Tiêu đề chính trước khi gen checklist
A7: =RPT -> 46290 | B7: aiRecommendDisclaimerHtml | C7: ='AI module'!B7 -> <b>Disclaimer:</b> Đây là nội dung gen tự động từ AI, chỉ để người đọc trải nghiệm và tham khảo thông tin gợi ý/lưu ý từ góc nhìn của AI. Không phải là khuyến nghị chính thức của QLRRTT&TK | D7: AI Module | E7: Nội dung disclaimer; HTML chỉ bôi đỏ/đậm chữ Disclaimer nếu HTML có CSS tương ứng
A8: =RPT -> 46290 | B8: aiRecommendSubtitle | C8: ='AI module'!B8 -> Mỗi lần bấm Generate, module sẽ rà soát lại dữ liệu đang hiển thị về Trading Gbond, MtM, Banking Gbond, Bond&CD-FI, Market II, thị trường và OMO để tạo checklist mới, không dùng lại checklist đã lưu trước đó. | D8: AI Module | E8: Subtitle module AI
A9: =RPT -> 46290 | B9: aiRecommendBackButton | C9: ='AI module'!B9 -> Back | D9: AI Module | E9: Nút quay lại checklist trước
A10: =RPT -> 46290 | B10: aiRecommendViewLeadership | C10: ='AI module'!B10 -> View lãnh đạo | D10: AI Module | E10: Tên view lãnh đạo
A11: =RPT -> 46290 | B11: aiRecommendViewSupervision | C11: ='AI module'!B11 -> View giám sát/khuyến nghị | D11: AI Module | E11: Tên view giám sát/khuyến nghị
A12: =RPT -> 46290 | B12: aiRecommendViewExecution | C12: ='AI module'!B12 -> View đơn vị thực hiện | D12: AI Module | E12: Tên view đơn vị thực hiện
A13: =RPT -> 46290 | B13: aiRecommendClearButton | C13: ='AI module'!B13 -> Xóa checklist hiện tại | D13: AI Module | E13: Nút xóa checklist hiện tại
A14: =RPT -> 46290 | B14: aiRecommendGenerateButton | C14: ='AI module'!B14 -> Generate new risk recommendation | D14: AI Module | E14: Nút gen checklist mới
... A51: =RPT -> 46290 | B51: importQualityStatusDone | C51: ='AI module'!B51 -> Done | D51: Import AI Check | E51: Trạng thái lỗi đã hết sau lần scan lại
A52: =RPT -> 46290 | B52: Key | C52: Value | D52: Module: Thông tin chung | E52: Group | F52: Note
A53: =RPT -> 46290 | B53: moduleNavLabel | C53: ='Module name'!B2 -> Menu báo cáo | D53: Thông tin chung | E53: Tên module | F53: Label thanh menu module
A54: =RPT -> 46290 | B54: moduleNav_executive | C54: ='Module name'!B3 -> Executive Messages | D54: Thông tin chung | E54: Tên module | F54: Tên tab module Executive Messages
A55: =RPT -> 46290 | B55: moduleNav_detailPortfolio | C55: ='Module name'!B4 -> Thông tin chi tiết Danh mục | D55: Thông tin chung | E55: Tên module | F55: Tên tab module Thông tin chi tiết Danh mục
A56: =RPT -> 46290 | B56: moduleNav_market | C56: ='Module name'!B5 -> Thông tin thị trường | D56: Thông tin chung | E56: Tên module | F56: Tên tab module Thông tin thị trường
A57: =RPT -> 46290 | B57: moduleNav_marketII | C57: ='Module name'!B6 -> Cơ cấu dòng tiền thanh khoản - Market II | D57: Thông tin chung | E57: Tên module | F57: Tên tab module Cơ cấu dòng tiền Market II
A58: =RPT -> 46290 | B58: moduleNav_import | C58: ='Module name'!B7 -> 🔒 Import Data | D58: Thông tin chung | E58: Tên module | F58: Tên tab module Import Data
A59: =RPT -> 46290 | B59: moduleNav_print | C59: ='Module name'!B8 -> In / PDF | D59: Thông tin chung | E59: Tên module | F59: Tên nút In / PDF trên thanh menu
A60: =RPT -> 46290 | B60: Key | C60: Value | D60: Module: Executive | E60: Section | F60: Field/Label
A61: =RPT -> 46290 | B61: reportDate | C61: =_xlfn.XLOOKUP(B61,Executive!B:B,Executive!D:D,,0) -> 46290 | D61: Executive Messages | E61: Header | F61: Tiêu đề module Executive
A62: =RPT -> 46290 | B62: reportMainTitle | C62: =_xlfn.XLOOKUP(B62,Executive!B:B,Executive!D:D,,0) -> Market & Liquidity Risk Report (Market II) | D62: Executive Messages
A63: =RPT -> 46290 | B63: reportSubtitle | C63: =_xlfn.XLOOKUP(B63,Executive!B:B,Executive!D:D,,0) -> Rủi ro thị trường - thanh khoản | Danh mục Gbond Banking Book & Trading Book | Theo dõi MtM, PV01, NIM và tín hiệu thị trường | D63: Executive Messages
A64: =RPT -> 46290 | B64: moduleExecutiveTitle | C64: =_xlfn.XLOOKUP(B64,Executive!B:B,Executive!D:D,,0) -> Executive Messages: (1) Chỉ số lỗ MtM của danh mục Bond Trading giữ mức 1.634 tỷ. Nếu yield tăng thêm 1 bps (~0.01%) ở tất cả các kỳ hạn, mức lỗ sẽ gia tăng thêm 11 tỷ. (2) Trạng thái danh mục GBond duy trì mức 17.513 tỷ - 88% hạn mức; Trạng thái danh mục FIBond & CD (bao gồm cả TPCP nước ngoài Kyrgyzstan) duy trì mức 39.414 tỷ - 88% hạn mức. (3) Lãi suất LNH kỳ ON tiếp tục giảm xuống 0.7% trong khi các kỳ dài hơn từ 1W-1M vẫn quanh mức 5-6%. Lưu ý rủi ro lỗ NIM vẫn tiềm ẩn do lãi suất có khả năng biến động mạnh. (4) Khe hở thanh khoản lũy kế - Gap 3M đang ở mức -25,2k tỷ, có xu hướng tăng chiều âm trong tháng 9, chủ yếu do giảm cho vay LNH kì 1-3M trong khi tăng huy động LNH kì dưới 3M | D64: Executive Messages | E64: Header | F64: Tiêu đề module Executive
A65: =RPT -> 46290 | B65: moduleExecutiveStatus | C65: =_xlfn.XLOOKUP(B65,Executive!B:B,Executive!D:D,,0) -> NGOẠI LỆ HẠN MỨC LỖ MtM & RỦI RO LỖ KÉP | D65: Executive Messages | E65: Header | F65: Trạng thái module Executive
A66: =RPT -> 46290 | B66: executiveMessageSectionTitle | C66: =_xlfn.XLOOKUP(B66,Executive!B:B,Executive!D:D,,0) -> 1. Thông điệp trọng tâm | D66: Executive Messages | E66: Thông điệp trọng tâm | F66: Tiêu đề section
A67: =RPT -> 46290 | B67: msg1Title | C67: =_xlfn.XLOOKUP(B67,Executive!B:B,Executive!D:D,,0) -> Phân tách lại danh mục TD và BK GovBond | D67: Executive Messages | E67: Thông điệp trọng tâm | F67: Tiêu đề 1
A68: =RPT -> 46290 | B68: msg1Body | C68: =_xlfn.XLOOKUP(B68,Executive!B:B,Executive!D:D,,0) -> Kể từ ngày báo cáo 10/08/2026, QLRR đã điều chỉnh danh mục Trading và Banking book theo bóc tách lại phần Danh mục Banking Gbond phù hợp với số vốn được Pool tài trợ 12k tỷ) từ DCM. Theo đó: (1) Danh mục theo mệnh giá của Trading book và Banking book tương ứng là: 17.413 tỷ và 10.848 tỷ. (2) Ngay tại thời điểm bóc tách lại (10/08), Lỗ MtM của danh mục Trading điều chỉnh tăng thêm 23 tỷ. | D68: Executive Messages | E68: Thông điệp trọng tâm | F68: Nội dung 1
A69: =RPT -> 46290 | B69: msg2Title | C69: =_xlfn.XLOOKUP(B69,Executive!B:B,Executive!D:D,,0) -> Thay đổi ngưỡng mục tiêu bộ đệm thanh khoản | D69: Executive Messages | E69: Thông điệp trọng tâm | F69: Tiêu đề 2
A70: =RPT -> 46290 | B70: msg2Body | C70: =_xlfn.XLOOKUP(B70,Executive!B:B,Executive!D:D,,0) -> Sau bóc tách lại danh mục TD & BK, ngưỡng mục tiêu bộ đệm thanh khoản điều chỉnh từ 11.440 tỷ về 10.400 tỷ. QLRR lưu ý: (1) Banking Gbond dự phòng cần được sử dụng/tối ưu có chọn lọc trong điều kiện bình thường, nhằm tránh làm suy giảm năng lực ứng phó khi thị trường xuất hiện cú sốc nguồn vốn. | D70: Executive Messages | E70: Thông điệp trọng tâm | F70: Nội dung 2
A71: =RPT -> 46290 | B71: msg3Title | C71: =_xlfn.XLOOKUP(B71,Executive!B:B,Executive!D:D,,0) -> Giám sát tình trạng NGOẠI LỆ vượt hạn mức lỗ mtm | D71: Executive Messages | E71: Thông điệp trọng tâm | F71: Tiêu đề 3
A72: =RPT -> 46290 | B72: msg3Body | C72: =_xlfn.XLOOKUP(B72,Executive!B:B,Executive!D:D,,0) -> Danh mục Trading Gbond hiện ghi nhận lỗ MtM quanh 1.640 tỷ đồng (xu hướng tăng gần đây do yield tăng liên tục tuần qua) trên quy mô trạng thái rủi ro 17.413 tỷ đồng, vượt hạn mức 400 tỷ đồng và đang trong quá trình phê duyệt ngoại lệ. => QLRR khuyến nghị FI/DCM duy trì báo cáo định kỳ cấp có thẩm quyền, vẫn tiếp tục tìm kiếm các biện pháp giảm thiểu/xử lý lỗ và kiểm soát không để rủi ro tiếp tục gia tăng; báo cáo xin ý kiến cấp có thẩm quyền trong t/h phát sinh các nhân tố có thể làm leo thang đáng kể tình trạng lỗ mtm. | D72: Executive Messages | E72: Thông điệp trọng tâm | F72: Nội dung 3
A73: =RPT -> 46290 | B73: msg4Title | C73: =_xlfn.XLOOKUP(B73,Executive!B:B,Executive!D:D,,0) -> Rủi ro LỖ KÉP tiếp tục là ÁP LỰC CHÍNH | D73: Executive Messages | E73: Thông điệp trọng tâm | F73: Tiêu đề 4
A74: =RPT -> 46290 | B74: msg4Body | C74: =_xlfn.XLOOKUP(B74,Executive!B:B,Executive!D:D,,0) -> Trong bối cảnh lợi suất trái phiếu tăng từ đầu tháng và chi phí vốn duy trì ở mức cao, các danh mục Banking Gbond, FIBond và Trading Gbond đang chịu đồng thời hai áp lực: lỗ đánh giá lại MtM và suy giảm NIM => Đây không chỉ là rủi ro thị trường ngắn hạn, mà là vấn đề cần được cân nhắc trong chiến lược phân bổ bảng cân đối (danh quy mô DM đầu tư) và tối ưu hiệu quả vốn. | D74: Executive Messages | E74: Thông điệp trọng tâm | F74: Nội dung 4
A75: =RPT -> 46290 | B75: executiveGbondSectionTitle | C75: =_xlfn.XLOOKUP(B75,Executive!B:B,Executive!D:D,,0) -> Tình hình rủi ro Danh mục Trái phiếu chính phủ | D75: Executive Messages | E75: KPI Gbond | F75: Tiêu đề nhóm
A76: =RPT -> 46290 | B76: tradingCardTitle | C76: =_xlfn.XLOOKUP(B76,Executive!B:B,Executive!D:D,,0) -> Trading Book chịu rủi ro thị trường | D76: Executive Messages | E76: Trading Book | F76: Tiêu đề card
...

Sheet MR>>

Sheet Code
A1: Provider=SQLOLEDB.1;Password=msb@2019;Persist Security Info=True;User ID=sa;Initial Catalog=GS_RRTT;Data Source=10.1.77.53,8888;Use Procedure for Prepare=1;Auto Translate=True;Packet Size=4096;Workstation ID=QLRR-TRANGTTQ3;Use Encryption for Data=False;Tag with column collation when possible=False
A2: STT | B2: Sản phẩm | C2: Para1 | D2: Code | E2: Mục đích code | F2: Connection name
A3: 1 | B3: BOND | C3: select RptDate, Indicators, Class,Tenor_Value,Actual from GS_RRTT.dbo.Bond_Trading_Historical a where Indicators like '%Trang thai mo' and Tenor_Value = '' and Class = 'All' and Input_data = 'Spot' and Rptdate >= | D3: =C3&TEXT(Lastyear,"'yyyy-m-d'")&"order by RptDate desc" -> select RptDate, Indicators, Class,Tenor_Value,Actual from GS_RRTT.dbo.Bond_Trading_Historical a where Indicators like '%Trang thai mo' and Tenor_Value = '' and Class = 'All' and Input_data = 'Spot' and Rptdate >='2024-12-31'order by RptDate desc | E3: Trạng thái Trading book theo kỳ hạn, theo loại trái phiếu | F3: BOND.1
A4: 2 | B4: BOND | C4: select RptDate, Indicators,Class, Tenor_Value,Actual from GS_RRTT.dbo.Bond_Banking_Historical a where Indicators like '%Trang thai mo' and Rpt_Grp = '' and Input_data = 'Spot' and Tenor_Value = '' and Class = 'All' and Rptdate >= | D4: =C4&TEXT(Lastyear,"'yyyy-m-d'")&"order by RptDate desc" -> select RptDate, Indicators,Class, Tenor_Value,Actual from GS_RRTT.dbo.Bond_Banking_Historical a where Indicators like '%Trang thai mo' and Rpt_Grp = '' and Input_data = 'Spot' and Tenor_Value = '' and Class = 'All' and Rptdate >='2024-12-31'order by RptDate desc | E4: Trạng thái Banking book theo kỳ hạn, theo loại trái phiếu | F4: BOND.2
A5: 3 | B5: BOND | C5: select RptDate, Indicators, Tenor_Value,Actual from GS_RRTT.dbo.Bond_Trading_Historical a where Indicators = 'PV01' and Tenor_Value = '' and Class = 'All' and Input_data = 'Spot' and Rptdate >= | D5: =C5&TEXT(Lastmonth,"'yyyy-m-d'")&"order by RptDate desc" -> select RptDate, Indicators, Tenor_Value,Actual from GS_RRTT.dbo.Bond_Trading_Historical a where Indicators = 'PV01' and Tenor_Value = '' and Class = 'All' and Input_data = 'Spot' and Rptdate >='2026-8-28'order by RptDate desc | E5: PV01 Trading book theo kỳ hạn | F5: BOND.3
A6: 4 | B6: BOND | C6: select RptDate,Indicators,Tenor_Value, Rpt_Grp,Actual from GS_RRTT.dbo.Bond_Banking_Historical where Indicators = 'PV01' and Tenor_Value = '' and Class = 'All' and Input_data = 'Spot' and Rptdate >= | D6: =C6&TEXT(Lastmonth,"'yyyy-m-d'")&"order by RptDate desc" -> select RptDate,Indicators,Tenor_Value, Rpt_Grp,Actual from GS_RRTT.dbo.Bond_Banking_Historical where Indicators = 'PV01' and Tenor_Value = '' and Class = 'All' and Input_data = 'Spot' and Rptdate >='2026-8-28'order by RptDate desc | E6: PV01 Banking book theo kỳ hạn | F6: BOND.4
A7: 5 | B7: BOND | C7: select RptDate, Indicators,Tenor_Value, Actual from GS_RRTT.dbo.Bond_Trading_Historical a where Indicators = 'Unrealized_ItD_MtM_PnL' and Tenor_Value = '' and Class = 'All' and Input_data = 'Spot' and Rptdate >= | D7: =C7&TEXT(Lastmonth,"'yyyy-m-d'")&"order by RptDate desc" -> select RptDate, Indicators,Tenor_Value, Actual from GS_RRTT.dbo.Bond_Trading_Historical a where Indicators = 'Unrealized_ItD_MtM_PnL' and Tenor_Value = '' and Class = 'All' and Input_data = 'Spot' and Rptdate >='2026-8-28'order by RptDate desc | E7: ItD Unrealized PnL Trading theo kỳ hạn | F7: BOND.5
A8: 6 | B8: BOND | C8: select RptDate, Indicators,Tenor_Value, Actual from GS_RRTT.dbo.Bond_Banking_Historical a where Indicators = 'ItD Unrealized PnL' and Tenor_Value = '' and Class = 'All' and Input_data = 'Spot' and Rptdate >= | D8: =C8&TEXT(Lastmonth,"'yyyy-m-d'")&"order by RptDate desc" -> select RptDate, Indicators,Tenor_Value, Actual from GS_RRTT.dbo.Bond_Banking_Historical a where Indicators = 'ItD Unrealized PnL' and Tenor_Value = '' and Class = 'All' and Input_data = 'Spot' and Rptdate >='2026-8-28'order by RptDate desc | E8: ItD Unrealized PnL banking theo kỳ hạn | F8: BOND.6
A9: 7 | B9: BOND | C9: select RptDate,Indicators,Input_data,Class,Actual from GS_RRTT.dbo.Bond_Trading_Historical where Indicators in ('ON BS','OFF BS','NGOAI BS','YTM_ON BS') and Rptdate >= | D9: =C9&TEXT(Lastyear,"'yyyy-m-d'")&"order by RptDate desc" -> select RptDate,Indicators,Input_data,Class,Actual from GS_RRTT.dbo.Bond_Trading_Historical where Indicators in ('ON BS','OFF BS','NGOAI BS','YTM_ON BS') and Rptdate >='2024-12-31'order by RptDate desc | E9: ON_OFF_NGOAI BS | F9: BOND.7
A10: 8 | B10: BOND | C10: select RptDate, Indicators, Product, Actual from GS_RRTT.dbo.FIBond_Historical where Product in ('FI Bond', 'CD') and Indicators = 'Face value' and Issuer = '' and Tenor = '' and Rptdate >= | D10: =C10&TEXT(Lastyear,"'yyyy-m-d'")&"order by RptDate desc" -> select RptDate, Indicators, Product, Actual from GS_RRTT.dbo.FIBond_Historical where Product in ('FI Bond', 'CD') and Indicators = 'Face value' and Issuer = '' and Tenor = '' and Rptdate >='2024-12-31'order by RptDate desc | E10: Face value FIBond | F10: BOND.8
A11: 9 | B11: BOND | C11: select RptDate, Indicators, Product, Actual from GS_RRTT.dbo.FIBond_Historical where Indicators in ('Face value','YTM binh quan') and Product like '% BS' and Rptdate >= | D11: =C11&TEXT(Lastyear,"'yyyy-m-d'")&"order by RptDate desc" -> select RptDate, Indicators, Product, Actual from GS_RRTT.dbo.FIBond_Historical where Indicators in ('Face value','YTM binh quan') and Product like '% BS' and Rptdate >='2024-12-31'order by RptDate desc | E11: FIBond On/Off/Ngoai BS & YTM | F11: BOND.9
A12: 10 | B12: BOND | C12: select Date,Indicators,Value from QLRRTT.dbo.MSB_Report_AvailableBond where indicators in ('Face_HLA','Face_Secured_Unused','Face_SBV_Overdraft','Face_OMO_Available','Face_HMNR_NAPAS') and Date >= | D12: =C12&TEXT(Lastmonth,"'yyyy-m-d'")&"order by Date desc" -> select Date,Indicators,Value from QLRRTT.dbo.MSB_Report_AvailableBond where indicators in ('Face_HLA','Face_Secured_Unused','Face_SBV_Overdraft','Face_OMO_Available','Face_HMNR_NAPAS') and Date >='2026-8-28'order by Date desc | E12: Available bond - dữ liệu LR | F12: BOND.10
A13: 11 | B13: BOND | C13: select RptDate,Indicators,Actual from GS_RRTT.dbo.Bond_Trading_Historical where indicators like 'Est %' and Rptdate = | D13: =C13&TEXT(RPT,"'yyyy-m-d'")&"order by RptDate desc" -> select RptDate,Indicators,Actual from GS_RRTT.dbo.Bond_Trading_Historical where indicators like 'Est %' and Rptdate ='2026-9-25'order by RptDate desc | E13: Ước tính NIM: Trạng thái nội bảng + YTM ước tính | F13: BOND.11
A14: 12 | B14: BOND | C14: select RptDate,Indicators,Actual from GS_RRTT.dbo.Bond_Trading_Historical where indicators in ('Realized off BS', 'Realized ngoai BS') and Rptdate >= | D14: =C14&TEXT(Yesterday,"'yyyy-m-d'")&"order by RptDate desc" -> select RptDate,Indicators,Actual from GS_RRTT.dbo.Bond_Trading_Historical where indicators in ('Realized off BS', 'Realized ngoai BS') and Rptdate >='2026-9-24'order by RptDate desc | E14: Ước tính Realized off BS | F14: BOND.12
A15: 13 | B15: BOND | C15: select RptDate, Indicators,Actual from GS_RRTT.dbo.Bond_Trading_Historical a where Indicators = 'YTM' and Rptdate >= | D15: =C15&TEXT(Yesterday,"'yyyy-m-d'")&"order by RptDate desc" -> select RptDate, Indicators,Actual from GS_RRTT.dbo.Bond_Trading_Historical a where Indicators = 'YTM' and Rptdate >='2026-9-24'order by RptDate desc | E15: YTM Trading | F15: BOND.13
A16: 15 | B16: Market info | C16: select RptDate,Tenor,Average as 'Yield' from GS_RRTT.dbo.All_Marketdata_Historical where Indicators like 'VBMA%' and Indicators not like 'VBMA.%' and Rptdate >= | D16: =C16&TEXT(Lastyear,"'yyyy-m-d'")&"order by RptDate desc" -> select RptDate,Tenor,Average as 'Yield' from GS_RRTT.dbo.All_Marketdata_Historical where Indicators like 'VBMA%' and Indicators not like 'VBMA.%' and Rptdate >='2024-12-31'order by RptDate desc | E16: Chuỗi yield 1 năm | F16: MK.1
A17: 16 | B17: Market info | C17: select RptDate,Indicators,Average from GS_RRTT.dbo.All_Marketdata_Historical where Class = 'LNH' and Indicators like '%VND' and Rptdate >= | D17: =C17&TEXT(Lastyear,"'yyyy-m-d'")&"order by RptDate desc" -> select RptDate,Indicators,Average from GS_RRTT.dbo.All_Marketdata_Historical where Class = 'LNH' and Indicators like '%VND' and Rptdate >='2024-12-31'order by RptDate desc | E17: Chuỗi ls LNH đồng VND | F17: MK.2
A18: 17 | B18: Market info | C18: select Date,Indicators,Value from QLRRTT.dbo.MSB_Report_Other_Data where Indicators like '%OMO%' and Date >= | D18: =C18&TEXT(Lastyear,"'yyyy-m-d'")&"order by Date desc" -> select Date,Indicators,Value from QLRRTT.dbo.MSB_Report_Other_Data where Indicators like '%OMO%' and Date >='2024-12-31'order by Date desc | E18: Chuỗi thông tin OMO_Lay tu LR | F18: MK.3
A19: 18 | B19: Market info | C19: select RptDate,Average as 'TygiaUV' from GS_RRTT.dbo.All_Marketdata_Historical where Indicators like 'UV1' and RptDate >= | D19: =C19&TEXT(Lastyear,"'yyyy-m-d'")&"order by RptDate desc" -> select RptDate,Average as 'TygiaUV' from GS_RRTT.dbo.All_Marketdata_Historical where Indicators like 'UV1' and RptDate >='2024-12-31'order by RptDate desc | E19: Chuỗi tỷ giá USDVND | F19: MK.4

Sheet BOND
A1: 1. Trang thai bond trading | G1: 2. Trang thai bond banking | M1: 3. PV01 trading | R1: 4. PV01 banking | X1: 5. ItD Unrealized PnL trading | AA1: =AA4-#REF! -> #REF! | AC1: 6. ItD Unrealized PnL banking | AH1: 7. On, off BS - Trading book | AN1: 8. Trang thai FI Bond | AS1: 9. FIBond On/Off/Ngoai BS & YTM | AX1: 10. Available bond | BB1: 11. Ước tính NIM | BF1: 12. Realized chưa ghi nhận | BJ1: 13. YTM | BN1: 14. QLHS
A3: RptDate | B3: Indicators | C3: Class | D3: Tenor_Value | E3: Actual | G3: RptDate | H3: Indicators | I3: Class | J3: Tenor_Value | K3: Actual | M3: RptDate | N3: Indicators | O3: Tenor_Value | P3: Actual | R3: RptDate | S3: Indicators | T3: Tenor_Value | U3: Actual | V3: Rpt_Grp | X3: RptDate | Y3: Indicators | Z3: Tenor_Value | AA3: Actual | AC3: RptDate | AD3: Indicators | AE3: Tenor_Value | AF3: Actual | AH3: RptDate | AI3: Indicators | AJ3: Input_data | AK3: Class | AL3: Actual | AN3: RptDate | AO3: Indicators | AP3: Product | AQ3: Actual | AS3: RptDate | AT3: Indicators | AU3: Product | AV3: Actual | AX3: Date | AY3: Indicators | AZ3: Value | BB3: RptDate | BC3: Indicators | BD3: Actual | BF3: RptDate | BG3: Indicators | BH3: Actual | BJ3: RptDate | BK3: Indicators | BL3: Actual | BN3: Date | BO3: Desk | BP3: Indicator | BQ3: Actual
A4: 2026-09-28 | B4: Trang thai mo | C4: All | E4: 17513 | G4: 2026-09-28 | H4: Trang thai mo | I4: All | K4: 10858.311 | M4: 2026-09-28 | N4: PV01 | P4: -10.543406 | R4: 2026-09-28 | S4: PV01 | U4: -8.3967355 | X4: 2026-09-28 | Y4: Unrealized_ItD_MtM_PnL | AA4: -1631.9295 | AC4: 2026-09-28 | AD4: ItD Unrealized PnL | AF4: -1738.7219 | AH4: 2026-09-28 | AI4: ON BS | AJ4: Face | AK4: All | AL4: 33460.3 | AN4: 2026-09-28 | AO4: Face value | AP4: FI Bond | AQ4: 11965.192 | AS4: 2026-09-28 | AT4: Face value | AU4: CD On BS | AV4: 18899.1 | AX4: 46293 | AY4: Face_HLA | AZ4: 10769.311 | BB4: 2026-09-25 | BC4: Est YTM T9 | BD4: 4.2464765 | BF4: 2026-09-28 | BG4: Realized off BS | BH4: -32.480626 | BJ4: 2026-09-28 | BK4: YTM | BL4: 3.0511557 | BN4: 46052 | BO4: Trading bonds_Govbond | BP4: NIM | BQ4: -14.84306
A5: 2026-09-25 | B5: Trang thai mo | C5: All | E5: 17513 | G5: 2026-09-25 | H5: Trang thai mo | I5: All | K5: 10858.311 | M5: 2026-09-25 | N5: PV01 | P5: -10.551946 | R5: 2026-09-25 | S5: PV01 | U5: -8.4014384 | X5: 2026-09-25 | Y5: Unrealized_ItD_MtM_PnL | AA5: -1633.9373 | AC5: 2026-09-25 | AD5: ItD Unrealized PnL | AF5: -1740.2885 | AH5: 2026-09-28 | AI5: ON BS | AJ5: MtM | AK5: All | AL5: 33706.984 | AN5: 2026-09-28 | AO5: Face value | AP5: CD | AQ5: 27449.1 | AS5: 2026-09-28 | AT5: Face value | AU5: FI Bond Listed On BS | AV5: 397.6106 | AX5: 46293 | AY5: Face_Secured_Unused | AZ5: -800 | BB5: 2026-09-25 | BC5: Est YTM T8 | BD5: 0 | BF5: 2026-09-28 | BG5: Realized ngoai BS | BH5: -0.61667935 | BJ5: 2026-09-25 | BK5: YTM | BL5: 3.0511557 | BN5: 46052 | BO5: Trading bonds_Govbond | BP5: Realized PnL | BQ5: 2.8633123
A6: 2026-09-24 | B6: Trang thai mo | C6: All | E6: 17513 | G6: 2026-09-24 | H6: Trang thai mo | I6: All | K6: 10858.311 | M6: 2026-09-24 | N6: PV01 | P6: -10.554996 | R6: 2026-09-24 | S6: PV01 | U6: -8.403096 | X6: 2026-09-24 | Y6: Unrealized_ItD_MtM_PnL | AA6: -1634.2983 | AC6: 2026-09-24 | AD6: ItD Unrealized PnL | AF6: -1740.6871 | AH6: 2026-09-28 | AI6: ON BS | AJ6: PTCK | AK6: All | AL6: 1710.1846 | AN6: 2026-09-25 | AO6: Face value | AP6: FI Bond | AQ6: 11965.305 | AS6: 2026-09-28 | AT6: Face value | AU6: FI Bond Unlisted On BS | AV6: 11000 | AX6: 46293 | AY6: Face_SBV_Overdraft | AZ6: -1459 | BB6: 2026-09-25 | BC6: Est YTM T7 | BD6: 0 | BF6: 2026-09-25 | BG6: Realized off BS | BH6: -35.502497 | BJ6: 2026-09-24 | BK6: YTM | BL6: 3.0511557 | BN6: 46052 | BO6: Trading bonds_FI bond | BP6: NIM | BQ6: -14.723
A7: 2026-09-23 | B7: Trang thai mo | C7: All | E7: 17513 | G7: 2026-09-23 | H7: Trang thai mo | I7: All | K7: 10858.311 | M7: 2026-09-23 | N7: PV01 | P7: -10.557814 | R7: 2026-09-23 | S7: PV01 | U7: -8.4046858 | X7: 2026-09-23 | Y7: Unrealized_ItD_MtM_PnL | AA7: -1635.0999 | AC7: 2026-09-23 | AD7: ItD Unrealized PnL | AF7: -1741.1784 | AH7: 2026-09-28 | AI7: ON BS | AJ7: Diff | AK7: All | AL7: -1463.5005 | AN7: 2026-09-25 | AO7: Face value | AP7: CD | AQ7: 27449.1 | AS7: 2026-09-28 | AT7: Face value | AU7: CD Off BS | AV7: 0 | AX7: 46293 | AY7: Face_HMNR_NAPAS | AZ7: -605 | BB7: 2026-09-25 | BC7: Est YTM T6 | BD7: 0 | BF7: 2026-09-25 | BG7: Realized ngoai BS | BH7: -0.60485888 | BN7: 46052 | BO7: Trading bonds_FI bond | BP7: Realized PnL | BQ7: -2.222
A8: 2026-09-22 | B8: Trang thai mo | C8: All | E8: 17513 | G8: 2026-09-22 | H8: Trang thai mo | I8: All | K8: 10858.311 | M8: 2026-09-22 | N8: PV01 | P8: -10.559507 | R8: 2026-09-22 | S8: PV01 | U8: -8.4057128 | X8: 2026-09-22 | Y8: Unrealized_ItD_MtM_PnL | AA8: -1637.6918 | AC8: 2026-09-22 | AD8: ItD Unrealized PnL | AF8: -1742.2555 | AH8: 2026-09-28 | AI8: ON BS | AJ8: ItD | AK8: All | AL8: -1432.6245 | AN8: 2026-09-24 | AO8: Face value | AP8: FI Bond | AQ8: 11965.754 | AS8: 2026-09-28 | AT8: Face value | AU8: FI Bond Listed Off BS | AV8: 0 | AX8: 46293 | AY8: Face_OMO_Available | AZ8: 7392.8209 | BB8: 2026-09-25 | BC8: Est YTM T5 | BD8: 0 | BF8: 2026-09-24 | BG8: Realized off BS | BH8: -33.975479 | BN8: 46052 | BO8: Banking bonds_Govbond | BP8: NIM | BQ8: -11.038693
A9: 2026-09-21 | B9: Trang thai mo | C9: All | E9: 17513 | G9: 2026-09-21 | H9: Trang thai mo | I9: All | K9: 10858.311 | M9: 2026-09-21 | N9: PV01 | P9: -10.563334 | R9: 2026-09-21 | S9: PV01 | U9: -8.4082436 | X9: 2026-09-21 | Y9: Unrealized_ItD_MtM_PnL | AA9: -1637.0596 | AC9: 2026-09-21 | AD9: ItD Unrealized PnL | AF9: -1741.8634 | AH9: 2026-09-28 | AI9: OFF BS | AJ9: Face | AK9: All | AL9: -17794.7 | AN9: 2026-09-24 | AO9: Face value | AP9: CD | AQ9: 27449.1 | AS9: 2026-09-28 | AT9: Face value | AU9: FI Bond Unlisted Off BS | AV9: 0 | AX9: 46292 | AY9: Face_HLA | AZ9: 15329.311 | BB9: 2026-09-25 | BC9: Est YTM T4 | BD9: 0 | BF9: 2026-09-24 | BG9: Realized ngoai BS | BH9: -2.4092188 | BN9: 46052 | BO9: Banking bonds_Govbond | BP9: Realized PnL | BQ9: -0.003892796
A10: 2026-09-18 | B10: Trang thai mo | C10: All | E10: 17513 | G10: 2026-09-18 | H10: Trang thai mo | I10: All | K10: 10858.311 | M10: 2026-09-18 | N10: PV01 | P10: -10.573884 | R10: 2026-09-18 | S10: PV01 | U10: -8.4146508 | X10: 2026-09-18 | Y10: Unrealized_ItD_MtM_PnL | AA10: -1637.485 | AC10: 2026-09-18 | AD10: ItD Unrealized PnL | AF10: -1741.8966 | AH10: 2026-09-28 | AI10: OFF BS | AJ10: MtM | AK10: All | AL10: -19411.76 | AN10: 2026-09-23 | AO10: Face value | AP10: FI Bond | AQ10: 12965.527 | AS10: 2026-09-28 | AT10: Face value | AU10: CD Ngoai BS | AV10: 8550 | AX10: 46292 | AY10: Face_Secured_Unused | AZ10: -800 | BB10: 2026-09-25 | BC10: Est YTM T3 | BD10: 0 | BN10: 46080 | BO10: Banking bonds_Govbond | BP10: Realized PnL | BQ10: -0.003892796
A11: 2026-09-17 | B11: Trang thai mo | C11: All | E11: 17513 | G11: 2026-09-17 | H11: Trang thai mo | I11: All | K11: 10858.311 | M11: 2026-09-17 | N11: PV01 | P11: -10.577626 | R11: 2026-09-17 | S11: PV01 | U11: -8.4177501 | X11: 2026-09-17 | Y11: Unrealized_ItD_MtM_PnL | AA11: -1637.4335 | AC11: 2026-09-17 | AD11: ItD Unrealized PnL | AF11: -1740.9607 | AH11: 2026-09-28 | AI11: OFF BS | AJ11: PTCK | AK11: All | AL11: -1515.1092 | AN11: 2026-09-23 | AO11: Face value | AP11: CD | AQ11: 28149.1 | AS11: 2026-09-28 | AT11: Face value | AU11: FI Bond Listed Ngoai BS | AV11: 0 | AX11: 46292 | AY11: Face_SBV_Overdraft | AZ11: -1459 | BB11: 2026-09-25 | BC11: Est YTM T2 | BD11: 0 | BN11: 46080 | BO11: Banking bonds_Govbond | BP11: NIM | BQ11: -11.430737
A12: 2026-09-16 | B12: Trang thai mo | C12: All | E12: 17513 | G12: 2026-09-16 | H12: Trang thai mo | I12: All | K12: 10858.311 | M12: 2026-09-16 | N12: PV01 | P12: -10.581797 | R12: 2026-09-16 | S12: PV01 | U12: -8.4199731 | X12: 2026-09-16 | Y12: Unrealized_ItD_MtM_PnL | AA12: -1636.2583 | AC12: 2026-09-16 | AD12: ItD Unrealized PnL | AF12: -1740.7866 | AH12: 2026-09-28 | AI12: OFF BS | AJ12: Diff | AK12: All | AL12: -101.95033 | AN12: 2026-09-22 | AO12: Face value | AP12: FI Bond | AQ12: 12966.387 | AS12: 2026-09-28 | AT12: Face value | AU12: FI Bond Unlisted Ngoai BS | AV12: 0 | AX12: 46292 | AY12: Face_HMNR_NAPAS | AZ12: -605 | BB12: 2026-09-25 | BC12: Est YTM T12 | BD12: 3.5992079 | BN12: 46080 | BO12: Trading bonds_FI bond | BP12: Realized PnL | BQ12: 3.048
A13: 2026-09-15 | B13: Trang thai mo | C13: All | E13: 17513 | G13: 2026-09-15 | H13: Trang thai mo | I13: All | K13: 10858.311 | M13: 2026-09-15 | N13: PV01 | P13: -10.584026 | R13: 2026-09-15 | S13: PV01 | U13: -8.4211269 | X13: 2026-09-15 | Y13: Unrealized_ItD_MtM_PnL | AA13: -1638.5772 | AC13: 2026-09-15 | AD13: ItD Unrealized PnL | AF13: -1741.6388 | AH13: 2026-09-28 | AI13: OFF BS | AJ13: ItD | AK13: All | AL13: -101.95033 | AN13: 2026-09-22 | AO13: Face value | AP13: CD | AQ13: 28749.1 | AS13: 2026-09-28 | AT13: YTM binh quan | AU13: FI Bond On BS | AV13: 7.6809373 | AX13: 46292 | AY13: Face_OMO_Available | AZ13: 7392.8209 | BB13: 2026-09-25 | BC13: Est YTM T11 | BD13: 3.8006658 | BN13: 46080 | BO13: Trading bonds_Govbond | BP13: Realized PnL | BQ13: 9.8120631
A14: 2026-09-14 | B14: Trang thai mo | C14: All | E14: 17663 | G14: 2026-09-14 | H14: Trang thai mo | I14: All | K14: 10858.311 | M14: 2026-09-14 | N14: PV01 | P14: -10.665756 | R14: 2026-09-14 | S14: PV01 | U14: -8.4239771 | X14: 2026-09-14 | Y14: Unrealized_ItD_MtM_PnL | AA14: -1638.8987 | AC14: 2026-09-14 | AD14: ItD Unrealized PnL | AF14: -1741.0148 | AH14: 2026-09-28 | AI14: OFF BS | AJ14: Face | AK14: Deal buy | AL14: 4731.32 | AN14: 2026-09-21 | AO14: Face value | AP14: FI Bond | AQ14: 12966.025 | AS14: 2026-09-28 | AT14: YTM binh quan | AU14: CD On BS | AV14: 7.3566433 | AX14: 46289 | AY14: Face_HLA | AZ14: 15469.311 | BB14: 2026-09-25 | BC14: Est YTM T10 | BD14: 3.9499879 | BN14: 46080 | BO14: Trading bonds_Govbond | BP14: NIM | BQ14: -13.818341
A15: 2026-09-11 | B15: Trang thai mo | C15: All | E15: 17513 | G15: 2026-09-11 | H15: Trang thai mo | I15: All | K15: 10858.311 | M15: 2026-09-11 | N15: PV01 | P15: -10.595633 | R15: 2026-09-11 | S15: PV01 | U15: -8.4261398 | X15: 2026-09-11 | Y15: Unrealized_ItD_MtM_PnL | AA15: -1641.3731 | AC15: 2026-09-11 | AD15: ItD Unrealized PnL | AF15: -1744.6063 | AH15: 2026-09-28 | AI15: OFF BS | AJ15: ItD | AK15: Deal buy | AL15: -144.41234 | AN15: 2026-09-21 | AO15: Face value | AP15: CD | AQ15: 28749.1 | AS15: 2026-09-28 | AT15: YTM binh quan | AU15: Total On BS | AV15: 7.6020316 | AX15: 46289 | AY15: Face_Secured_Unused | AZ15: -800 | BB15: 2026-09-25 | BC15: Est YTM T1 | BD15: 0 | BN15: 46080 | BO15: Trading bonds_FI bond | BP15: NIM | BQ15: -56.599
A16: 2026-09-10 | B16: Trang thai mo | C16: All | E16: 17513 | G16: 2026-09-10 | H16: Trang thai mo | I16: All | K16: 10858.311 | M16: 2026-09-10 | N16: PV01 | P16: -10.602965 | R16: 2026-09-10 | S16: PV01 | U16: -8.43164 | X16: 2026-09-10 | Y16: Unrealized_ItD_MtM_PnL | AA16: -1637.3042 | AC16: 2026-09-10 | AD16: ItD Unrealized PnL | AF16: -1741.5353 | AH16: 2026-09-28 | AI16: OFF BS | AJ16: Face | AK16: Deal sell | AL16: 22526.02 | AN16: 2026-09-18 | AO16: Face value | AP16: FI Bond | AQ16: 12966.21 | AS16: 2026-09-25 | AT16: Face value | AU16: CD On BS | AV16: 18899.1 | AX16: 46289 | AY16: Face_SBV_Overdraft | AZ16: -1459 | BB16: 2026-09-25 | BC16: Est Posi onBS T9 | BD16: 34454.3 | BN16: 46112 | BO16: Trading bonds_Govbond | BP16: NIM | BQ16: -23.324771
A17: 2026-09-09 | B17: Trang thai mo | C17: All | E17: 18513 | G17: 2026-09-09 | H17: Trang thai mo | I17: All | K17: 10858.311 | M17: 2026-09-09 | N17: PV01 | P17: -11.388407 | R17: 2026-09-09 | S17: PV01 | U17: -8.4349222 | X17: 2026-09-09 | Y17: Unrealized_ItD_MtM_PnL | AA17: -1635.319 | AC17: 2026-09-09 | AD17: ItD Unrealized PnL | AF17: -1740.2686 | AH17: 2026-09-28 | AI17: OFF BS | AJ17: ItD | AK17: Deal sell | AL17: -42.462006 | AN17: 2026-09-18 | AO17: Face value | AP17: CD | AQ17: 28749.1 | AS17: 2026-09-25 | AT17: Face value | AU17: FI Bond Listed On BS | AV17: 397.6106 | AX17: 46289 | AY17: Face_HMNR_NAPAS | AZ17: -605 | BB17: 2026-09-25 | BC17: Est Posi onBS T8 | BD17: 0 | BN17: 46112 | BO17: Trading bonds_Govbond | BP17: Realized PnL | BQ17: 3.9186446
A18: 2026-09-08 | B18: Trang thai mo | C18: All | E18: 17513 | G18: 2026-09-08 | H18: Trang thai mo | I18: All | K18: 10858.311 | M18: 2026-09-08 | N18: PV01 | P18: -10.609883 | R18: 2026-09-08 | S18: PV01 | U18: -8.4350591 | X18: 2026-09-08 | Y18: Unrealized_ItD_MtM_PnL | AA18: -1637.0617 | AC18: 2026-09-08 | AD18: ItD Unrealized PnL | AF18: -1742.1945 | AH18: 2026-09-28 | AI18: NGOAI BS | AJ18: Face | AK18: All | AL18: 1847.4 | AN18: 2026-09-17 | AO18: Face value | AP18: FI Bond | AQ18: 12966.096 | AS18: 2026-09-25 | AT18: Face value | AU18: FI Bond Unlisted On BS | AV18: 11000 | AX18: 46289 | AY18: Face_OMO_Available | AZ18: 7692.8209 | BB18: 2026-09-25 | BC18: Est Posi onBS T7 | BD18: 0 | BN18: 46112 | BO18: Trading bonds_FI bond | BP18: NIM | BQ18: -6.892
A19: 2026-09-07 | B19: Trang thai mo | C19: All | E19: 17513 | G19: 2026-09-07 | H19: Trang thai mo | I19: All | K19: 10858.311 | M19: 2026-09-07 | N19: PV01 | P19: -10.612477 | R19: 2026-09-07 | S19: PV01 | U19: -8.4355926 | X19: 2026-09-07 | Y19: Unrealized_ItD_MtM_PnL | AA19: -1637.7748 | AC19: 2026-09-07 | AD19: ItD Unrealized PnL | AF19: -1743.5763 | AH19: 2026-09-28 | AI19: NGOAI BS | AJ19: MtM | AK19: All | AL19: 1705.8913 | AN19: 2026-09-17 | AO19: Face value | AP19: CD | AQ19: 28799.1 | AS19: 2026-09-25 | AT19: Face value | AU19: CD Off BS | AV19: 0 | AX19: 46288 | AY19: Face_HLA | AZ19: 12899.311 | BB19: 2026-09-25 | BC19: Est Posi onBS T6 | BD19: 0 | BN19: 46112 | BO19: Trading bonds_FI bond | BP19: Realized PnL | BQ19: -24.617
A20: 2026-09-04 | B20: Trang thai mo | C20: All | E20: 17513 | G20: 2026-09-04 | H20: Trang thai mo | I20: All | K20: 10858.311 | M20: 2026-09-04 | N20: PV01 | P20: -10.621377 | R20: 2026-09-04 | S20: PV01 | U20: -8.4413599 | X20: 2026-09-04 | Y20: Unrealized_ItD_MtM_PnL | AA20: -1639.6465 | AC20: 2026-09-04 | AD20: ItD Unrealized PnL | AF20: -1744.2174 | AH20: 2026-09-28 | AI20: NGOAI BS | AJ20: PTCK | AK20: All | AL20: -65.268159 | AN20: 2026-09-16 | AO20: Face value | AP20: FI Bond | AQ20: 12965.701 | AS20: 2026-09-25 | AT20: Face value | AU20: FI Bond Listed Off BS | AV20: 0 | AX20: 46288 | AY20: Face_Secured_Unused | AZ20: -800 | BB20: 2026-09-25 | BC20: Est Posi onBS T5 | BD20: 0 | BN20: 46112 | BO20: Banking bonds_Govbond | BP20: NIM | BQ20: -12.727281
A21: 2026-09-03 | B21: Trang thai mo | C21: All | E21: 17513 | G21: 2026-09-03 | H21: Trang thai mo | I21: All | K21: 10858.311 | M21: 2026-09-03 | N21: PV01 | P21: -10.62725 | R21: 2026-09-03 | S21: PV01 | U21: -8.4438313 | X21: 2026-09-03 | Y21: Unrealized_ItD_MtM_PnL | AA21: -1635.9934 | AC21: 2026-09-03 | AD21: ItD Unrealized PnL | AF21: -1743.7375 | AH21: 2026-09-28 | AI21: NGOAI BS | AJ21: Diff | AK21: All | AL21: -76.240517 | AN21: 2026-09-16 | AO21: Face value | AP21: CD | AQ21: 28799.1 | AS21: 2026-09-25 | AT21: Face value | AU21: FI Bond Unlisted Off BS | AV21: 0 | AX21: 46288 | AY21: Face_SBV_Overdraft | AZ21: -1459 | BB21: 2026-09-25 | BC21: Est Posi onBS T4 | BD21: 0 | BN21: 46112 | BO21: Banking bonds_Govbond | BP21: Realized PnL | BQ21: -0.003892796
A22: 2026-08-28 | B22: Trang thai mo | C22: All | E22: 17513 | G22: 2026-08-28 | H22: Trang thai mo | I22: All | K22: 10858.311 | M22: 2026-08-28 | N22: PV01 | P22: -10.64537 | R22: 2026-08-28 | S22: PV01 | U22: -8.4550612 | X22: 2026-08-28 | Y22: Unrealized_ItD_MtM_PnL | AA22: -1640.2643 | AC22: 2026-08-28 | AD22: ItD Unrealized PnL | AF22: -1745.4062 | AH22: 2026-09-28 | AI22: NGOAI BS | AJ22: ItD | AK22: All | AL22: -76.240517 | AN22: 2026-09-15 | AO22: Face value | AP22: FI Bond | AQ22: 12965.081 | AS22: 2026-09-25 | AT22: Face value | AU22: CD Ngoai BS | AV22: 8550 | AX22: 46288 | AY22: Face_HMNR_NAPAS | AZ22: -605 | BB22: 2026-09-25 | BC22: Est Posi onBS T3 | BD22: 0 | BN22: 46141 | BO22: Banking bonds_Govbond | BP22: NIM | BQ22: -10.589189
A23: 2026-08-27 | B23: Trang thai mo | C23: All | E23: 17513 | G23: 2026-08-27 | H23: Trang thai mo | I23: All | K23: 10858.311 | AH23: 2026-09-28 | AI23: NGOAI BS | AJ23: Face | AK23: Deal buy | AL23: 7763.4 | AN23: 2026-09-15 | AO23: Face value | AP23: CD | AQ23: 28799.1 | AS23: 2026-09-25 | AT23: Face value | AU23: FI Bond Listed Ngoai BS | AV23: 0 | AX23: 46288 | AY23: Face_OMO_Available | AZ23: 8042.8209 | BB23: 2026-09-25 | BC23: Est Posi onBS T2 | BD23: 0 | BN23: 46141 | BO23: Trading bonds_FI bond | BP23: Realized PnL | BQ23: -16.905
A24: 2026-08-26 | B24: Trang thai mo | C24: All | E24: 17513 | G24: 2026-08-26 | H24: Trang thai mo | I24: All | K24: 10858.311 | AH24: 2026-09-28 | AI24: NGOAI BS | AJ24: ItD | AK24: Deal buy | AL24: -478.75172 | AN24: 2026-09-14 | AO24: Face value | AP24: FI Bond | AQ24: 12965.496 | AS24: 2026-09-25 | AT24: Face value | AU24: FI Bond Unlisted Ngoai BS | AV24: 0 | AX24: 46287 | AY24: Face_HLA | AZ24: 11846.531 | BB24: 2026-09-25 | BC24: Est Posi onBS T12 | BD24: 28046.7 | BN24: 46141 | BO24: Banking bonds_Govbond | BP24: Realized PnL | BQ24: -0.003892796
A25: 2026-08-25 | B25: Trang thai mo | C25: All | E25: 17513 | G25: 2026-08-25 | H25: Trang thai mo | I25: All | K25: 10858.311 | AH25: 2026-09-28 | AI25: NGOAI BS | AJ25: Face | AK25: Deal sell | AL25: 5916 | AN25: 2026-09-14 | AO25: Face value | AP25: CD | AQ25: 28799.1 | AS25: 2026-09-25 | AT25: YTM binh quan | AU25: FI Bond On BS | AV25: 7.6807069 | AX25: 46287 | AY25: Face_Secured_Unused | AZ25: -800 | BB25: 2026-09-25 | BC25: Est Posi onBS T11 | BD25: 33845.7 | BN25: 46141 | BO25: Trading bonds_Govbond | BP25: Realized PnL | BQ25: 12.845423
A26: 2026-08-24 | B26: Trang thai mo | C26: All | E26: 17513 | G26: 2026-08-24 | H26: Trang thai mo | I26: All | K26: 10858.311 | AH26: 2026-09-28 | AI26: NGOAI BS | AJ26: ItD | AK26: Deal sell | AL26: -402.5112 | AN26: 2026-09-11 | AO26: Face value | AP26: FI Bond | AQ26: 12963.988 | AS26: 2026-09-25 | AT26: YTM binh quan | AU26: CD On BS | AV26: 7.3566433 | AX26: 46287 | AY26: Face_SBV_Overdraft | AZ26: -1459 | BB26: 2026-09-25 | BC26: Est Posi onBS T10 | BD26: 34767.7 | BN26: 46141 | BO26: Trading bonds_Govbond | BP26: NIM | BQ26: -9.994472
A27: 2026-08-21 | B27: Trang thai mo | C27: All | E27: 17513 | G27: 2026-08-21 | H27: Trang thai mo | I27: All | K27: 10858.311 | AH27: 2026-09-28 | AI27: YTM_ON BS | AJ27: Spot | AK27: All | AL27: 4.1229722 | AN27: 2026-09-11 | AO27: Face value | AP27: CD | AQ27: 28799.1 | AS27: 2026-09-25 | AT27: YTM binh quan | AU27: Total On BS | AV27: 7.6020316 | AX27: 46287 | AY27: Face_HMNR_NAPAS | AZ27: -605 | BB27: 2026-09-25 | BC27: Est Posi onBS T1 | BD27: 0 | BN27: 46141 | BO27: Trading bonds_FI bond | BP27: NIM | BQ27: -8.637
A28: 2026-08-20 | B28: Trang thai mo | C28: All | E28: 17513 | G28: 2026-08-20 | H28: Trang thai mo | I28: All | K28: 10858.311 | AH28: 2026-09-25 | AI28: YTM_ON BS | AJ28: Spot | AK28: All | AL28: 4.0940599 | AN28: 2026-09-10 | AO28: Face value | AP28: FI Bond | AQ28: 12963.804 | AS28: 2026-09-24 | AT28: Face value | AU28: CD On BS | AV28: 16599.1 | AX28: 46287 | AY28: Face_OMO_Available | AZ28: 8770.0403 | BN28: 46171 | BO28: Trading bonds_Govbond | BP28: NIM | BQ28: -14.006186
A29: 2026-08-19 | B29: Trang thai mo | C29: All | E29: 17513 | G29: 2026-08-19 | H29: Trang thai mo | I29: All | K29: 10858.311 | AH29: 2026-09-25 | AI29: ON BS | AJ29: Face | AK29: All | AL29: 38020.3 | AN29: 2026-09-10 | AO29: Face value | AP29: CD | AQ29: 27899.1 | AS29: 2026-09-24 | AT29: Face value | AU29: FI Bond Listed On BS | AV29: 397.6106 | AX29: 46286 | AY29: Face_HLA | AZ29: 15607.311 | BN29: 46171 | BO29: Trading bonds_Govbond | BP29: Realized PnL | BQ29: 12.177066
A30: 2026-08-18 | B30: Trang thai mo | C30: All | E30: 17513 | G30: 2026-08-18 | H30: Trang thai mo | I30: All | K30: 10858.311 | AH30: 2026-09-25 | AI30: ON BS | AJ30: MtM | AK30: All | AL30: 38033.784 | AN30: 2026-09-09 | AO30: Face value | AP30: FI Bond | AQ30: 12963.8 | AS30: 2026-09-24 | AT30: Face value | AU30: FI Bond Unlisted On BS | AV30: 11000 | AX30: 46286 | AY30: Face_Secured_Unused | AZ30: -800 | BN30: 46171 | BO30: Trading bonds_FI bond | BP30: NIM | BQ30: -31.377
A31: 2026-08-17 | B31: Trang thai mo | C31: All | E31: 17513 | G31: 2026-08-17 | H31: Trang thai mo | I31: All | K31: 10858.311 | AH31: 2026-09-25 | AI31: ON BS | AJ31: PTCK | AK31: All | AL31: 1658.4947 | AN31: 2026-09-09 | AO31: Face value | AP31: CD | AQ31: 27899.1 | AS31: 2026-09-24 | AT31: Face value | AU31: CD Off BS | AV31: 0 | AX31: 46286 | AY31: Face_SBV_Overdraft | AZ31: -1459 | BN31: 46171 | BO31: Trading bonds_FI bond | BP31: Realized PnL | BQ31: 5.733
A32: 2026-08-14 | B32: Trang thai mo | C32: All | E32: 17513 | G32: 2026-08-14 | H32: Trang thai mo | I32: All | K32: 10858.311 | AH32: 2026-09-25 | AI32: ON BS | AJ32: Diff | AK32: All | AL32: -1645.011 | AN32: 2026-09-08 | AO32: Face value | AP32: FI Bond | AQ32: 12965.259 | AS32: 2026-09-24 | AT32: Face value | AU32: FI Bond Listed Off BS | AV32: 0 | AX32: 46286 | AY32: Face_HMNR_NAPAS | AZ32: -605 | BN32: 46171 | BO32: Banking bonds_Govbond | BP32: NIM | BQ32: -12.61037
A33: 2026-08-13 | B33: Trang thai mo | C33: All | E33: 17513 | G33: 2026-08-13 | H33: Trang thai mo | I33: All | K33: 10858.311 | AH33: 2026-09-25 | AI33: ON BS | AJ33: ItD | AK33: All | AL33: -1614.1155 | AN33: 2026-09-08 | AO33: Face value | AP33: CD | AQ33: 28199.1 | AS33: 2026-09-24 | AT33: Face value | AU33: FI Bond Unlisted Off BS | AV33: 0 | AX33: 46286 | AY33: Face_OMO_Available | AZ33: 7952.8209 | BN33: 46171 | BO33: Banking bonds_Govbond | BP33: Realized PnL | BQ33: -0.003892796
A34: 2026-08-12 | B34: Trang thai mo | C34: All | E34: 17513 | G34: 2026-08-12 | H34: Trang thai mo | I34: All | K34: 10858.311 | AH34: 2026-09-25 | AI34: OFF BS | AJ34: Face | AK34: All | AL34: -24864.7 | AN34: 2026-09-07 | AO34: Face value | AP34: FI Bond | AQ34: 12966.251 | AS34: 2026-09-24 | AT34: Face value | AU34: CD Ngoai BS | AV34: 10850 | AX34: 46285 | AY34: Face_HLA | AZ34: 14261.311 | BN34: 46203 | BO34: Banking bonds_Govbond | BP34: Realized PnL | BQ34: -0.003892796
A35: 2026-08-11 | B35: Trang thai mo | C35: All | E35: 17513 | G35: 2026-08-11 | H35: Trang thai mo | I35: All | K35: 10858.311 | AH35: 2026-09-25 | AI35: OFF BS | AJ35: MtM | AK35: All | AL35: -26045.627 | AN35: 2026-09-07 | AO35: Face value | AP35: CD | AQ35: 27199.1 | AS35: 2026-09-24 | AT35: Face value | AU35: FI Bond Listed Ngoai BS | AV35: 0 | AX35: 46285 | AY35: Face_Secured_Unused | AZ35: -800 | BN35: 46203 | BO35: Trading bonds_FI bond | BP35: Realized PnL | BQ35: -5.246
A36: 2026-08-10 | B36: Trang thai mo | C36: All | E36: 17513 | G36: 2026-08-10 | H36: Trang thai mo | I36: All | K36: 10858.311 | AH36: 2026-09-25 | AI36: OFF BS | AJ36: PTCK | AK36: All | AL36: -1449.1643 | AN36: 2026-09-04 | AO36: Face value | AP36: FI Bond | AQ36: 12967.292 | AS36: 2026-09-24 | AT36: Face value | AU36: FI Bond Unlisted Ngoai BS | AV36: 0 | AX36: 46285 | AY36: Face_SBV_Overdraft | AZ36: -1459 | BN36: 46203 | BO36: Banking bonds_Govbond | BP36: NIM | BQ36: -11.352707
A37: 2026-08-07 | B37: Trang thai mo | C37: All | E37: 16370 | G37: 2026-08-07 | H37: Trang thai mo | I37: All | K37: 12001.311 | AH37: 2026-09-25 | AI37: OFF BS | AJ37: Diff | AK37: All | AL37: 268.23706 | AN37: 2026-09-04 | AO37: Face value | AP37: CD | AQ37: 27199.1 | AS37: 2026-09-24 | AT37: YTM binh quan | AU37: FI Bond On BS | AV37: 7.6808236 | AX37: 46285 | AY37: Face_HMNR_NAPAS | AZ37: -803 | BN37: 46203 | BO37: Trading bonds_Govbond | BP37: Realized PnL | BQ37: 17.012411
A38: 2026-08-06 | B38: Trang thai mo | C38: All | E38: 16370 | G38: 2026-08-06 | H38: Trang thai mo | I38: All | K38: 12001.311 | AH38: 2026-09-25 | AI38: OFF BS | AJ38: ItD | AK38: All | AL38: 268.23706 | AN38: 2026-09-03 | AO38: Face value | AP38: FI Bond | AQ38: 12967.996 | AS38: 2026-09-24 | AT38: YTM binh quan | AU38: CD On BS | AV38: 7.2133672 | AX38: 46285 | AY38: Face_OMO_Available | AZ38: 7254.8209 | BN38: 46203 | BO38: Trading bonds_Govbond | BP38: NIM | BQ38: -23.518877
A39: 2026-08-05 | B39: Trang thai mo | C39: All | E39: 16370 | G39: 2026-08-05 | H39: Trang thai mo | I39: All | K39: 12001.311 | AH39: 2026-09-25 | AI39: OFF BS | AJ39: Face | AK39: Deal buy | AL39: 500 | AN39: 2026-09-03 | AO39: Face value | AP39: CD | AQ39: 27199.1 | AS39: 2026-09-24 | AT39: YTM binh quan | AU39: Total On BS | AV39: 7.5349143 | AX39: 46282 | AY39: Face_HLA | AZ39: 10666.447 | BN39: 46203 | BO39: Trading bonds_FI bond | BP39: NIM | BQ39: -37.67
... A51: 2026-07-20 | B51: Trang thai mo | C51: All | E51: 11412 | G51: 2026-07-20 | H51: Trang thai mo | I51: All | K51: 16959.311 | AH51: 2026-09-25 | AI51: NGOAI BS | AJ51: ItD | AK51: Deal sell | AL51: -403.0263 | AN51: 2026-08-21 | AO51: Face value | AP51: CD | AQ51: 26949.1 | AS51: 2026-09-23 | AT51: YTM binh quan | AU51: Total On BS | AV51: 7.4414365 | AX51: 46280 | AY51: Face_SBV_Overdraft | AZ51: -1459 | BN51: 46262 | BO51: Banking bonds_Govbond | BP51: Realized PnL | BQ51: -0.003892796
A52: 2026-07-17 | B52: Trang thai mo | C52: All | E52: 11412 | G52: 2026-07-17 | H52: Trang thai mo | I52: All | K52: 16959.311 | AH52: 2026-09-24 | AI52: ON BS | AJ52: Face | AK52: All | AL52: 35910.3 | AN52: 2026-08-20 | AO52: Face value | AP52: FI Bond | AQ52: 10768.385 | AS52: 2026-09-22 | AT52: Face value | AU52: CD On BS | AV52: 14399.1 | AX52: 46280 | AY52: Face_HMNR_NAPAS | AZ52: -803
...

Sheet NIM
A1: Chỉ tiêu | B1: 46052 | C1: 46080 | D1: 46112 | E1: 46141 | F1: 46171 | G1: 46203 | H1: 46234 | I1: 46262 | J1: 46295 | K1: 46326 | L1: 46356 | M1: 46387 | N1: Estimate NII 2026
A2: I.Trạng thái rủi ro thị trường
A3: Trading book GBond | B3: =SUMIFS(BOND!$E:$E,BOND!$A:$A,B1) -> 8062 | C3: =SUMIFS(BOND!$E:$E,BOND!$A:$A,C1) -> 7802 | D3: =SUMIFS(BOND!$E:$E,BOND!$A:$A,D1) -> 6141 | E3: =SUMIFS(BOND!$E:$E,BOND!$A:$A,E1) -> 6462 | F3: =SUMIFS(BOND!$E:$E,BOND!$A:$A,F1) -> 6162 | G3: =SUMIFS(BOND!$E:$E,BOND!$A:$A,G1) -> 11412 | H3: =SUMIFS(BOND!$E:$E,BOND!$A:$A,H1) -> 16370 | I3: =SUMIFS(BOND!$E:$E,BOND!$A:$A,I1) -> 17513 | J3: =SUMIFS(BOND!$E:$E,BOND!$A:$A,RPT) -> 17513 | K3: =J3 -> 17513 | L3: =K3 -> 17513 | M3: =L3 -> 17513
A4: Banking book GBond | B4: =SUMIFS(BOND!$K:$K,BOND!$G:$G,B1) -> 16959.311 | C4: =SUMIFS(BOND!$K:$K,BOND!$G:$G,C1) -> 16959.311 | D4: =SUMIFS(BOND!$K:$K,BOND!$G:$G,D1) -> 16959.311 | E4: =SUMIFS(BOND!$K:$K,BOND!$G:$G,E1) -> 16959.311 | F4: =SUMIFS(BOND!$K:$K,BOND!$G:$G,F1) -> 16959.311 | G4: =SUMIFS(BOND!$K:$K,BOND!$G:$G,G1) -> 16959.311 | H4: =SUMIFS(BOND!$K:$K,BOND!$G:$G,H1) -> 12001.311 | I4: =SUMIFS(BOND!$K:$K,BOND!$G:$G,I1) -> 10858.311 | J4: =I4 -> 10858.311 | K4: =J4 -> 10858.311 | L4: =K4-300 -> 10558.311 | M4: =L4 -> 10558.311 | P4: chưa có cth, tháng 11 đáo hạn 300 tỷ
A5: FI bond | B5: =SUMIFS(BOND!$AQ:$AQ,BOND!$AN:$AN,B1) -> 34458.682 | C5: =SUMIFS(BOND!$AQ:$AQ,BOND!$AN:$AN,C1) -> 38969.947 | D5: =SUMIFS(BOND!$AQ:$AQ,BOND!$AN:$AN,D1) -> 27119.74 | E5: =SUMIFS(BOND!$AQ:$AQ,BOND!$AN:$AN,E1) -> 30669.469 | F5: =SUMIFS(BOND!$AQ:$AQ,BOND!$AN:$AN,F1) -> 35474.47 | G5: =SUMIFS(BOND!$AQ:$AQ,BOND!$AN:$AN,G1) -> 39497.611 | H5: =SUMIFS(BOND!$AQ:$AQ,BOND!$AN:$AN,H1) -> 39522.262 | I5: =SUMIFS(BOND!$AQ:$AQ,BOND!$AN:$AN,I1) -> 40166.528 | J5: =SUMIFS(BOND!$AQ:$AQ,BOND!$AN:$AN,RPT) -> 39414.405 | K5: =J5 -> 39414.405 | L5: =K5 -> 39414.405 | M5: =L5 -> 39414.405
A6: II.Trạng thái rủi ro IRRBB
A7: Trading book Gbond | B7: =SUMIFS(BOND!$AL:$AL,BOND!$AH:$AH,NIM!B1,BOND!$AI:$AI,"ON BS",BOND!$AJ:$AJ,"Face") -> 26803.3 | C7: =SUMIFS(BOND!$AL:$AL,BOND!$AH:$AH,NIM!C1,BOND!$AI:$AI,"ON BS",BOND!$AJ:$AJ,"Face") -> 30279 | D7: =SUMIFS(BOND!$AL:$AL,BOND!$AH:$AH,NIM!D1,BOND!$AI:$AI,"ON BS",BOND!$AJ:$AJ,"Face") -> 31928.3 | E7: =SUMIFS(BOND!$AL:$AL,BOND!$AH:$AH,NIM!E1,BOND!$AI:$AI,"ON BS",BOND!$AJ:$AJ,"Face") -> 35981.7 | F7: =SUMIFS(BOND!$AL:$AL,BOND!$AH:$AH,NIM!F1,BOND!$AI:$AI,"ON BS",BOND!$AJ:$AJ,"Face") -> 34368.7 | G7: =SUMIFS(BOND!$AL:$AL,BOND!$AH:$AH,NIM!G1,BOND!$AI:$AI,"ON BS",BOND!$AJ:$AJ,"Face") -> 36404.7 | H7: =SUMIFS(BOND!$AL:$AL,BOND!$AH:$AH,NIM!H1,BOND!$AI:$AI,"ON BS",BOND!$AJ:$AJ,"Face") -> 41024.2 | I7: =SUMIFS(BOND!$AL:$AL,BOND!$AH:$AH,NIM!I1,BOND!$AI:$AI,"ON BS",BOND!$AJ:$AJ,"Face") -> 39207.7 | J7: =_xlfn.XLOOKUP(J22,BOND!$BC:$BC,BOND!$BD:$BD,,0) -> 34454.3 | K7: =_xlfn.XLOOKUP(K22,BOND!$BC:$BC,BOND!$BD:$BD,,0) -> 34767.7 | L7: =_xlfn.XLOOKUP(L22,BOND!$BC:$BC,BOND!$BD:$BD,,0) -> 33845.7 | M7: =_xlfn.XLOOKUP(M22,BOND!$BC:$BC,BOND!$BD:$BD,,0) -> 28046.7
A8: Lợi suất bình quân | B8: 0.036272434 | C8: 0.037166247 | D8: 0.039292138 | E8: 0.039726522 | F8: 0.040102125 | G8: =SUMIFS(BOND!$AL:$AL,BOND!$AH:$AH,G1,BOND!$AI:$AI,"YTM_ON BS")/100 -> 0.040545139 | H8: =SUMIFS(BOND!$AL:$AL,BOND!$AH:$AH,H1,BOND!$AI:$AI,"YTM_ON BS")/100 -> 0.03940561 | I8: =SUMIFS(BOND!$AL:$AL,BOND!$AH:$AH,I1,BOND!$AI:$AI,"YTM_ON BS")/100 -> 0.040128409 | J8: =_xlfn.XLOOKUP(J23,BOND!$BC:$BC,BOND!$BD:$BD,,0)/100 -> 0.042464765 | K8: =_xlfn.XLOOKUP(K23,BOND!$BC:$BC,BOND!$BD:$BD,,0)/100 -> 0.039499879 | L8: =_xlfn.XLOOKUP(L23,BOND!$BC:$BC,BOND!$BD:$BD,,0)/100 -> 0.038006658 | M8: =_xlfn.XLOOKUP(M23,BOND!$BC:$BC,BOND!$BD:$BD,,0)/100 -> 0.035992079 | P8: thiếu công thức các tháng cũ
A9: Banking book Gbond | B9: =SUMIFS(BOND!$K:$K,BOND!$G:$G,B$1) -> 16959.311 | C9: =SUMIFS(BOND!$K:$K,BOND!$G:$G,C$1) -> 16959.311 | D9: =SUMIFS(BOND!$K:$K,BOND!$G:$G,D$1) -> 16959.311 | E9: =SUMIFS(BOND!$K:$K,BOND!$G:$G,E$1) -> 16959.311 | F9: =SUMIFS(BOND!$K:$K,BOND!$G:$G,F$1) -> 16959.311 | G9: =SUMIFS(BOND!$K:$K,BOND!$G:$G,G$1) -> 16959.311 | H9: =SUMIFS(BOND!$K:$K,BOND!$G:$G,H$1) -> 12001.311 | O9: tháng 11 đáo hạn 300 tỷ | P9: chưa có cth, tháng 11 đáo hạn 300 tỷ
A10: Lợi suất bình quân | B10: 0.026682072 | C10: 0.026682072 | D10: 0.026682072 | E10: 0.026682072 | F10: 0.026682072 | G10: 0.026682072 | H10: 0.026682072 | P10: chưa có cth, book BK fix nên số fix k sửa
A11: FI bond | B11: =SUMIFS(BOND!$AQ:$AQ,BOND!$AN:$AN,B1) -> 34458.682 | C11: =SUMIFS(BOND!$AQ:$AQ,BOND!$AN:$AN,C1) -> 38969.947 | D11: =SUMIFS(BOND!$AQ:$AQ,BOND!$AN:$AN,D1) -> 27119.74 | E11: =SUMIFS(BOND!$AQ:$AQ,BOND!$AN:$AN,E1) -> 30669.469 | F11: =SUMIFS(BOND!$AQ:$AQ,BOND!$AN:$AN,F1) -> 35474.47 | G11: =SUMIFS(BOND!$AQ:$AQ,BOND!$AN:$AN,G1) -> 39497.611 | H11: =SUMIFS(BOND!$AQ:$AQ,BOND!$AN:$AN,H1) -> 39522.262 | I11: =SUMIFS(BOND!$AQ:$AQ,BOND!$AN:$AN,I1) -> 40166.528 | J11: =I11 -> 40166.528 | K11: =J11 -> 40166.528 | L11: =K11 -> 40166.528 | M11: =L11 -> 40166.528 | P11: chưa có cth, chưa có ước tính, các tháng sau cho = số thực tế ngày báo cáo
A12: Lợi suất bình quân | B12: 0.057621928 | C12: 0.054484147 | D12: 0.05357593 | E12: 0.053719867 | F12: =SUMIFS(BOND!$AV:$AV,BOND!$AS:$AS,F1,BOND!$AU:$AU,"Total On BS")/100 -> 0.056270865 | G12: =SUMIFS(BOND!$AV:$AV,BOND!$AS:$AS,G1,BOND!$AU:$AU,"Total On BS")/100 -> 0.05894094 | H12: =SUMIFS(BOND!$AV:$AV,BOND!$AS:$AS,H1,BOND!$AU:$AU,"Total On BS")/100 -> 0.064706749 | I12: =SUMIFS(BOND!$AV:$AV,BOND!$AS:$AS,I1,BOND!$AU:$AU,"Total On BS")/100 -> 0.074070015 | J12: =I12 -> 0.074070015 | K12: =J12 -> 0.074070015 | L12: =K12 -> 0.074070015 | M12: =L12 -> 0.074070015 | P12: chưa có cth, chưa có ước tính, các tháng sau cho = số thực tế ngày báo cáo
