Workbook

Sheet README
A1: PROJECT LOTUS - IPO ADVISORY MODEL (FICTIONAL)
A2: Illustrative - fictional data. Not based on any real company.
A4: Target (fictional) | B4: NovaPay Digital JSC - Vietnam e-wallet + merchant payment gateway
A5: Adviser (fictional) | B5: Meridian Partners Securities - proposed Lead Manager / Bookrunner
A6: Proposed venue | B6: HOSE
A7: Currency | B7: USD millions unless stated otherwise
A8: Fiscal year | B8: FY ends 31 December
A10: DISCLAIMER | B10: Every company name, transaction, KPI and valuation figure in this file is INVENTED
B11: for an illustrative pitch exercise. No real issuer, bank, exchange or deal is referenced.
B12: Regulatory points are described generically as 'per prevailing listing regulations'.
A14: Colour convention | B14: BLUE font on yellow fill = hardcoded assumption. BLACK font = formula.
A16: Sheet | B16: Contents
A17: Operating_KPI | B17: TPV, take rate, MAU, merchants - 3Y historical + 3Y forecast
A18: Financials | B18: Revenue build, gross margin, EBITDA, net income, net cash
A19: Comps | B19: 5 fictional listed payment/fintech peers - EV/Rev, EV/EBITDA, P/E
A20: Precedents | B20: 4 fictional fintech M&A / IPO precedent transactions
A21: DCF | B21: Unlevered FCF, WACC build, terminal value, equity bridge
A22: Sensitivity | B22: DCF equity value vs WACC and terminal growth
A23: Football_Field | B23: Valuation ranges by methodology + IPO discount -> offer range
A24: Offer_Structure | B24: Primary/secondary split, proceeds, free float, use of proceeds
A25: IPO_Timeline | B25: Indicative execution calendar
A26: Slide_Numbers | B26: Every number that appears on a slide, with its source cell

Sheet Operating_KPI
A1: OPERATING KPIs
A2: Illustrative - fictional data. Not based on any real company.
A4: Line item | B4: Unit | C4: FY23A | D4: FY24A | E4: FY25A | F4: FY26E | G4: FY27E | H4: FY28E
A5: Total payment volume (TPV) | B5: USD bn | C5: 8 | D5: 11.2 | E5: 15.1 | F5: 19.6 | G5: 24.9 | H5: 31.1
A6: TPV growth y/y | B6: % | D6: =D5/C5-1 | E6: =E5/D5-1 | F6: =F5/E5-1 | G6: =G5/F5-1 | H6: =H5/G5-1
A7: Take rate (blended) | B7: % | C7: 0.0062 | D7: 0.0066 | E7: 0.007 | F7: 0.0072 | G7: 0.0074 | H7: 0.0075
A8: Monthly active users (MAU) | B8: m | C8: 6.2 | D8: 8.1 | E8: 10.3 | F8: 12.4 | G8: 14.5 | H8: 16.4
A9: Active merchants | B9: '000 | C9: 118 | D9: 172 | E9: 245 | F9: 320 | G9: 405 | H9: 490
A10: TPV per MAU | B10: USD/yr | C10: =C5*1000/C8 | D10: =D5*1000/D8 | E10: =E5*1000/E8 | F10: =F5*1000/F8 | G10: =G5*1000/G8 | H10: =H5*1000/H8
A11: TPV per merchant | B11: USD'000/yr | C11: =C5*1000000/C9/1000 | D11: =D5*1000000/D9/1000 | E11: =E5*1000000/E9/1000 | F11: =F5*1000000/F9/1000 | G11: =G5*1000000/G9/1000 | H11: =H5*1000000/H9/1000
A13: Illustrative - fictional data

Sheet Financials
A1: FINANCIAL SUMMARY (USD m)
A2: Illustrative - fictional data. Not based on any real company.
A4: Line item | B4: Unit | C4: FY23A | D4: FY24A | E4: FY25A | F4: FY26E | G4: FY27E | H4: FY28E
A5: Payment revenue (TPV x take rate) | B5: USD m | C5: =Operating_KPI!C5*1000*Operating_KPI!C7 | D5: =Operating_KPI!D5*1000*Operating_KPI!D7 | E5: =Operating_KPI!E5*1000*Operating_KPI!E7 | F5: =Operating_KPI!F5*1000*Operating_KPI!F7 | G5: =Operating_KPI!G5*1000*Operating_KPI!G7 | H5: =Operating_KPI!H5*1000*Operating_KPI!H7
A6: Value-added services revenue | B6: USD m | C6: 4 | D6: 6.5 | E6: 10.5 | F6: 15.5 | G6: 22 | H6: 30
A7: Total revenue | B7: USD m | C7: =SUM(C5:C6) | D7: =SUM(D5:D6) | E7: =SUM(E5:E6) | F7: =SUM(F5:F6) | G7: =SUM(G5:G6) | H7: =SUM(H5:H6)
A8: Revenue growth y/y | B8: % | D8: =D7/C7-1 | E8: =E7/D7-1 | F8: =F7/E7-1 | G8: =G7/F7-1 | H8: =H7/G7-1
A9: Gross margin | B9: % | C9: 0.41 | D9: 0.44 | E9: 0.47 | F9: 0.49 | G9: 0.51 | H9: 0.52
A10: Gross profit | B10: USD m | C10: =C7*C9 | D10: =D7*D9 | E10: =E7*E9 | F10: =F7*F9 | G10: =G7*G9 | H10: =H7*H9
A11: EBITDA margin | B11: % | C11: 0.03 | D11: 0.08 | E11: 0.13 | F11: 0.16 | G11: 0.19 | H11: 0.21
A12: EBITDA | B12: USD m | C12: =C7*C11 | D12: =D7*D11 | E12: =E7*E11 | F12: =F7*F11 | G12: =G7*G11 | H12: =H7*H11
A13: Depreciation & amortisation | B13: USD m | C13: 3.5 | D13: 4.6 | E13: 6 | F13: 7.5 | G13: 9.3 | H13: 11.3
A14: EBIT | B14: USD m | C14: =C12-C13 | D14: =D12-D13 | E14: =E12-E13 | F14: =F12-F13 | G14: =G12-G13 | H14: =H12-H13
A15: Net interest & other income | B15: USD m | C15: 0.6 | D15: 0.9 | E15: 1.4 | F15: 1.8 | G15: 2.4 | H15: 3.2
A16: Profit before tax | B16: USD m | C16: =C14+C15 | D16: =D14+D15 | E16: =E14+E15 | F16: =F14+F15 | G16: =G14+G15 | H16: =H14+H15
A17: Effective tax rate | B17: % | C17: 0.2 | D17: 0.2 | E17: 0.2 | F17: 0.2 | G17: 0.2 | H17: 0.2
A18: Tax expense | B18: USD m | C18: =-MAX(0,C16)*C17 | D18: =-MAX(0,D16)*D17 | E18: =-MAX(0,E16)*E17 | F18: =-MAX(0,F16)*F17 | G18: =-MAX(0,G16)*G17 | H18: =-MAX(0,H16)*H17
A19: Net income | B19: USD m | C19: =C16+C18 | D19: =D16+D18 | E19: =E16+E18 | F19: =F16+F18 | G19: =G16+G18 | H19: =H16+H18
A20: Net margin | B20: % | C20: =C19/C7 | D20: =D19/D7 | E20: =E19/E7 | F20: =F19/F7 | G20: =G19/G7 | H20: =H19/H7
A22: Capital expenditure | B22: USD m | C22: 7 | D22: 9 | E22: 11 | F22: 12.5 | G22: 15 | H22: 18
A23: Increase in net working capital | B23: USD m | C23: 1.5 | D23: 2 | E23: 2.6 | F23: 3 | G23: 3.5 | H23: 4
A24: Net cash (cash less debt), year end | B24: USD m | C24: 18 | D24: 24 | E24: 36 | F24: 52 | G24: 78 | H24: 118
A26: Illustrative - fictional data

Sheet Comps
A1: TRADING COMPARABLES (FICTIONAL LISTED PEERS)
A2: Illustrative - fictional data. Not based on any real company.
A4: Peer (fictional) | B4: Region | C4: EV (USD m) | D4: FY26E Rev (USD m) | E4: FY26E EBITDA (USD m) | F4: FY26E NI (USD m) | G4: EV/Revenue | H4: EV/EBITDA | I4: P/E
A5: Meridian Pay Holdings | B5: SE Asia | C5: 11020 | D5: 1900 | E5: 355 | F5: 262 | G5: =C5/D5 | H5: =C5/E5 | I5: =(C5*0.97)/F5
A6: Sundara Digital Payments | B6: SE Asia | C6: 5290 | D6: 1150 | E6: 200 | F6: 151 | G6: =C6/D6 | H6: =C6/E6 | I6: =(C6*0.97)/F6
A7: Kalisa Fintech Group | B7: SE Asia | C7: 2340 | D7: 600 | E7: 106 | F7: 77 | G7: =C7/D7 | H7: =C7/E7 | I7: =(C7*0.97)/F7
A8: Northwind Payments Inc. | B8: Global | C8: 24960 | D8: 3900 | E8: 745 | F8: 555 | G8: =C8/D8 | H8: =C8/E8 | I8: =(C8*0.97)/F8
A9: Arcadia Merchant Services | B9: Global | C9: 8500 | D9: 1700 | E9: 309 | F9: 233 | G9: =C9/D9 | H9: =C9/E9 | I9: =(C9*0.97)/F9
A10: Minimum | G10: =MIN(G5:G9) | H10: =MIN(H5:H9) | I10: =MIN(I5:I9)
A11: Median | G11: =MEDIAN(G5:G9) | H11: =MEDIAN(H5:H9) | I11: =MEDIAN(I5:I9)
A12: Mean | G12: =AVERAGE(G5:G9) | H12: =AVERAGE(H5:H9) | I12: =AVERAGE(I5:I9)
A13: Maximum | G13: =MAX(G5:G9) | H13: =MAX(H5:H9) | I13: =MAX(I5:I9)
A15: Applied to NovaPay FY26E
A16: EV/Revenue range (min-max) | C16: =G10*Financials!F7 | D16: =G13*Financials!F7
A17: -> implied equity value (EV + net cash) | C17: =C16+Financials!F24 | D17: =D16+Financials!F24
A18: EV/EBITDA range (min-max) | C18: =H10*Financials!F12 | D18: =H13*Financials!F12
A19: -> implied equity value (EV + net cash) | C19: =C18+Financials!F24 | D19: =D18+Financials!F24
A21: Illustrative - fictional data

Sheet Precedents
A1: PRECEDENT TRANSACTIONS / IPOs (FICTIONAL)
A2: Illustrative - fictional data. Not based on any real company.
A4: Year | B4: Target (fictional) | C4: Acquirer / Event (fictional) | D4: Type | E4: EV (USD m) | F4: LTM Rev (USD m) | G4: LTM EBITDA (USD m) | H4: EV/Revenue | I4: EV/EBITDA
A5: 2023 | B5: Lotus Wallet Co. | C5: Arcadia Merchant Services | D5: M&A | E5: 540 | F5: 120 | G5: 22.5 | H5: =E5/F5 | I5: =E5/G5
A6: 2024 | B6: Meridian Pay Holdings | C6: IPO (regional exchange) | D6: IPO | E6: 7930 | F6: 1300 | G6: 264 | H6: =E6/F6 | I6: =E6/G6
A7: 2024 | B7: Orion Gateway Ltd. | C7: Sable Pay (merger) | D7: M&A | E7: 1890 | F7: 350 | G7: 70 | H7: =E7/F7 | I7: =E7/G7
A8: 2025 | B8: Vantage Digital Pay | C8: IPO (regional exchange) | D8: IPO | E8: 3600 | F8: 500 | G8: 106 | H8: =E8/F8 | I8: =E8/G8
B9: Minimum | H9: =MIN(H5:H8) | I9: =MIN(I5:I8)
B10: Median | H10: =MEDIAN(H5:H8) | I10: =MEDIAN(I5:I8)
B11: Mean | H11: =AVERAGE(H5:H8) | I11: =AVERAGE(I5:I8)
B12: Maximum | H12: =MAX(H5:H8) | I12: =MAX(I5:I8)
B14: Applied to NovaPay FY26E revenue
B15: Implied EV range (min-max EV/Rev) | E15: =H9*Financials!F7 | F15: =H12*Financials!F7
B16: Implied equity value (EV + net cash) | E16: =E15+Financials!F24 | F16: =F15+Financials!F24
A18: Illustrative - fictional data

Sheet DCF
A1: DISCOUNTED CASH FLOW
A2: Illustrative - fictional data. Not based on any real company.
A4: WACC build
A5: Risk-free rate | B5: 0.045
A6: Equity risk premium | B6: 0.07
A7: Country / size premium | B7: 0.025
A8: Beta (levered) | B8: 1.15
A9: Cost of equity | B9: =B5+B8*B6+B7
A10: After-tax cost of debt | B10: 0.06
A11: Debt / total capital | B11: 0.05
A12: WACC | B12: =B9*(1-B11)+B10*B11
A13: Terminal growth rate (g) | B13: 0.04
A15: Unlevered free cash flow (USD m) | C15: FY26E | D15: FY27E | E15: FY28E | F15: FY29E | G15: FY30E | H15: FY31E | I15: FY32E | J15: FY33E
A16: EBIT | C16: =Financials!F14 | D16: =Financials!G14 | E16: =Financials!H14 | F16: =E16*1.4 | G16: =F16*1.34 | H16: =G16*1.28 | I16: =H16*1.2 | J16: =I16*1.14
A17: Tax on EBIT (20%) | C17: =-C16*0.20 | D17: =-D16*0.20 | E17: =-E16*0.20 | F17: =-F16*0.20 | G17: =-G16*0.20 | H17: =-H16*0.20 | I17: =-I16*0.20 | J17: =-J16*0.20
A18: D&A | C18: =Financials!F13 | D18: =Financials!G13 | E18: =Financials!H13 | F18: =E18*1.10 | G18: =F18*1.10 | H18: =G18*1.10 | I18: =H18*1.10 | J18: =I18*1.10
A19: Capital expenditure | C19: =-Financials!F22 | D19: =-Financials!G22 | E19: =-Financials!H22 | F19: =E19*1.06 | G19: =F19*1.06 | H19: =G19*1.06 | I19: =H19*1.06 | J19: =I19*1.06
A20: Change in net working capital | C20: =-Financials!F23 | D20: =-Financials!G23 | E20: =-Financials!H23 | F20: =E20*1.08 | G20: =F20*1.08 | H20: =G20*1.08 | I20: =H20*1.08 | J20: =I20*1.08
A21: Unlevered free cash flow | C21: =SUM(C16:C20) | D21: =SUM(D16:D20) | E21: =SUM(E16:E20) | F21: =SUM(F16:F20) | G21: =SUM(G16:G20) | H21: =SUM(H16:H20) | I21: =SUM(I16:I20) | J21: =SUM(J16:J20)
A22: Discount period (yrs, mid-year) | C22: 0.5 | D22: 1.5 | E22: 2.5 | F22: 3.5 | G22: 4.5 | H22: 5.5 | I22: 6.5 | J22: 7.5
A23: Discount factor | C23: =1/(1+$B$12)^C22 | D23: =1/(1+$B$12)^D22 | E23: =1/(1+$B$12)^E22 | F23: =1/(1+$B$12)^F22 | G23: =1/(1+$B$12)^G22 | H23: =1/(1+$B$12)^H22 | I23: =1/(1+$B$12)^I22 | J23: =1/(1+$B$12)^J22
A24: PV of FCF | C24: =C21*C23 | D24: =D21*D23 | E24: =E21*E23 | F24: =F21*F23 | G24: =G21*G23 | H24: =H21*H23 | I24: =I21*I23 | J24: =J21*J23
A26: PV of forecast FCF (FY26-FY33) | C26: =SUM(C24:J24)
A27: Terminal value (Gordon growth, on FY33 FCF) | C27: =J21*(1+$B$13)/($B$12-$B$13)
A28: PV of terminal value | C28: =C27*J23
A29: Enterprise value | C29: =C26+C28
A30: Plus: net cash (FY26E) | C30: =Financials!F24
A31: Equity value (DCF, base case) | C31: =C29+C30
A33: Terminal value as % of EV | C33: =C28/C29
A35: Illustrative - fictional data

Sheet Sensitivity
A1: DCF EQUITY VALUE SENSITIVITY (USD m)
A2: Illustrative - fictional data. Not based on any real company.
A4: Rows = WACC | Columns = terminal growth rate
A6: WACC \ g | B6: 0.03 | C6: 0.035 | D6: 0.04 | E6: 0.045 | F6: 0.05
A7: 0.115 | B7: =DCF!C21/(1+$A7)^DCF!C22+DCF!D21/(1+$A7)^DCF!D22+DCF!E21/(1+$A7)^DCF!E22+DCF!F21/(1+$A7)^DCF!F22+DCF!G21/(1+$A7)^DCF!G22+DCF!H21/(1+$A7)^DCF!H22+DCF!I21/(1+$A7)^DCF!I22+DCF!J21/(1+$A7)^DCF!J22+(DCF!J21*(1+B$6)/($A7-B$6))/(1+$A7)^DCF!J22+Financials!F24 | C7: =DCF!C21/(1+$A7)^DCF!C22+DCF!D21/(1+$A7)^DCF!D22+DCF!E21/(1+$A7)^DCF!E22+DCF!F21/(1+$A7)^DCF!F22+DCF!G21/(1+$A7)^DCF!G22+DCF!H21/(1+$A7)^DCF!H22+DCF!I21/(1+$A7)^DCF!I22+DCF!J21/(1+$A7)^DCF!J22+(DCF!J21*(1+C$6)/($A7-C$6))/(1+$A7)^DCF!J22+Financials!F24 | D7: =DCF!C21/(1+$A7)^DCF!C22+DCF!D21/(1+$A7)^DCF!D22+DCF!E21/(1+$A7)^DCF!E22+DCF!F21/(1+$A7)^DCF!F22+DCF!G21/(1+$A7)^DCF!G22+DCF!H21/(1+$A7)^DCF!H22+DCF!I21/(1+$A7)^DCF!I22+DCF!J21/(1+$A7)^DCF!J22+(DCF!J21*(1+D$6)/($A7-D$6))/(1+$A7)^DCF!J22+Financials!F24 | E7: =DCF!C21/(1+$A7)^DCF!C22+DCF!D21/(1+$A7)^DCF!D22+DCF!E21/(1+$A7)^DCF!E22+DCF!F21/(1+$A7)^DCF!F22+DCF!G21/(1+$A7)^DCF!G22+DCF!H21/(1+$A7)^DCF!H22+DCF!I21/(1+$A7)^DCF!I22+DCF!J21/(1+$A7)^DCF!J22+(DCF!J21*(1+E$6)/($A7-E$6))/(1+$A7)^DCF!J22+Financials!F24 | F7: =DCF!C21/(1+$A7)^DCF!C22+DCF!D21/(1+$A7)^DCF!D22+DCF!E21/(1+$A7)^DCF!E22+DCF!F21/(1+$A7)^DCF!F22+DCF!G21/(1+$A7)^DCF!G22+DCF!H21/(1+$A7)^DCF!H22+DCF!I21/(1+$A7)^DCF!I22+DCF!J21/(1+$A7)^DCF!J22+(DCF!J21*(1+F$6)/($A7-F$6))/(1+$A7)^DCF!J22+Financials!F24
A8: 0.125 | B8: =DCF!C21/(1+$A8)^DCF!C22+DCF!D21/(1+$A8)^DCF!D22+DCF!E21/(1+$A8)^DCF!E22+DCF!F21/(1+$A8)^DCF!F22+DCF!G21/(1+$A8)^DCF!G22+DCF!H21/(1+$A8)^DCF!H22+DCF!I21/(1+$A8)^DCF!I22+DCF!J21/(1+$A8)^DCF!J22+(DCF!J21*(1+B$6)/($A8-B$6))/(1+$A8)^DCF!J22+Financials!F24 | C8: =DCF!C21/(1+$A8)^DCF!C22+DCF!D21/(1+$A8)^DCF!D22+DCF!E21/(1+$A8)^DCF!E22+DCF!F21/(1+$A8)^DCF!F22+DCF!G21/(1+$A8)^DCF!G22+DCF!H21/(1+$A8)^DCF!H22+DCF!I21/(1+$A8)^DCF!I22+DCF!J21/(1+$A8)^DCF!J22+(DCF!J21*(1+C$6)/($A8-C$6))/(1+$A8)^DCF!J22+Financials!F24 | D8: =DCF!C21/(1+$A8)^DCF!C22+DCF!D21/(1+$A8)^DCF!D22+DCF!E21/(1+$A8)^DCF!E22+DCF!F21/(1+$A8)^DCF!F22+DCF!G21/(1+$A8)^DCF!G22+DCF!H21/(1+$A8)^DCF!H22+DCF!I21/(1+$A8)^DCF!I22+DCF!J21/(1+$A8)^DCF!J22+(DCF!J21*(1+D$6)/($A8-D$6))/(1+$A8)^DCF!J22+Financials!F24 | E8: =DCF!C21/(1+$A8)^DCF!C22+DCF!D21/(1+$A8)^DCF!D22+DCF!E21/(1+$A8)^DCF!E22+DCF!F21/(1+$A8)^DCF!F22+DCF!G21/(1+$A8)^DCF!G22+DCF!H21/(1+$A8)^DCF!H22+DCF!I21/(1+$A8)^DCF!I22+DCF!J21/(1+$A8)^DCF!J22+(DCF!J21*(1+E$6)/($A8-E$6))/(1+$A8)^DCF!J22+Financials!F24 | F8: =DCF!C21/(1+$A8)^DCF!C22+DCF!D21/(1+$A8)^DCF!D22+DCF!E21/(1+$A8)^DCF!E22+DCF!F21/(1+$A8)^DCF!F22+DCF!G21/(1+$A8)^DCF!G22+DCF!H21/(1+$A8)^DCF!H22+DCF!I21/(1+$A8)^DCF!I22+DCF!J21/(1+$A8)^DCF!J22+(DCF!J21*(1+F$6)/($A8-F$6))/(1+$A8)^DCF!J22+Financials!F24
A9: 0.135 | B9: =DCF!C21/(1+$A9)^DCF!C22+DCF!D21/(1+$A9)^DCF!D22+DCF!E21/(1+$A9)^DCF!E22+DCF!F21/(1+$A9)^DCF!F22+DCF!G21/(1+$A9)^DCF!G22+DCF!H21/(1+$A9)^DCF!H22+DCF!I21/(1+$A9)^DCF!I22+DCF!J21/(1+$A9)^DCF!J22+(DCF!J21*(1+B$6)/($A9-B$6))/(1+$A9)^DCF!J22+Financials!F24 | C9: =DCF!C21/(1+$A9)^DCF!C22+DCF!D21/(1+$A9)^DCF!D22+DCF!E21/(1+$A9)^DCF!E22+DCF!F21/(1+$A9)^DCF!F22+DCF!G21/(1+$A9)^DCF!G22+DCF!H21/(1+$A9)^DCF!H22+DCF!I21/(1+$A9)^DCF!I22+DCF!J21/(1+$A9)^DCF!J22+(DCF!J21*(1+C$6)/($A9-C$6))/(1+$A9)^DCF!J22+Financials!F24 | D9: =DCF!C21/(1+$A9)^DCF!C22+DCF!D21/(1+$A9)^DCF!D22+DCF!E21/(1+$A9)^DCF!E22+DCF!F21/(1+$A9)^DCF!F22+DCF!G21/(1+$A9)^DCF!G22+DCF!H21/(1+$A9)^DCF!H22+DCF!I21/(1+$A9)^DCF!I22+DCF!J21/(1+$A9)^DCF!J22+(DCF!J21*(1+D$6)/($A9-D$6))/(1+$A9)^DCF!J22+Financials!F24 | E9: =DCF!C21/(1+$A9)^DCF!C22+DCF!D21/(1+$A9)^DCF!D22+DCF!E21/(1+$A9)^DCF!E22+DCF!F21/(1+$A9)^DCF!F22+DCF!G21/(1+$A9)^DCF!G22+DCF!H21/(1+$A9)^DCF!H22+DCF!I21/(1+$A9)^DCF!I22+DCF!J21/(1+$A9)^DCF!J22+(DCF!J21*(1+E$6)/($A9-E$6))/(1+$A9)^DCF!J22+Financials!F24 | F9: =DCF!C21/(1+$A9)^DCF!C22+DCF!D21/(1+$A9)^DCF!D22+DCF!E21/(1+$A9)^DCF!E22+DCF!F21/(1+$A9)^DCF!F22+DCF!G21/(1+$A9)^DCF!G22+DCF!H21/(1+$A9)^DCF!H22+DCF!I21/(1+$A9)^DCF!I22+DCF!J21/(1+$A9)^DCF!J22+(DCF!J21*(1+F$6)/($A9-F$6))/(1+$A9)^DCF!J22+Financials!F24
A10: 0.145 | B10: =DCF!C21/(1+$A10)^DCF!C22+DCF!D21/(1+$A10)^DCF!D22+DCF!E21/(1+$A10)^DCF!E22+DCF!F21/(1+$A10)^DCF!F22+DCF!G21/(1+$A10)^DCF!G22+DCF!H21/(1+$A10)^DCF!H22+DCF!I21/(1+$A10)^DCF!I22+DCF!J21/(1+$A10)^DCF!J22+(DCF!J21*(1+B$6)/($A10-B$6))/(1+$A10)^DCF!J22+Financials!F24 | C10: =DCF!C21/(1+$A10)^DCF!C22+DCF!D21/(1+$A10)^DCF!D22+DCF!E21/(1+$A10)^DCF!E22+DCF!F21/(1+$A10)^DCF!F22+DCF!G21/(1+$A10)^DCF!G22+DCF!H21/(1+$A10)^DCF!H22+DCF!I21/(1+$A10)^DCF!I22+DCF!J21/(1+$A10)^DCF!J22+(DCF!J21*(1+C$6)/($A10-C$6))/(1+$A10)^DCF!J22+Financials!F24 | D10: =DCF!C21/(1+$A10)^DCF!C22+DCF!D21/(1+$A10)^DCF!D22+DCF!E21/(1+$A10)^DCF!E22+DCF!F21/(1+$A10)^DCF!F22+DCF!G21/(1+$A10)^DCF!G22+DCF!H21/(1+$A10)^DCF!H22+DCF!I21/(1+$A10)^DCF!I22+DCF!J21/(1+$A10)^DCF!J22+(DCF!J21*(1+D$6)/($A10-D$6))/(1+$A10)^DCF!J22+Financials!F24 | E10: =DCF!C21/(1+$A10)^DCF!C22+DCF!D21/(1+$A10)^DCF!D22+DCF!E21/(1+$A10)^DCF!E22+DCF!F21/(1+$A10)^DCF!F22+DCF!G21/(1+$A10)^DCF!G22+DCF!H21/(1+$A10)^DCF!H22+DCF!I21/(1+$A10)^DCF!I22+DCF!J21/(1+$A10)^DCF!J22+(DCF!J21*(1+E$6)/($A10-E$6))/(1+$A10)^DCF!J22+Financials!F24 | F10: =DCF!C21/(1+$A10)^DCF!C22+DCF!D21/(1+$A10)^DCF!D22+DCF!E21/(1+$A10)^DCF!E22+DCF!F21/(1+$A10)^DCF!F22+DCF!G21/(1+$A10)^DCF!G22+DCF!H21/(1+$A10)^DCF!H22+DCF!I21/(1+$A10)^DCF!I22+DCF!J21/(1+$A10)^DCF!J22+(DCF!J21*(1+F$6)/($A10-F$6))/(1+$A10)^DCF!J22+Financials!F24
A11: 0.155 | B11: =DCF!C21/(1+$A11)^DCF!C22+DCF!D21/(1+$A11)^DCF!D22+DCF!E21/(1+$A11)^DCF!E22+DCF!F21/(1+$A11)^DCF!F22+DCF!G21/(1+$A11)^DCF!G22+DCF!H21/(1+$A11)^DCF!H22+DCF!I21/(1+$A11)^DCF!I22+DCF!J21/(1+$A11)^DCF!J22+(DCF!J21*(1+B$6)/($A11-B$6))/(1+$A11)^DCF!J22+Financials!F24 | C11: =DCF!C21/(1+$A11)^DCF!C22+DCF!D21/(1+$A11)^DCF!D22+DCF!E21/(1+$A11)^DCF!E22+DCF!F21/(1+$A11)^DCF!F22+DCF!G21/(1+$A11)^DCF!G22+DCF!H21/(1+$A11)^DCF!H22+DCF!I21/(1+$A11)^DCF!I22+DCF!J21/(1+$A11)^DCF!J22+(DCF!J21*(1+C$6)/($A11-C$6))/(1+$A11)^DCF!J22+Financials!F24 | D11: =DCF!C21/(1+$A11)^DCF!C22+DCF!D21/(1+$A11)^DCF!D22+DCF!E21/(1+$A11)^DCF!E22+DCF!F21/(1+$A11)^DCF!F22+DCF!G21/(1+$A11)^DCF!G22+DCF!H21/(1+$A11)^DCF!H22+DCF!I21/(1+$A11)^DCF!I22+DCF!J21/(1+$A11)^DCF!J22+(DCF!J21*(1+D$6)/($A11-D$6))/(1+$A11)^DCF!J22+Financials!F24 | E11: =DCF!C21/(1+$A11)^DCF!C22+DCF!D21/(1+$A11)^DCF!D22+DCF!E21/(1+$A11)^DCF!E22+DCF!F21/(1+$A11)^DCF!F22+DCF!G21/(1+$A11)^DCF!G22+DCF!H21/(1+$A11)^DCF!H22+DCF!I21/(1+$A11)^DCF!I22+DCF!J21/(1+$A11)^DCF!J22+(DCF!J21*(1+E$6)/($A11-E$6))/(1+$A11)^DCF!J22+Financials!F24 | F11: =DCF!C21/(1+$A11)^DCF!C22+DCF!D21/(1+$A11)^DCF!D22+DCF!E21/(1+$A11)^DCF!E22+DCF!F21/(1+$A11)^DCF!F22+DCF!G21/(1+$A11)^DCF!G22+DCF!H21/(1+$A11)^DCF!H22+DCF!I21/(1+$A11)^DCF!I22+DCF!J21/(1+$A11)^DCF!J22+(DCF!J21*(1+F$6)/($A11-F$6))/(1+$A11)^DCF!J22+Financials!F24
A13: Gold cell = base case (WACC 13.5%, g 4.0%) and ties to DCF!C31
A15: Illustrative - fictional data

Sheet Football_Field
A1: VALUATION SUMMARY - FOOTBALL FIELD (EQUITY VALUE, USD m)
A2: Illustrative - fictional data. Not based on any real company.
A4: Methodology | B4: Metric / basis | C4: Low (USD m) | D4: High (USD m) | E4: Midpoint
A5: Trading comps - EV/Revenue | B5: FY26E revenue x 3.9x-6.4x | C5: =Comps!C12 | D5: =Comps!D12 | E5: =AVERAGE(C5:D5)
A6: Trading comps - EV/EBITDA | B6: FY26E EBITDA x 22.0x-33.5x | C6: =Comps!C14 | D6: =Comps!D14 | E6: =AVERAGE(C6:D6)
A7: Precedent transactions | B7: FY26E revenue x 4.5x-7.2x | C7: =Precedents!E12 | D7: =Precedents!F12 | E7: =AVERAGE(C7:D7)
A8: DCF | B8: WACC 12.5%-14.5%, g 3.5%-4.5% | C8: =Sensitivity!C10 | D8: =Sensitivity!E8 | E8: =AVERAGE(C8:D8)
A10: Concluded reference equity value range | B10: Central overlap of the four methodologies | C10: =MEDIAN(C5:C8) | D10: =MEDIAN(D5:D8) | E10: =AVERAGE(C10:D10)
A12: IPO discount to concluded midpoint (low end / high end) | C12: 0.2 | D12: 0.1
A13: Pre-money equity value at IPO (post-discount) | C13: =$E$10*(1-C12) | D13: =$E$10*(1-D12) | E13: =AVERAGE(C13:D13)
A15: Implied FY26E EV/Revenue at offer (pre-money) | C15: =(C13-Financials!F24)/Financials!F7 | D15: =(D13-Financials!F24)/Financials!F7
A16: Implied FY26E EV/EBITDA at offer (pre-money) | C16: =(C13-Financials!F24)/Financials!F12 | D16: =(D13-Financials!F24)/Financials!F12
A18: Illustrative - fictional data

Sheet Offer_Structure
A1: OFFER STRUCTURE & USE OF PROCEEDS
A2: Illustrative - fictional data. Not based on any real company.
A4: Pre-IPO shares outstanding | B4: 320 | C4: m shares
A5: New primary shares issued | B5: 51 | C5: m shares
A6: Secondary (selling shareholder) shares | B6: 22 | C6: m shares
A7: Base offering size | B7: =B5+B6 | C7: m shares
A8: Primary share of offering | B8: =B5/B7 | C8: % of base offer
A9: Over-allotment option (greenshoe) | B9: =B7*0.15 | C9: m shares (15%)
A10: Post-IPO shares outstanding | B10: =B4+B5 | C10: m shares
A12: Offer price - low | B12: =Football_Field!C13/B4 | C12: USD / share
A13: Offer price - high | B13: =Football_Field!D13/B4 | C13: USD / share
A14: Offer price - midpoint | B14: =AVERAGE(B12:B13) | C14: USD / share
A16: Gross proceeds - total (low) | B16: =B7*B12 | C16: USD m
A17: Gross proceeds - total (high) | B17: =B7*B13 | C17: USD m
A18: Primary gross proceeds (midpoint) | B18: =B5*B14 | C18: USD m - to the company
A19: Secondary gross proceeds (midpoint) | B19: =B6*B14 | C19: USD m - to selling holders
A20: Underwriting & offering costs | B20: =B18*0.05 | C20: USD m (5% of primary)
A21: Net primary proceeds (midpoint) | B21: =B18-B20 | C21: USD m
A23: Post-money market cap at midpoint | B23: =B10*B14 | C23: USD m
A24: Market cap at low / high | B24: =B10*B12 | C24: USD m (low)
B25: =B10*B13 | C25: USD m (high)
A26: Free float - base offering | B26: =B7/B10 | C26: % of post-IPO shares
A27: Free float - incl. greenshoe | B27: =(B7+B9)/B10 | C27: % of post-IPO shares
A29: Use of primary proceeds
A30: Category | B30: % of net proceeds | C30: USD m
A31: Merchant acquisition & POS / QR terminal rollout | B31: 0.35 | C31: =$B$21*B31
A32: Technology platform, risk & fraud infrastructure | B32: 0.25 | C32: =$B$21*B32
A33: Licensing capital & regulatory reserve for new products | B33: 0.15 | C33: =$B$21*B33
A34: Strategic M&A and partnership investments | B34: 0.15 | C34: =$B$21*B34
A35: Working capital and general corporate purposes | B35: 0.1 | C35: =$B$21*B35
A36: Total | B36: =SUM(B31:B35) | C36: =SUM(C31:C35)
A38: Illustrative - fictional data

Sheet IPO_Timeline
A1: INDICATIVE IPO EXECUTION TIMELINE
A2: Illustrative - fictional data. Not based on any real company.
A4: Phase | B4: Weeks from kick-off | C4: Duration (weeks) | D4: Key workstreams
A5: 1. Preparation & readiness | B5: W0 - W10 | C5: 10 | D5: Financial and legal due diligence, audit of 3 years, corporate restructuring, ESOP clean-up, governance and independent board build-out
A6: 2. Documentation & filing | B6: W10 - W20 | C6: 10 | D6: Prospectus drafting, valuation report, listing application to the exchange per prevailing listing regulations
A7: 3. Regulatory review | B7: W20 - W30 | C7: 10 | D7: Responses to regulator comments, approval of the registration file, finalisation of the offering structure
A8: 4. Marketing & roadshow | B8: W30 - W34 | C8: 4 | D8: Analyst presentation, pre-deal investor education, management roadshow across domestic and regional accounts
A9: 5. Bookbuilding & pricing | B9: W34 - W36 | C9: 2 | D9: Order book build, price discovery within the range, allocation to anchor and institutional investors
A10: 6. Listing & aftermarket | B10: W36 - W40 | C10: 4 | D10: Settlement, listing on HOSE, stabilisation via greenshoe, index inclusion work, research coverage initiation
A11: Total elapsed | C11: =SUM(C5:C10) | D11: weeks of sequential + overlapping workstreams; target listing ~9-10 months from mandate
A13: Illustrative - fictional data

Sheet Slide_Numbers
A1: SLIDE-TO-MODEL TRACE (every number used on a slide)
A2: Illustrative - fictional data. Not based on any real company.
A4: Slide | B4: Figure as shown on slide | C4: Source cell | D4: Live value
A5: 2 | B5: FY25A revenue (USD m) | C5: Financials!E7 | D5: =Financials!E7
A6: 2 | B6: FY25A EBITDA (USD m) | C6: Financials!E12 | D6: =Financials!E12
A7: 2 | B7: Pre-money equity value low (USD m) | C7: Football_Field!C13 | D7: =Football_Field!C13
A8: 2 | B8: Pre-money equity value high (USD m) | C8: Football_Field!D13 | D8: =Football_Field!D13
A9: 2 | B9: Primary gross proceeds, midpoint (USD m) | C9: Offer_Structure!B18 | D9: =Offer_Structure!B18
A10: 2 | B10: Free float incl. greenshoe (%) | C10: Offer_Structure!B27 | D10: =Offer_Structure!B27
A11: 4 | B11: FY25A TPV (USD bn) | C11: Operating_KPI!E5 | D11: =Operating_KPI!E5
A12: 5 | B12: FY23A TPV (USD bn) | C12: Operating_KPI!C5 | D12: =Operating_KPI!C5
A13: 5 | B13: FY28E TPV (USD bn) | C13: Operating_KPI!H5 | D13: =Operating_KPI!H5
A14: 5 | B14: FY25A MAU (m) | C14: Operating_KPI!E8 | D14: =Operating_KPI!E8
A15: 5 | B15: FY28E MAU (m) | C15: Operating_KPI!H8 | D15: =Operating_KPI!H8
A16: 5 | B16: FY25A merchants ('000) | C16: Operating_KPI!E9 | D16: =Operating_KPI!E9
A17: 5 | B17: FY28E merchants ('000) | C17: Operating_KPI!H9 | D17: =Operating_KPI!H9
A18: 5 | B18: FY25A take rate (%) | C18: Operating_KPI!E7 | D18: =Operating_KPI!E7
A19: 5 | B19: FY28E take rate (%) | C19: Operating_KPI!H7 | D19: =Operating_KPI!H7
A20: 6 | B20: FY23A revenue (USD m) | C20: Financials!C7 | D20: =Financials!C7
A21: 6 | B21: FY28E revenue (USD m) | C21: Financials!H7 | D21: =Financials!H7
A22: 6 | B22: FY25A EBITDA margin (%) | C22: Financials!E11 | D22: =Financials!E11
A23: 6 | B23: FY28E EBITDA margin (%) | C23: Financials!H11 | D23: =Financials!H11
A24: 6 | B24: FY28E net income (USD m) | C24: Financials!H19 | D24: =Financials!H19
A25: 7 | B25: Comps EV/Rev low - high | C25: Comps!G10 / Comps!G13
A26: 7 | B26: Comps EV/EBITDA low - high | C26: Comps!H10 / Comps!H13
A27: 7 | B27: Precedents EV/Rev low - high | C27: Precedents!H9 / Precedents!H12
A28: 7 | B28: DCF equity low - high (USD m) | C28: Football_Field!C8 / Football_Field!D8
A29: 7 | B29: Concluded range (USD m) | C29: Football_Field!C10 / Football_Field!D10
A30: 7 | B30: IPO discount range (%) | C30: Football_Field!D12 / Football_Field!C12
A31: 7 | B31: Offer-price equity range (USD m) | C31: Football_Field!C13 / Football_Field!D13
A32: 7 | B32: Offer price per share (USD) | C32: Offer_Structure!B12 / Offer_Structure!B13
A33: 8 | B33: Base offering shares (m) | C33: Offer_Structure!B7 | D33: =Offer_Structure!B7
A34: 8 | B34: Primary % of offering | C34: Offer_Structure!B8 | D34: =Offer_Structure!B8
A35: 8 | B35: Net primary proceeds (USD m) | C35: Offer_Structure!B21 | D35: =Offer_Structure!B21
A36: 8 | B36: Secondary proceeds (USD m) | C36: Offer_Structure!B19 | D36: =Offer_Structure!B19
A37: 8 | B37: Post-money market cap (USD m) | C37: Offer_Structure!B23 | D37: =Offer_Structure!B23
A38: 8 | B38: Free float base / incl. shoe | C38: Offer_Structure!B26 / Offer_Structure!B27
A39: 8 | B39: Use of proceeds % | C39: Offer_Structure!B31:B35
A40: 9 | B40: Timeline phases / weeks | C40: IPO_Timeline!A5:C10
A41: A1 | B41: Full comps table | C41: Comps!A4:I13
...
